Workbook

Sheet Main
M1: =SUBTOTAL(9,M4:M226) -> 199 | N1: =SUBTOTAL(9,N4:N226) -> 528 | O1: =SUBTOTAL(9,O4:O226) -> 120 | P1: =SUBTOTAL(9,P4:P226) -> 847 | R1: =SUBTOTAL(9,R4:R226) -> 103 | S1: =SUBTOTAL(9,S4:S226) -> 384 | T1: =SUBTOTAL(9,T4:T226) -> 250 | U1: =SUBTOTAL(9,U4:U226) -> 737 | W1: =SUBTOTAL(9,W4:W226) -> 81 | X1: =SUBTOTAL(9,X4:X226) -> 652 | Y1: =SUBTOTAL(9,Y4:Y226) -> 430 | Z1: =SUBTOTAL(9,Z4:Z226) -> 1163 | AA1: =SUBTOTAL(9,AA4:AA226) -> 1 | AC1: =SUBTOTAL(9,AC4:AC226) -> 33 | AD1: =SUBTOTAL(9,AD4:AD226) -> 276 | AE1: =SUBTOTAL(9,AE4:AE226) -> 1032 | AF1: =SUBTOTAL(9,AF4:AF226) -> 1341 | AG1: =SUBTOTAL(9,AG4:AG226) -> 1 | AI1: =SUBTOTAL(9,AI4:AI226) -> 38 | AJ1: =SUBTOTAL(9,AJ4:AJ226) -> 65 | AK1: =SUBTOTAL(9,AK4:AK226) -> 1075 | AL1: =SUBTOTAL(9,AL4:AL226) -> 1178 | AM1: =SUBTOTAL(9,AM4:AM226) -> 1 | AO1: =SUBTOTAL(9,AO4:AO226) -> 27 | AP1: =SUBTOTAL(9,AP4:AP226) -> 1710 | AQ1: =SUBTOTAL(9,AQ4:AQ130) -> 1351 | AR1: =SUBTOTAL(9,AR4:AR226) -> #REF! | AS1: =SUBTOTAL(9,AS4:AS130) -> #REF! | AU1: =SUBTOTAL(9,AU4:AU226) -> 83 | AV1: =SUBTOTAL(9,AV4:AV226) -> 1569 | AW1: =SUBTOTAL(9,AW4:AW130) -> 1424 | AX1: =SUBTOTAL(9,AX4:AX226) -> #REF! | AY1: =SUBTOTAL(9,AY4:AY130) -> #REF! | BA1: =SUBTOTAL(9,BA4:BA226) -> 23 | BB1: =SUBTOTAL(9,BB4:BB226) -> 1926 | BC1: =SUBTOTAL(9,BC4:BC130) -> 1676 | BD1: =SUBTOTAL(9,BD4:BD226) -> #REF! | BE1: =SUBTOTAL(9,BE4:BE135) -> #REF! | BG1: =SUBTOTAL(9,BG4:BG226) -> 16 | BH1: =SUBTOTAL(9,BH4:BH226) -> 2095 | BI1: =SUBTOTAL(9,BI4:BI130) -> 1771 | BJ1: =BJ2*1.18 -> #REF! | BK1: =SUBTOTAL(9,BK4:BK141) -> #REF! | BM1: =SUBTOTAL(9,BM4:BM226) -> 0 | BN1: =SUBTOTAL(9,BN4:BN226) -> 2072 | BO1: =SUBTOTAL(9,BO4:BO130) -> 1654 | BP1: =BP2*1.18 -> #REF! | BQ1: =SUBTOTAL(9,BQ4:BQ135) -> #REF! | BS1: =SUBTOTAL(9,BS4:BS226) -> 0 | BT1: =SUBTOTAL(9,BT4:BT226) -> 2439 | BU1: =SUBTOTAL(9,BU4:BU226) -> 6737706.2 | BV1: =SUBTOTAL(9,BV4:BV226) -> 96 | BW1: =SUBTOTAL(9,BW4:BW226) -> 272694 | BX1: =SUBTOTAL(9,BX4:BX226) -> 685 | BY1: =SUBTOTAL(9,BY4:BY226) -> 1171870 | BZ1: =SUBTOTAL(9,BZ4:BZ130) -> 2626 | CA1: =SUBTOTAL(9,CA4:CA226) -> 8182270.2 | CB1: =SUBTOTAL(9,CB4:CB135) -> 0.74538426 | CC1: =CC2*1.18 -> #REF! | CD1: =SUBTOTAL(9,CD4:CD226) -> 1873 | CE1: =SUBTOTAL(9,CE4:CE226) -> 5396090.9 | CF1: =SUBTOTAL(9,CF4:CF226) -> 44 | CG1: =SUBTOTAL(9,CG4:CG226) -> 146542 | CH1: =SUBTOTAL(9,CH4:CH226) -> 935 | CI1: =SUBTOTAL(9,CI4:CI226) -> 1865835 | CJ1: =SUBTOTAL(9,CJ4:CJ130) -> 2303 | CK1: =SUBTOTAL(9,CK4:CK226) -> 7408467.9 | CL1: =SUBTOTAL(9,CL4:CL135) -> 0.74987856 | CM1: =CM2*1.18 -> #REF! | CN1: =SUBTOTAL(9,CN4:CN226) -> 2460 | CO1: =SUBTOTAL(9,CO4:CO226) -> 6610727.9 | CP1: =SUBTOTAL(9,CP4:CP226) -> 10 | CQ1: =SUBTOTAL(9,CQ4:CQ226) -> 32289 | CR1: =SUBTOTAL(9,CR4:CR226) -> 173 | CS1: =SUBTOTAL(9,CS4:CS226) -> 432745 | CT1: =SUBTOTAL(9,CT4:CT130) -> 2155 | CU1: =SUBTOTAL(9,CU4:CU226) -> 7075761.9 | CV1: =SUBTOTAL(9,CV4:CV135) -> 0.78134155 | CW1: =CW2*1.18 -> #REF! | CX1: =SUBTOTAL(9,CX4:CX226) -> 2652 | CY1: =SUBTOTAL(9,CY4:CY226) -> 7605982.4 | CZ1: =SUBTOTAL(9,CZ4:CZ226) -> 17 | DA1: =SUBTOTAL(9,DA4:DA226) -> 47183 | DB1: =SUBTOTAL(9,DB4:DB130) -> 2177 | DC1: =SUBTOTAL(9,DC4:DC226) -> 7653165.4 | DD1: =SUBTOTAL(9,DD4:DD141) -> 0.77677723 | DE1: =SUBTOTAL(9,DE4:DE145) -> 144488 | DF1: =SUBTOTAL(9,DF4:DF145) -> 2604 | DG1: =SUBTOTAL(9,DG4:DG226) -> 8750289 | DH1: =DH2*1.18 -> #REF! | DI1: =SUBTOTAL(9,DI4:DI226) -> 3353 | DJ1: =SUBTOTAL(9,DJ4:DJ226) -> 8700271.9 | DK1: =SUBTOTAL(9,DK4:DK226) -> 10 | DL1: =SUBTOTAL(9,DL4:DL226) -> 30465 | DM1: =SUBTOTAL(9,DM4:DM145) -> 2875 | DN1: =SUBTOTAL(9,DN4:DN226) -> 8730736.9 | DO1: =SUBTOTAL(9,DO4:DO226) -> 7398929.5 | DP1: =SUBTOTAL(9,DP4:DP145) -> 0.80828823 | DQ1: =SUBTOTAL(9,DQ4:DQ145) -> 177633 | DR1: =SUBTOTAL(9,DR4:DR145) -> 3423 | DS1: =SUBTOTAL(9,DS4:DS226) -> 10017803 | DT1: =SUBTOTAL(9,DT4:DT145) -> 0.8082313 | DU1: =DU2*1.18 -> #REF! | DW1: SD Ads | DX1: 57013 | DY1: 255 | DZ1: 621270 | EE1: =SUBTOTAL(9,EE4:EE226) -> 3696 | EF1: =SUBTOTAL(9,EF4:EF226) -> 9750173.6 | EG1: =SUBTOTAL(9,EG4:EG226) -> 50 | EH1: =SUBTOTAL(9,EH4:EH226) -> 105454 | EI1: =SUBTOTAL(9,EI4:EI145) -> 3355 | EJ1: =SUBTOTAL(9,EJ4:EJ226) -> 9855627.6 | EK1: =SUBTOTAL(9,EK4:EK226) -> 8352226.8 | EL1: =SUBTOTAL(9,EL4:EL145) -> 0.85177186 | EM1: =SUBTOTAL(9,EM4:EM145) -> 216308 | EN1: =SUBTOTAL(9,EN4:EN145) -> 4107 | EO1: =SUBTOTAL(9,EO4:EO226) -> 11324963 | EP1: =SUBTOTAL(9,EP4:EP145) -> 0.85130071 | EQ1: =EQ2*1.18 -> #REF! | EV1: =SUBTOTAL(9,EV4:EV226) -> 3674 | EW1: =SUBTOTAL(9,EW4:EW226) -> 10009755 | EX1: =SUBTOTAL(9,EX4:EX226) -> 97 | EY1: =SUBTOTAL(9,EY4:EY226) -> 231693 | EZ1: =SUBTOTAL(9,EZ4:EZ145) -> 3596 | FA1: =SUBTOTAL(9,FA4:FA226) -> 10241448 | FB1: =SUBTOTAL(9,FB4:FB226) -> 8679193.5 | FC1: =SUBTOTAL(9,FC4:FC145) -> 0.92497847 | FD1: =SUBTOTAL(9,FD4:FD145) -> 252805 | FE1: =SUBTOTAL(9,FE4:FE145) -> 4769 | FF1: =SUBTOTAL(9,FF4:FF226) -> 13143204 | FG1: =SUBTOTAL(9,FG4:FG145) -> 0.91013485 | FH1: =FH2*1.18 -> #REF! | FI1: =SUBTOTAL(9,FI4:FI226) -> 4923 | FJ1: =SUBTOTAL(9,FJ4:FJ226) -> 12829934 | FK1: =SUBTOTAL(9,FK4:FK226) -> 53 | FL1: =SUBTOTAL(9,FL4:FL226) -> 129636 | FM1: =SUBTOTAL(9,FM4:FM145) -> 4814 | FN1: =SUBTOTAL(9,FN4:FN226) -> 12959570 | FO1: =SUBTOTAL(9,FO4:FO226) -> 10982686 | FP1: =SUBTOTAL(9,FP4:FP145) -> 0.94893897 | FQ1: =SUBTOTAL(9,FQ4:FQ145) -> 293469 | FR1: =SUBTOTAL(9,FR4:FR145) -> 6620 | FS1: =SUBTOTAL(9,FS4:FS226) -> 16828994 | FT1: =SUBTOTAL(9,FT4:FT145) -> 0.94658944 | FU1: =FU2*1.18 -> #REF! | FV1: =SUBTOTAL(9,FV4:FV226) -> 4205 | FW1: =SUBTOTAL(9,FW4:FW226) -> 10794801 | FX1: =SUBTOTAL(9,FX4:FX226) -> 34 | FY1: =SUBTOTAL(9,FY4:FY226) -> 89795.15 | FZ1: =SUBTOTAL(9,FZ4:FZ145) -> 4126 | GA1: =SUBTOTAL(9,GA4:GA226) -> 10884596 | GB1: =SUBTOTAL(9,GB4:GB226) -> 9224234.1 | GC1: =SUBTOTAL(9,GC4:GC145) -> 0.95596183 | GD1: =SUBTOTAL(9,GD4:GD145) -> 244552 | GE1: =SUBTOTAL(9,GE4:GE145) -> 4933 | GF1: =SUBTOTAL(9,GF4:GF226) -> 12300352 | GG1: =SUBTOTAL(9,GG4:GG145) -> 0.95900792 | GI1: =SUBTOTAL(9,GI4:GI226) -> 3531 | GJ1: =SUBTOTAL(9,GJ4:GJ226) -> 8988574.4 | GK1: =SUBTOTAL(9,GK4:GK226) -> 0 | GL1: =SUBTOTAL(9,GL4:GL226) -> 0 | GM1: =SUBTOTAL(9,GM4:GM145) -> 3438 | GN1: =SUBTOTAL(9,GN4:GN226) -> 8988574.4 | GO1: =SUBTOTAL(9,GO4:GO226) -> 7617435.9 | GP1: =SUBTOTAL(9,GP4:GP145) -> 0.95132859 | GQ1: =SUBTOTAL(9,GQ4:GQ145) -> 199906 | GR1: =SUBTOTAL(9,GR4:GR145) -> 4190 | GS1: =SUBTOTAL(9,GS4:GS226) -> 10542481 | GT1: =SUBTOTAL(9,GT4:GT145) -> 0.94841774 | GV1: =SUBTOTAL(9,GV4:GV226) -> 3314 | GW1: =SUBTOTAL(9,GW4:GW226) -> 8336692.6 | GX1: =SUBTOTAL(9,GX4:GX226) -> 0 | GY1: =SUBTOTAL(9,GY4:GY226) -> 0 | GZ1: =SUBTOTAL(9,GZ4:GZ145) -> 3250 | HA1: =SUBTOTAL(9,HA4:HA226) -> 8336692.6 | HB1: =SUBTOTAL(9,HB4:HB226) -> 7064993.7 | HC1: =SUBTOTAL(9,HC4:HC145) -> 0.96263694 | HD1: =SUBTOTAL(9,HD4:HD145) -> 236753 | HE1: =SUBTOTAL(9,HE4:HE145) -> 4749 | HF1: =SUBTOTAL(9,HF4:HF226) -> 11527161 | HG1: =SUBTOTAL(9,HG4:HG145) -> 0.97251873 | HI1: =SUBTOTAL(9,HI4:HI226) -> 3126 | HJ1: =SUBTOTAL(9,HJ4:HJ226) -> 8375891.2 | HK1: =SUBTOTAL(9,HK4:HK226) -> 0 | HL1: =SUBTOTAL(9,HL4:HL226) -> 0 | HM1: =SUBTOTAL(9,HM4:HM145) -> 3093 | HN1: =SUBTOTAL(9,HN4:HN226) -> 8375891.2 | HO1: =SUBTOTAL(9,HO4:HO226) -> 7098212.9 | HP1: =SUBTOTAL(9,HP4:HP145) -> 0.98373128 | HQ1: =SUBTOTAL(9,HQ4:HQ145) -> 196637 | HR1: =SUBTOTAL(9,HR4:HR145) -> 3769 | HS1: =SUBTOTAL(9,HS4:HS226) -> 9635624 | HT1: =SUBTOTAL(9,HT4:HT145) -> 0.98478355 | HV1: =SUBTOTAL(9,HV4:HV226) -> 1496 | HW1: =SUBTOTAL(9,HW4:HW226) -> 3981195.1 | HX1: =SUBTOTAL(9,HX4:HX226) -> 2937 | HY1: =SUBTOTAL(9,HY4:HY226) -> 8285013.5 | HZ1: =SUBTOTAL(9,HZ4:HZ145) -> 4393 | IA1: =SUBTOTAL(9,IA4:IA226) -> 12266209 | IB1: =SUBTOTAL(9,IB4:IB226) -> 10395092 | IC1: =SUBTOTAL(9,IC4:IC145) -> 0.98713499 | ID1: =SUBTOTAL(9,ID4:ID145) -> 186926 | IE1: =SUBTOTAL(9,IE4:IE145) -> 743 | IF1: =SUBTOTAL(9,IF4:IF226) -> 1806669 | IG1: =SUBTOTAL(9,IG4:IG145) -> 0.91429033 | II1: =SUBTOTAL(9,II4:II226) -> 571 | IJ1: =SUBTOTAL(9,IJ4:IJ226) -> 1690069.7 | IK1: =SUBTOTAL(9,IK4:IK226) -> 2548 | IL1: =SUBTOTAL(9,IL4:IL226) -> 7509275.6 | IM1: =SUBTOTAL(9,IM4:IM145) -> 3087 | IN1: =SUBTOTAL(9,IN4:IN226) -> 9199345.3 | IO1: =SUBTOTAL(9,IO4:IO226) -> 7796055.4 | IP1: =SUBTOTAL(9,IP4:IP145) -> 0.98110261 | IQ1: =SUBTOTAL(9,IQ4:IQ145) -> 175562 | IR1: =SUBTOTAL(9,IR4:IR145) -> 369 | IS1: =SUBTOTAL(9,IS4:IS226) -> 1047344 | IT1: =SUBTOTAL(9,IT4:IT145) -> 0.94518897 | IZ1: =SUBTOTAL(9,IZ4:IZ226) -> 3918 | JA1: =SUBTOTAL(9,JA4:JA226) -> 6080727.3 | JB1: =SUBTOTAL(9,JB4:JB226) -> 24152 | JC1: =SUBTOTAL(9,JC4:JC226) -> 32036302 | JD1: =SUBTOTAL(9,JD4:JD226) -> 3345 | JE1: =SUBTOTAL(9,JE4:JE226) -> 5339300.8 | JF1: =SUBTOTAL(9,JF4:JF226) -> 0 | JG1: =SUBTOTAL(9,JG4:JG226) -> 0 | ... JO1: =SUBTOTAL(9,JO4:JO226) -> 79503093 | JS1: =SUBTOTAL(9,JS4:JS226) -> 358 | JT1: =SUBTOTAL(9,JT4:JT226) -> 1080576.8 | JU1: =SUBTOTAL(9,JU4:JU226) -> 3354 | JV1: =SUBTOTAL(9,JV4:JV226) -> 9920003.8 | JW1: =SUBTOTAL(9,JW4:JW145) -> 3695 | JX1: =SUBTOTAL(9,JX4:JX226) -> 11000581 | JY1: =SUBTOTAL(9,JY4:JY226) -> 9322525.9 | JZ1: =SUBTOTAL(9,JZ4:JZ145) -> 0.99272404 | KA1: =SUBTOTAL(9,KA4:KA145) -> 204806 | KB1: =SUBTOTAL(9,KB4:KB145) -> 369 | KC1: =SUBTOTAL(9,KC4:KC226) -> 1047344 | KD1: =SUBTOTAL(9,KD4:KD145) -> 0.94518897 | KJ1: =SUBTOTAL(9,KJ4:KJ226) -> 3025 | KK1: =SUBTOTAL(9,KK4:KK226) -> 4402048.7 | KL1: =SUBTOTAL(9,KL4:KL226) -> 20764 | KM1: =SUBTOTAL(9,KM4:KM226) -> 26249692 | KN1: =SUBTOTAL(9,KN4:KN226) -> 3345 | KO1: =SUBTOTAL(9,KO4:KO226) -> 5339300.8 | KP1: =SUBTOTAL(9,KP4:KP226) -> 0 | KQ1: =SUBTOTAL(9,KQ4:KQ226) -> 0 | ... KY1: =SUBTOTAL(9,KY4:KY226) -> 72037803 | LC1: =SUBTOTAL(9,LC4:LC158) -> 333 | LD1: =SUBTOTAL(9,LD4:LD158) -> 908342.42 | LE1: =SUBTOTAL(9,LE4:LE158) -> 3585 | LF1: =SUBTOTAL(9,LF4:LF158) -> 9905025.8 | LG1: =SUBTOTAL(9,LG4:LG158) -> 3918 | LH1: =SUBTOTAL(9,LH4:LH158) -> 10813368 | LI1: =SUBTOTAL(9,LI4:LI158) -> 9163871.3 | LJ1: =SUBTOTAL(9,LJ4:LJ158) -> 1 | LK1: =SUBTOTAL(9,LK4:LK158) -> 223977 | LL1: =SUBTOTAL(9,LL4:LL145) -> 369 | LM1: =SUBTOTAL(9,LM4:LM226) -> 1047344 | LN1: =SUBTOTAL(9,LN4:LN145) -> 0.94518897 | LT1: =SUBTOTAL(9,LT4:LT158) -> 2478 | LU1: =SUBTOTAL(9,LU4:LU158) -> 3779771.9 | LV1: =SUBTOTAL(9,LV4:LV158) -> 22136 | LW1: =SUBTOTAL(9,LW4:LW158) -> 28406946 | LX1: =SUBTOTAL(9,LX4:LX158) -> 1055 | LY1: =SUBTOTAL(9,LY4:LY158) -> 1890004.8 | LZ1: =SUBTOTAL(9,LZ4:LZ158) -> 0 | MA1: =SUBTOTAL(9,MA4:MA158) -> 0 | ... MI1: =SUBTOTAL(9,MI4:MI158) -> 73264303 | MM1: =SUBTOTAL(9,MM4:MM158) -> 348 | MN1: =SUBTOTAL(9,MN4:MN158) -> 897838 | MO1: =SUBTOTAL(9,MO4:MO158) -> 4737 | MP1: =SUBTOTAL(9,MP4:MP158) -> 12744267 | MQ1: =SUBTOTAL(9,MQ4:MQ158) -> 5085 | MR1: =SUBTOTAL(9,MR4:MR158) -> 13642105 | MS1: =SUBTOTAL(9,MS4:MS158) -> 11561106 | MT1: =SUBTOTAL(9,MT4:MT158) -> 1 | MU1: =SUBTOTAL(9,MU4:MU158) -> 268408 | MV1: =SUBTOTAL(9,MV4:MV145) -> 369 | MW1: =SUBTOTAL(9,MW4:MW226) -> 1047344 | MX1: =SUBTOTAL(9,MX4:MX145) -> 0.94518897 | ND1: =SUBTOTAL(9,ND4:ND158) -> 5047 | NE1: =SUBTOTAL(9,NE4:NE158) -> 7742219.6 | NF1: =SUBTOTAL(9,NF4:NF158) -> 19446 | NG1: =SUBTOTAL(9,NG4:NG158) -> 25336771 | NH1: =SUBTOTAL(9,NH4:NH158) -> 1561 | NI1: =SUBTOTAL(9,NI4:NI158) -> 2326639.7 | NJ1: =SUBTOTAL(9,NJ4:NJ158) -> 0 | NK1: =SUBTOTAL(9,NK4:NK158) -> 0 | ... NT1: =SUBTOTAL(9,NT4:NT158) -> 2598 | NX1: =SUBTOTAL(9,NX4:NX291) -> 725 | NY1: =SUBTOTAL(9,NY4:NY291) -> 1775892.2 | NZ1: =SUBTOTAL(9,NZ4:NZ291) -> 4664 | OA1: =SUBTOTAL(9,OA4:OA291) -> 12495185 | OB1: =SUBTOTAL(9,OB4:OB291) -> 5389 | OC1: =SUBTOTAL(9,OC4:OC291) -> 14271077 | OD1: =SUBTOTAL(9,OD4:OD291) -> 12094133 | OE1: =SUBTOTAL(9,OE4:OE291) -> 1 | OF1: =SUBTOTAL(9,OF4:OF291) -> 289280 | OG1: =SUBTOTAL(9,OG4:OG145) -> 369 | OH1: =SUBTOTAL(9,OH4:OH226) -> 1047344 | OI1: =SUBTOTAL(9,OI4:OI145) -> 0.94518897 | OO1: =SUBTOTAL(9,OO4:OO291) -> 4451 | OP1: =SUBTOTAL(9,OP4:OP291) -> 6986168.8 | OQ1: =SUBTOTAL(9,OQ4:OQ291) -> 19075 | OR1: =SUBTOTAL(9,OR4:OR291) -> 26128951 | OS1: =SUBTOTAL(9,OS4:OS291) -> 1060 | OT1: =SUBTOTAL(9,OT4:OT291) -> 2001844.3 | OU1: =SUBTOTAL(9,OU4:OU291) -> 0 | OV1: =SUBTOTAL(9,OV4:OV291) -> 0 | ... PE1: =SUBTOTAL(9,PE4:PE291) -> 8588 | PI1: =SUBTOTAL(9,PI4:PI291) -> 348 | PJ1: =SUBTOTAL(9,PJ4:PJ291) -> 1031620.8 | PK1: =SUBTOTAL(9,PK4:PK291) -> 5907 | PL1: =SUBTOTAL(9,PL4:PL291) -> 16720157 | PM1: =SUBTOTAL(9,PM4:PM291) -> 6255 | PN1: =SUBTOTAL(9,PN4:PN291) -> 17751778 | PO1: =SUBTOTAL(9,PO4:PO291) -> 15043879 | PP1: =SUBTOTAL(9,PP4:PP291) -> 1 | PQ1: =SUBTOTAL(9,PQ4:PQ291) -> 393079 | PR1: =SUBTOTAL(9,PR4:PR145) -> 369 | PS1: =SUBTOTAL(9,PS4:PS226) -> 1047344 | PT1: =SUBTOTAL(9,PT4:PT145) -> 0.94518897 | PZ1: =SUBTOTAL(9,PZ4:PZ291) -> 4212 | QA1: =SUBTOTAL(9,QA4:QA291) -> 6690948.7 | QB1: =SUBTOTAL(9,QB4:QB291) -> 0 | QC1: =SUBTOTAL(9,QC4:QC291) -> 0 | QD1: =SUBTOTAL(9,QD4:QD291) -> 1060 | QE1: =SUBTOTAL(9,QE4:QE291) -> 2001844.3 | QF1: =SUBTOTAL(9,QF4:QF291) -> 0 | QG1: =SUBTOTAL(9,QG4:QG291) -> 0 | ... QP1: =SUBTOTAL(9,QP4:QP291) -> 9360 | QT1: =SUBTOTAL(9,QT4:QT291) -> 683 | QU1: =SUBTOTAL(9,QU4:QU291) -> 1646930 | QV1: =SUBTOTAL(9,QV4:QV291) -> 5810 | QW1: =SUBTOTAL(9,QW4:QW291) -> 17040943 | QX1: =SUBTOTAL(9,QX4:QX291) -> 6493 | QY1: =SUBTOTAL(9,QY4:QY291) -> 18687873 | QZ1: =SUBTOTAL(9,QZ4:QZ291) -> 15837181 | RA1: =SUBTOTAL(9,RA4:RA291) -> 1 | RB1: =SUBTOTAL(9,RB4:RB291) -> 385023 | RC1: =SUBTOTAL(9,RC4:RC145) -> 369 | RD1: =SUBTOTAL(9,RD4:RD226) -> 1047344 | RE1: =SUBTOTAL(9,RE4:RE145) -> 0.94518897 | RK1: =SUBTOTAL(9,RK4:RK291) -> 4704 | RL1: =SUBTOTAL(9,RL4:RL291) -> 7172396.8 | RM1: =SUBTOTAL(9,RM4:RM291) -> 31551 | RN1: =SUBTOTAL(9,RN4:RN291) -> 37112381 | RO1: =SUBTOTAL(9,RO4:RO291) -> 327 | RP1: =SUBTOTAL(9,RP4:RP291) -> 399057.21 | RQ1: =SUBTOTAL(9,RQ4:RQ291) -> 0 | RR1: =SUBTOTAL(9,RR4:RR291) -> 0 | ... SA1: =SUBTOTAL(9,SA4:SA291) -> 6220 | SE1: =SUBTOTAL(9,SE4:SE291) -> 607 | SF1: =SUBTOTAL(9,SF4:SF291) -> 1647889 | SG1: =SUBTOTAL(9,SG4:SG291) -> 5054 | SH1: =SUBTOTAL(9,SH4:SH291) -> 13961356 | SI1: =SUBTOTAL(9,SI4:SI291) -> 5661 | SJ1: =SUBTOTAL(9,SJ4:SJ291) -> 15609245 | SK1: =SUBTOTAL(9,SK4:SK291) -> 13228174 | SL1: =SUBTOTAL(9,SL4:SL291) -> 1 | SM1: =SUBTOTAL(9,SM4:SM291) -> 815364 | SN1: =SUBTOTAL(9,SN4:SN145) -> 369 | SO1: =SUBTOTAL(9,SO4:SO226) -> 1047344 | SP1: =SUBTOTAL(9,SP4:SP145) -> 0.94518897 | SV1: =SUBTOTAL(9,SV4:SV291) -> 5600 | SW1: =SUBTOTAL(9,SW4:SW291) -> 8140949.1 | SX1: =SUBTOTAL(9,SX4:SX291) -> 27836 | SY1: =SUBTOTAL(9,SY4:SY291) -> 32738015 | SZ1: =SUBTOTAL(9,SZ4:SZ291) -> 327 | TA1: =SUBTOTAL(9,TA4:TA291) -> 399057.21 | TB1: =SUBTOTAL(9,TB4:TB291) -> 0 | TC1: =SUBTOTAL(9,TC4:TC291) -> 0 | ... TL1: =SUBTOTAL(9,TL4:TL291) -> 5824 | TP1: =SUBTOTAL(9,TP4:TP291) -> 928 | TQ1: =SUBTOTAL(9,TQ4:TQ291) -> 2761372.5 | TR1: =SUBTOTAL(9,TR4:TR291) -> 5330 | TS1: =SUBTOTAL(9,TS4:TS291) -> 14170339 | TT1: =SUBTOTAL(9,TT4:TT291) -> 6258 | TU1: =SUBTOTAL(9,TU4:TU291) -> 16931712 | TV1: =SUBTOTAL(9,TV4:TV291) -> 14348908 | TW1: =SUBTOTAL(9,TW4:TW291) -> 1 | TX1: =SUBTOTAL(9,TX4:TX291) -> 680842 | TY1: =SUBTOTAL(9,TY4:TY145) -> 369 | TZ1: =SUBTOTAL(9,TZ4:TZ226) -> 1047344 | UA1: =SUBTOTAL(9,UA4:UA145) -> 0.94518897 | UG1: =SUBTOTAL(9,UG4:UG291) -> 5657 | UH1: =SUBTOTAL(9,UH4:UH291) -> 7872024.6 | UI1: =SUBTOTAL(9,UI4:UI291) -> 25285 | UJ1: =SUBTOTAL(9,UJ4:UJ291) -> 33724374 | UK1: =SUBTOTAL(9,UK4:UK291) -> 327 | UL1: =SUBTOTAL(9,UL4:UL291) -> 399057.21 | UM1: =SUBTOTAL(9,UM4:UM291) -> 0 | UN1: =SUBTOTAL(9,UN4:UN291) -> 0 | ... UW1: =SUBTOTAL(9,UW4:UW291) -> 6852 | VA1: =SUBTOTAL(9,VA4:VA291) -> 936 | VB1: =SUBTOTAL(9,VB4:VB291) -> 2502652.5 | VC1: =SUBTOTAL(9,VC4:VC291) -> 4998 | VD1: =SUBTOTAL(9,VD4:VD291) -> 14227811 | VE1: =SUBTOTAL(9,VE4:VE291) -> 5934 | VF1: =SUBTOTAL(9,VF4:VF291) -> 16730464 | VG1: =SUBTOTAL(9,VG4:VG291) -> 14178359 | VH1: =SUBTOTAL(9,VH4:VH291) -> 1 | VI1: =SUBTOTAL(9,VI4:VI291) -> 668540 | VJ1: =SUBTOTAL(9,VJ4:VJ145) -> 381 | VK1: =SUBTOTAL(9,VK4:VK226) -> 1066532 | VL1: =SUBTOTAL(9,VL4:VL145) -> 0.9635096 | VR1: =SUBTOTAL(9,VR4:VR291) -> 5297 | VS1: =SUBTOTAL(9,VS4:VS291) -> 9022277.7 | VT1: =SUBTOTAL(9,VT4:VT291) -> 32912 | VU1: =SUBTOTAL(9,VU4:VU291) -> 41844322 | VV1: =SUBTOTAL(9,VV4:VV291) -> 248 | VW1: =SUBTOTAL(9,VW4:VW291) -> 350971.34 | VX1: =SUBTOTAL(9,VX4:VX291) -> 0 | VY1: =SUBTOTAL(9,VY4:VY291) -> 0 | ... WH1: =SUBTOTAL(9,WH4:WH291) -> 6578
L2: 45047 | P2: May | Q2: 45078 | U2: June | V2: 45108 | Z2: July | AB2: 45139 | AF2: Aug | AH2: 45170 | AL2: Sept | AN2: 45200 | AQ2: Oct | AR2: =AR1*1.18 -> #REF! | AT2: 45231 | AW2: Nov | AX2: =AX1*1.18 -> #REF! | AZ2: 45261 | BC2: Dec | BD2: =BD1*1.18 -> #REF! | BF2: 45292 | BI2: Jan | BJ2: =SUBTOTAL(9,BJ4:BJ135) -> #REF! | BL2: 45323 | BO2: Feb | BP2: =SUBTOTAL(9,BP4:BP135) -> #REF! | BR2: 45352 | BS2: 45352 | BT2: 45352 | BU2: =BU1/1.18 -> 5709920.5 | BV2: 45352 | BW2: =BW1/1.18 -> 231096.61 | BX2: 45352 | BY2: =BY1/1.18 -> 993110.17 | BZ2: March | CA2: =CA1/1.18 -> 6934127.3 | CC2: =SUBTOTAL(9,CC4:CC135) -> #REF! | CD2: April | CE2: =CE1/1.18 -> 4572958.4 | CF2: 45383 | CG2: =CG1/1.18 -> 124188.14 | CH2: April | CI2: =CI1/1.18 -> 1581216.1 | CJ2: April | CK2: =CK1/1.18 -> 6278362.6 | CM2: =SUBTOTAL(9,CM4:CM135) -> #REF! | CN2: 45413 | CO2: =CO1/1.18 -> 5602311.8 | CP2: 45413 | CQ2: =CQ1/1.18 -> 27363.559 | CR2: 45413 | CS2: =CS1/1.18 -> 366733.05 | CT2: May | CU2: =CU1/1.18 -> 5996408.4 | CW2: =SUBTOTAL(9,CW4:CW135) -> #REF! | CX2: 45444 | CY2: =CY1/1.18 -> 6445747.8 | DA2: =DA1/1.18 -> 39985.593 | DB2: June | DC2: =DC1/1.18 -> 6485733.4 | DD2: 45444 | DG2: =DG1/1.18 -> 7415499.2 | DH2: =SUBTOTAL(9,DH4:DH135) -> #REF! | DI2: 45474 | DJ2: =DJ1/1.18 -> 7373111.7 | DK2: 45474 | DL2: =DL1/1.18 -> 25817.797 | DM2: 45474 | DN2: =DN1/1.18 -> 7398929.5 | DP2: 45474 | DS2: =DS1/1.18 -> 8489663.4 | DT2: 45474 | DU2: =SUBTOTAL(9,DU4:DU135) -> #REF! | DX2: =SUBTOTAL(9,DX4:DX145) -> 555681.27 | DY2: =SUBTOTAL(9,DY4:DY145) -> 1740 | DZ2: =SUBTOTAL(9,DZ4:DZ145) -> 3570893.3 | EA2: =(DX2+DX1)/(DZ2+DZ1) -> 0.14615229 | EB2: =(DX2+DX1)/DO1 -> 0.082808502 | EE2: 45505 | EF2: =EF1/1.18 -> 8262859 | EG2: 45505 | EH2: =EH1/1.18 -> 89367.797 | EI2: 45505 | EJ2: =EJ1/1.18 -> 8352226.8 | EL2: 45505 | EO2: =EO1/1.18 -> 9597426.3 | EP2: 45505 | EQ2: =SUBTOTAL(9,EQ4:EQ135) -> #REF! | EV2: 45536 | EW2: =EW1/1.18 -> 8482843.5 | EX2: 45536 | EY2: =EY1/1.18 -> 196350 | EZ2: 45536 | FA2: =FA1/1.18 -> 8679193.5 | FC2: 45536 | FF2: =FF1/1.18 -> 11138308 | FG2: 45536 | FH2: =SUBTOTAL(9,FH4:FH135) -> #REF! | FI2: Oct | FJ2: =FJ1/1.18 -> 10872825 | FK2: Oct | FL2: =FL1/1.18 -> 109861.02 | FM2: Oct'24 | FN2: =FN1/1.18 -> 10982686 | FP2: Oct'24 | FS2: =FS1/1.18 -> 14261860 | FT2: Oct'24 | FU2: =SUBTOTAL(9,FU4:FU135) -> #REF! | FV2: Nov'24 | FW2: =FW1/1.18 -> 9148136.5 | FX2: Nov'24 | FY2: =FY1/1.18 -> 76097.585 | FZ2: Nov'24 | GA2: =GA1/1.18 -> 9224234.1 | GC2: Nov'24 | GF2: =GF1/1.18 -> 10424027 | GG2: Nov'24 | GH2: =SUBTOTAL(9,GH4:GH135) -> 5501818.9 | GI2: Dec'24 | GJ2: =GJ1/1.18 -> 7617435.9 | GK2: Dec'24 | GL2: =GL1/1.18 -> 0 | GM2: Dec'24 | GN2: =GN1/1.18 -> 7617435.9 | GP2: Dec'24 | GS2: =GS1/1.18 -> 8934305.9 | GT2: Dec'24 | GU2: =SUBTOTAL(9,GU4:GU135) -> 4418985.6 | GV2: Jan'25 | GW2: =GW1/1.18 -> 7064993.7 | GX2: Jan'25 | GY2: =GY1/1.18 -> 0 | GZ2: Jan'25 | HA2: =HA1/1.18 -> 7064993.7 | HC2: Jan'25 | HF2: =HF1/118 -> 97687.805 | HG2: Jan'25 | HH2: =SUBTOTAL(9,HH4:HH135) -> 4219869.8 | HI2: Feb'25 | HJ2: =HJ1/1.18 -> 7098212.9 | HK2: Feb'25 | HL2: =HL1/1.18 -> 0 | HM2: Feb'25 | HN2: =HN1/1.18 -> 7098212.9 | HP2: Feb'25 | HS2: =HS1/1.18 -> 8165783.1 | HT2: Feb'25 | HU2: =SUBTOTAL(9,HU4:HU135) -> 4212443.6 | HV2: Mar'25 | HW2: =HW1/1.18 -> 3373894.1 | HX2: Mar'25 | HY2: =HY1/1.18 -> 7021197.9 | HZ2: Mar'25 | IA2: =IA1/1.18 -> 10395092 | IC2: Mar'25 | IF2: =IF1/1.18 -> 1531075.4 | IG2: Mar'25 | IH2: =SUBTOTAL(9,IH4:IH135) -> 6534044.2 | II2: Apr'25 | IJ2: =IJ1/1.18 -> 1432262.5 | IK2: Apr'25 | IL2: =IL1/1.18 -> 6363792.9 | IM2: Apr'25 | IN2: =IN1/1.18 -> 7796055.4 | IP2: Apr'25 | IS2: =IS1/1.18 -> 887579.66 | IT2: Apr'25 | IU2: =SUBTOTAL(9,IU4:IU135) -> 4971318.1 | IZ2: 28th April | JB2: 28th April | JD2: 15th April | JJ2: May Pickup | JL2: Yet to picked | JN2: AZ+AMPM+Incoming | JS2: May'25 | JT2: =JT1/1.18 -> 915743.08 | JU2: May'25 | JV2: =JV1/1.18 -> 8406782.8 | JW2: May'25 | JX2: =JX1/1.18 -> 9322525.9 | JZ2: May'25 | KC2: =KC1/1.18 -> 887579.66 | KD2: Apr'25 | KE2: =SUBTOTAL(9,KE4:KE135) -> 6057257.5 | KJ2: 28th April | KL2: 28th April | KN2: 15th April | KT2: May Pickup | KV2: Yet to picked | KX2: AZ+AMPM+Incoming | LC2: June'25 | LD2: =LD1/1.18 -> 769781.71 | LE2: June'25 | LF2: =LF1/1.18 -> 8394089.6 | LG2: June'25 | LH2: =LH1/1.18 -> 9163871.3 | LJ2: June'25 | LM2: =LM1/1.18 -> 887579.66 | LN2: Apr'25 | LO2: =SUBTOTAL(9,LO4:LO135) -> 5356653.5 | LT2: 23rd June | LV2: 23rd June | LX2: 15th June | MB2: July | MD2: July Pickup | MF2: Yet to picked | MH2: AZ+AMPM+Incoming | MM2: July'25 | MN2: =MN1/1.18 -> 760879.66 | MO2: July'25 | MP2: =MP1/1.18 -> 10800227 | MQ2: July'25 | MR2: =MR1/1.18 -> 11561106 | MT2: July'25 | MW2: =MW1/1.18 -> 887579.66 | MX2: Apr'25 | MY2: =SUBTOTAL(9,MY4:MY135) -> 6912870.9 | ND2: 01st Aug | NF2: 28th July | NH2: 03rd July | NJ2: Aug | NL2: Aug | NN2: July Pickup | NP2: Yet to picked | NR2: AZ+AMPM+Incoming | NT2: 30th July | NX2: Aug'25 | NY2: =NY1/1.18 -> 1504993.4 | NZ2: Aug'25 | OA2: =OA1/1.18 -> 10589140 | OB2: Aug'25 | OC2: =OC1/1.18 -> 12094133 | OE2: Aug'25 | OH2: =OH1/1.18 -> 887579.66 | OI2: Apr'25 | OJ2: =SUBTOTAL(9,OJ4:OJ135) -> 7255025.4 | OO2: 1st Sept | OQ2: 1st Sept | OS2: 20th Aug | OU2: Sept | OW2: Sept | OY2: Sept Pickup | PA2: Yet to picked | PC2: AZ+AMPM+Incoming | PE2: 02nd Sept | PI2: Sept'25 | PJ2: =PJ1/1.18 -> 874254.95 | PK2: Sept'25 | PL2: =PL1/1.18 -> 14169624 | PM2: Sept'25 | PN2: =PN1/1.18 -> 15043879 | PP2: Sept'25 | PS2: =PS1/1.18 -> 887579.66 | PT2: Apr'25 | PU2: =SUBTOTAL(9,PU4:PU135) -> 9329963.8 | PZ2: 1st Sept | QB2: 1st Sept | QD2: 20th Aug | QF2: Sept | QH2: Sept | QJ2: Sept Pickup | QL2: Yet to picked | QN2: AZ+AMPM+Incoming | QP2: 02nd Sept | QT2: Oct'25 | QU2: =QU1/1.18 -> 1395703.4 | QV2: Oct'25 | QW2: =QW1/1.18 -> 14441477 | QX2: Oct'25 | QY2: =QY1/1.18 -> 15837181 | RA2: Oct'25 | RD2: =RD1/1.18 -> 887579.66 | RE2: Apr'25 | RF2: =SUBTOTAL(9,RF4:RF135) -> 9801564.8 | RK2: 03rd Nov | RM2: 03rd Nov | RO2: 29th Oct | RQ2: Oct | RS2: Oct | RU2: Oct Pickup | RW2: Yet to picked | RY2: AZ+AMPM+Incoming | SA2: 02nd Nov | SE2: Nov'25 | SF2: =SF1/1.18 -> 1396516.1 | SG2: Nov'25 | SH2: =SH1/1.18 -> 11831658 | SI2: Nov'25 | SJ2: =SJ1/1.18 -> 13228174 | SL2: Nov'25 | SO2: =SO1/1.18 -> 887579.66 | SP2: Apr'25 | SQ2: =SUBTOTAL(9,SQ4:SQ135) -> 7881033.7 | SV2: 01st Dec | SX2: 01st Dec | SZ2: 29th Oct | TB2: Dec | TD2: Dec | TF2: Dec | TH2: Yet to picked | TJ2: AZ+AMPM+Incoming | TL2: 04th Dec | TP2: Dec'25 | TQ2: =TQ1/1.18 -> 2340146.2 | TR2: Dec'25 | TS2: =TS1/1.18 -> 12008762 | TT2: Dec'25 | TU2: =TU1/1.18 -> 14348908 | TW2: Dec'25 | TZ2: =TZ1/1.18 -> 887579.66 | UA2: Apr'25 | UB2: =SUBTOTAL(9,UB4:UB135) -> 8691386.6 | UG2: 15th Dec | UI2: 13th Dec | UK2: 29th Oct | UM2: Dec | UO2: Dec | UQ2: Dec | US2: Yet to picked | UU2: AZ+AMPM+Incoming | UW2: 16th Dec | VA2: Jan'26 | VB2: =VB1/1.18 -> 2120891.9 | VC2: Jan'26 | VD2: =VD1/1.18 -> 12057467 | VE2: Jan'26 | VF2: =VF1/1.18 -> 14178359 | VH2: Jan'26 | VK2: =VK1/1.18 -> 903840.68 | VL2: Apr'25 | VM2: =SUBTOTAL(9,VM4:VM135) -> 8551426 | VR2: 3rd Feb | VT2: 3rd Feb | VV2: 04th Feb | VX2: Feb | VZ2: Feb | WB2: Feb | WD2: Yet to picked | WF2: AZ+AMPM+Incoming | WH2: 02nd Feb
A3: Asin | B3: SKU | C3: Updated Remarks - 03rd June | D3: Brand | E3: Product Code | F3: ASIN Classification | G3: OEM Model 0me | H3: Category | I3: Sub-Category | J3: NLC | K3: Supplier 0me | L3: Buybox | M3: AMB. Sales | N3: CCB sales | O3: Cambium Sales | P3: Total Sales | Q3: Buybox | R3: AMB. Sales | S3: CCB sales | T3: Cambium Sales | U3: Total Sales | V3: Buybox | W3: AMB. Sales | X3: CCB sales | Y3: Cambium Sales | Z3: Total Sales | AA3: Contribution to Sales | AB3: Buybox | AC3: AMB. Sales | AD3: CCB sales | AE3: Cambium Sales | AF3: Total Sales | AG3: Contribution to Sales | AH3: Buybox | AI3: AMB. Sales | AJ3: CCB sales | AK3: Cambium Sales | AL3: Total Sales | AM3: Contribution to Sales | AN3: Buybox | AO3: AMB. Sales | AP3: Cambium Sales | AQ3: Total Sales | AR3: Total Sales Value | AS3: Contribution to Sales | AT3: Buybox | AU3: AMB. Sales | AV3: Cambium Sales | AW3: Total Sales | AX3: Total Sales Value | AY3: Contribution to Sales | AZ3: Buybox | BA3: AMB. Sales | BB3: Cambium Sales | BC3: Total Sales | BD3: Total Sales Value | BE3: Contribution to Sales | BF3: Buybox | BG3: AMB. Sales | BH3: Cambium Sales | BI3: Total Sales | BJ3: Total Sales Value at DP | BK3: Contribution to Sales | BL3: Buybox | BM3: AMB. Sales | BN3: Cambium Sales | BO3: Total Sales | BP3: Total Sales Value at DP | BQ3: Contribution to Sales | BR3: Buybox | BS3: AMB. Sales | BT3: Amazon Sales Units | BU3: Amazon Sales Value | BV3: Amb. Sales Units | BW3: Amb. Sales Value | BX3: Flipkart Sales Units | BY3: Flipkart Sales Value | BZ3: Total Sales | CA3: Total Sales At SP | CB3: Contribution to Sales | CC3: Total Sales Value at DP | CD3: Amazon Sales Units | CE3: Amazon Sales Value | CF3: Amb. Sales Units | CG3: Amb. Sales Value | CH3: Flipkart Sales Units | CI3: Flipkart Sales Value | CJ3: Total Sales | CK3: Total Sales At SP | CL3: Contribution to Sales | CM3: Total Sales Value at DP | CN3: Amazon Sales Units | CO3: Amazon Sales Value | CP3: Amb. Sales Units | CQ3: Amb. Sales Value | CR3: Flipkart Sales Units | CS3: Flipkart Sales Value | CT3: Total Sales | CU3: Total Sales At SP | CV3: Contribution to Sales | CW3: Total Sales Value at DP | CX3: Amazon Sales Units | CY3: Amazon Sales Value | CZ3: Amb. Sales Units | DA3: Amb. Sales Value | DB3: Total Sales | DC3: Total Sales At SP | DD3: Contribution to Sales | DE3: Sessions | DF3: Gross Units Sold | DG3: Gross Sales Value | DH3: Total Sales Value at DP | DI3: Amazon Sales Units | DJ3: Amazon Sales Value | DK3: Amb. Sales Units | DL3: Amb. Sales Value | DM3: Total Sales | DN3: Total Sales At SP | DO3: Total Sales At SP (Without GST) | DP3: Contribution to Sales | DQ3: Sessions | DR3: Gross Units Sold | DS3: Gross Sales Value | DT3: Contribution to Sales | DU3: Total Sales Value at DP | DV3: Month On Month Growth (Gross Sales) | DW3: Month On Month Growth (Net Sales) | DX3: AMS Spend | DY3: AMS Orders | DZ3: AMS Sale | EA3: Acos | EB3: Tacos | EC3: Remarks | ED3: Action Point | EE3: Amazon Sales Units | EF3: Amazon Sales Value | EG3: Amb. Sales Units | EH3: Amb. Sales Value | EI3: Total Sales | EJ3: Total Sales At SP | EK3: Total Sales At SP (Without GST) | EL3: Contribution to Sales | EM3: Sessions | EN3: Gross Units Sold | EO3: Gross Sales Value | EP3: Contribution to Sales | EQ3: Total Sales Value at DP | ER3: Month On Month Growth (Gross Sales) | ES3: Month On Month Growth (Net Sales) | ET3: Remarks1 | EU3: Remarks2 | EV3: Amazon Sales Units | EW3: Amazon Sales Value | EX3: Amb. Sales Units | EY3: Amb. Sales Value | EZ3: Total Sales | FA3: Total Sales At SP | FB3: Total Sales At SP (Without GST) | FC3: Contribution to Sales | FD3: Sessions | FE3: Gross Units Sold | FF3: Gross Sales Value | FG3: Contribution to Sales | FH3: Total Sales Value at DP | FI3: Amazon Sales Units | FJ3: Amazon Sales Value | FK3: Amb. Sales Units | FL3: Amb. Sales Value | FM3: Total Sales | FN3: Total Sales At SP | FO3: Total Sales At SP (Without GST) | FP3: Contribution to Sales | FQ3: Sessions | FR3: Gross Units Sold | FS3: Gross Sales Value | FT3: Contribution to Sales | FU3: Total Sales Value at DP | FV3: Amazon Sales Units | FW3: Amazon Sales Value | FX3: Amb. Sales Units | FY3: Amb. Sales Value | FZ3: Total Sales | GA3: Total Sales At SP | GB3: Total Sales At SP (Without GST) | GC3: Contribution to Sales | GD3: Sessions | GE3: Gross Units Sold | GF3: Gross Sales Value | GG3: Contribution to Sales | GH3: Total Sales Value at NLC | GI3: Amazon Sales Units | GJ3: Amazon Sales Value | GK3: Amb. Sales Units | GL3: Amb. Sales Value | GM3: Total Sales | GN3: Total Sales At SP | GO3: Total Sales At SP (Without GST) | GP3: Contribution to Sales | GQ3: Sessions | GR3: Gross Units Sold | GS3: Gross Sales Value | GT3: Contribution to Sales | GU3: Total Sales Value at NLC | GV3: Amazon Sales Units | GW3: Amazon Sales Value | GX3: Amb. Sales Units | GY3: Amb. Sales Value | GZ3: Total Sales | HA3: Total Sales At SP | HB3: Total Sales At SP (Without GST) | HC3: Contribution to Sales | HD3: Sessions | HE3: Gross Units Sold | HF3: Gross Sales Value | HG3: Contribution to Sales | HH3: Total Sales Value at NLC | HI3: Amazon Sales Units | HJ3: Amazon Sales Value | HK3: Amb. Sales Units | HL3: Amb. Sales Value | HM3: Total Sales | HN3: Total Sales At SP | HO3: Total Sales At SP (Without GST) | HP3: Contribution to Sales | HQ3: Sessions | HR3: Gross Units Sold | HS3: Gross Sales Value | HT3: Contribution to Sales | HU3: Total Sales Value at NLC | HV3: Amazon Sales Units | HW3: Amazon Sales Value | HX3: CCB. Sales Units | HY3: CCB. Sales Value | HZ3: Total Sales | IA3: Total Sales At SP | IB3: Total Sales At SP (Without GST) | IC3: Contribution to Sales | ID3: Sessions | IE3: Gross Units Sold | IF3: Gross Sales Value | IG3: Contribution to Sales | IH3: Total Sales Value at NLC | II3: Amazon Sales Units | IJ3: Amazon Sales Value | IK3: CCB. Sales Units | IL3: CCB. Sales Value | IM3: Total Sales | IN3: Total Sales At SP | IO3: Total Sales At SP (Without GST) | IP3: Contribution to Sales | IQ3: Sessions | IR3: Gross Units Sold | IS3: Gross Sales Value | IT3: Contribution to Sales | IU3: Total Sales Value at NLC | IV3: =E3 -> Product Code | IW3: =A3 -> Asin | IX3: =B3 -> SKU | IY3: NLC | IZ3: AZ Soh | JA3: Value | JB3: AMPM | JC3: Value | JD3: Recalled Units (Andheri+AMPM) | JE3: Value | JF3: CHA Intransit Qty | JG3: Value | JH3: Incom. Shipments | JI3: Value | JJ3: Pipeline Qty | JK3: Value | JL3: Yet to picked | JM3: Value | JN3: Total SOH - Az+AMPM+Recall+CHA Intransit+Incomm+Pending Pickup | JO3: SOH Value | JP3: =E3 -> Product Code | JQ3: ASIN Classification | JR3: NLC | JS3: Amazon Sales Units | JT3: Amazon Sales Value | JU3: CCB. Sales Units | JV3: CCB. Sales Value | JW3: Total Sales | JX3: Total Sales At SP | JY3: Total Sales At SP (Without GST) | JZ3: Contribution to Sales | KA3: Sessions | KB3: Gross Units Sold | KC3: Gross Sales Value | KD3: Contribution to Sales | KE3: Total Sales Value at NLC | KF3: =E3 -> Product Code | KG3: =A3 -> Asin | KH3: =B3 -> SKU | KI3: NLC | KJ3: AZ Soh | KK3: Value | KL3: AMPM | KM3: Value | KN3: Recalled Units (Andheri+AMPM) | KO3: Value | KP3: CHA Intransit Qty | KQ3: Value | KR3: Incom. Shipments | KS3: Value | KT3: Pipeline Qty | KU3: Value | KV3: Yet to picked | KW3: Value | KX3: Total SOH - Az+AMPM+Recall+CHA Intransit+Incomm+Pending Pickup | KY3: SOH Value | KZ3: =E3 -> Product Code | LA3: ASIN Classification | LB3: NLC | LC3: Amazon Sales Units | LD3: Amazon Sales Value | LE3: CCB. Sales Units | LF3: CCB. Sales Value | LG3: Total Sales | LH3: Total Sales At SP | LI3: Total Sales At SP (Without GST) | LJ3: Contribution to Sales | LK3: Sessions | LL3: Gross Units Sold | LM3: Gross Sales Value | LN3: Contribution to Sales | LO3: Total Sales Value at NLC | LP3: =E3 -> Product Code | LQ3: =A3 -> Asin | LR3: =B3 -> SKU | LS3: NLC | LT3: AZ Soh | LU3: Value | LV3: AMPM | LW3: Value | LX3: Recalled Units (Andheri+AMPM) | LY3: Value | LZ3: CHA Intransit Qty | MA3: Value | MB3: Incom. Shipments | MC3: Value | MD3: Pipeline Qty | ME3: Value | MF3: Yet to picked | MG3: Value | MH3: Total SOH - Az+AMPM+Recall+CHA Intransit+Incomm+Pending Pickup | MI3: SOH Value | MJ3: =E3 -> Product Code | MK3: ASIN Classification | ML3: NLC | MM3: Amazon Sales Units | MN3: Amazon Sales Value | MO3: CCB. Sales Units | MP3: CCB. Sales Value | MQ3: Total Sales | MR3: Total Sales At SP | MS3: Total Sales At SP (Without GST) | MT3: Contribution to Sales | MU3: Sessions | MV3: Gross Units Sold | MW3: Gross Sales Value | MX3: Contribution to Sales | MY3: Total Sales Value at NLC | MZ3: =E3 -> Product Code | NA3: =A3 -> Asin | NB3: =B3 -> SKU | NC3: NLC | ND3: AZ Soh | NE3: Value | NF3: AMPM | NG3: Value | NH3: Recalled Units (Andheri+AMPM) | NI3: Value | NJ3: CHA Intransit Qty | NK3: Value | NL3: Incom. Shipments | NM3: Value | NN3: Pipeline Qty | NO3: Value | NP3: Yet to picked | NQ3: Value | NR3: Total SOH - Az+AMPM+Recall+CHA Intransit+Incomm+Pending Pickup | NS3: SOH Value | NT3: CB Stock | NU3: =E3 -> Product Code | NV3: ASIN Classification | NW3: NLC | NX3: Amazon Sales Units | NY3: Amazon Sales Value | NZ3: CCB. Sales Units | OA3: CCB. Sales Value | OB3: Total Sales | OC3: Total Sales At SP | OD3: Total Sales At SP (Without GST) | OE3: Contribution to Sales | OF3: Sessions | OG3: Gross Units Sold | OH3: Gross Sales Value | OI3: Contribution to Sales | OJ3: Total Sales Value at NLC | OK3: =E3 -> Product Code | OL3: =A3 -> Asin | OM3: =B3 -> SKU | ON3: NLC | OO3: AZ Soh | OP3: Value | OQ3: AMPM | OR3: Value | OS3: Recalled Units (Andheri+AMPM) | OT3: Value | OU3: CHA Intransit Qty | OV3: Value | OW3: Incom. Shipments | OX3: Value | OY3: Pipeline Qty | OZ3: Value | PA3: Yet to picked | PB3: Value | PC3: Total SOH - Az+AMPM+Recall+CHA Intransit+Incomm+Pending Pickup | PD3: SOH Value | PE3: CB Stock | PF3: =E3 -> Product Code | PG3: ASIN Classification | PH3: NLC | PI3: Amazon Sales Units | PJ3: Amazon Sales Value | PK3: CCB. Sales Units | PL3: CCB. Sales Value | PM3: Total Sales | PN3: Total Sales At SP | PO3: Total Sales At SP (Without GST) | PP3: Contribution to Sales | PQ3: Sessions | PR3: Gross Units Sold | PS3: Gross Sales Value | PT3: Contribution to Sales | PU3: Total Sales Value at NLC | PV3: =E3 -> Product Code | PW3: =A3 -> Asin | PX3: =B3 -> SKU | PY3: NLC | PZ3: AZ Soh | QA3: Value | QB3: AMPM | QC3: Value | QD3: Recalled Units (Andheri+AMPM) | QE3: Value | QF3: CHA Intransit Qty | QG3: Value | QH3: Incom. Shipments | QI3: Value | QJ3: Pipeline Qty | QK3: Value | QL3: Yet to picked | QM3: Value | QN3: Total SOH - Az+AMPM+Recall+CHA Intransit+Incomm+Pending Pickup | QO3: SOH Value | QP3: CB Stock | QQ3: =E3 -> Product Code | QR3: ASIN Classification | QS3: NLC | QT3: Amazon Sales Units | QU3: Amazon Sales Value | QV3: CCB. Sales Units | QW3: CCB. Sales Value | QX3: Total Sales | QY3: Total Sales At SP | QZ3: Total Sales At SP (Without GST) | RA3: Contribution to Sales | RB3: Sessions | RC3: Gross Units Sold | RD3: Gross Sales Value | RE3: Contribution to Sales | RF3: Total Sales Value at NLC | RG3: =E3 -> Product Code | RH3: =A3 -> Asin | RI3: =B3 -> SKU | RJ3: NLC | RK3: AZ Soh | RL3: Value | RM3: AMPM | RN3: Value | RO3: Recalled Units (Andheri+AMPM) | RP3: Value | RQ3: CHA Intransit Qty | RR3: Value | RS3: Incom. Shipments | RT3: Value | RU3: Pipeline Qty | RV3: Value | RW3: Yet to picked | RX3: Value | RY3: Total SOH - Az+AMPM+Recall+CHA Intransit+Incomm+Pending Pickup | RZ3: SOH Value | SA3: CB Stock | SB3: =E3 -> Product Code | SC3: ASIN Classification | SD3: NLC | SE3: Amazon Sales Units | SF3: Amazon Sales Value | SG3: CCB. Sales Units | SH3: CCB. Sales Value | SI3: Total Sales | SJ3: Total Sales At SP | SK3: Total Sales At SP (Without GST) | SL3: Contribution to Sales | SM3: Sessions | SN3: Gross Units Sold | SO3: Gross Sales Value | SP3: Contribution to Sales | SQ3: Total Sales Value at NLC | SR3: =E3 -> Product Code | SS3: =A3 -> Asin | ST3: =B3 -> SKU | SU3: NLC | SV3: AZ Soh | SW3: Value | SX3: AMPM | SY3: Value | SZ3: Recalled Units (Andheri+AMPM) | TA3: Value | TB3: CHA Intransit Qty | TC3: Value | TD3: Incom. Shipments | TE3: Value | TF3: Pipeline Qty | TG3: Value | TH3: Yet to picked | TI3: Value | TJ3: Total SOH - Az+AMPM+Recall+CHA Intransit+Incomm+Pending Pickup | TK3: SOH Value | TL3: CB Stock | TM3: =E3 -> Product Code | TN3: ASIN Classification | TO3: NLC | TP3: Amazon Sales Units | TQ3: Amazon Sales Value | TR3: CCB. Sales Units | TS3: CCB. Sales Value | TT3: Total Sales | TU3: Total Sales At SP | TV3: Total Sales At SP (Without GST) | TW3: Contribution to Sales | TX3: Sessions | TY3: Gross Units Sold | TZ3: Gross Sales Value | UA3: Contribution to Sales | UB3: Total Sales Value at NLC | UC3: =E3 -> Product Code | UD3: =A3 -> Asin | UE3: =B3 -> SKU | UF3: NLC | UG3: AZ Soh | UH3: Value | UI3: AMPM | UJ3: Value | UK3: Recalled Units (Andheri+AMPM) | UL3: Value | UM3: CHA Intransit Qty | UN3: Value | UO3: Incom. Shipments | UP3: Value | UQ3: Pipeline Qty | UR3: Value | US3: Yet to picked | UT3: Value | UU3: Total SOH - Az+AMPM+Recall+CHA Intransit+Incomm+Pending Pickup | UV3: SOH Value | UW3: CB Stock | UX3: =E3 -> Product Code | UY3: ASIN Classification | UZ3: NLC | VA3: Amazon Sales Units | VB3: Amazon Sales Value | VC3: CCB. Sales Units | VD3: CCB. Sales Value | VE3: Total Sales | VF3: Total Sales At SP | VG3: Total Sales At SP (Without GST) | VH3: Contribution to Sales | VI3: Sessions | VJ3: Gross Units Sold | VK3: Gross Sales Value | VL3: Contribution to Sales | VM3: Total Sales Value at NLC | VN3: =E3 -> Product Code | VO3: =A3 -> Asin | VP3: =B3 -> SKU | VQ3: NLC | VR3: AZ Soh | VS3: Value | VT3: AMPM | VU3: Value | VV3: Recalled Units (Andheri+AMPM) | VW3: Value | VX3: CHA Intransit Qty | VY3: Value | VZ3: Incom. Shipments | WA3: Value | WB3: Pipeline Qty | WC3: Value | WD3: Yet to picked | WE3: Value | WF3: Total SOH - Az+AMPM+Recall+CHA Intransit+Incomm+Pending Pickup | WG3: SOH Value | WH3: CB Stock | WI3: =E3 -> Product Code | WJ3: ASIN Classification | WK3: NLC
A4: B0BPLZ5CGV | B4: FBA76864 | C4: Head | D4: Audio Array | E4: AI-04 Red | F4: Head | G4: ZS22U | H4: Audio Interface | I4: Audio Interface | J4: 2038.7371 | K4: Zimhome (Lucas) | L4: 0.9825 | M4: 0 | N4: 1 | O4: 6 | P4: =M4+N4+O4 -> 7 | Q4: 0.9949 | R4: 0 | S4: 0 | T4: 44 | U4: =R4+S4+T4 -> 44 | V4: 0.8107 | W4: 0 | X4: 17 | Y4: 86 | Z4: =W4+X4+Y4 -> 103 | AA4: =Z4/$Z$1 -> 0.088564058 | AB4: 0.8413 | AC4: 0 | AD4: 31 | AE4: 145 | AF4: =AC4+AD4+AE4 -> 176 | AG4: =AF4/$AF$1 -> 0.13124534 | AH4: 0.971 | AI4: 0 | AJ4: 1 | AK4: 89 | AL4: =AI4+AJ4+AK4 -> 90 | AM4: =AL4/$AL$1 -> 0.076400679 | AN4: 0.9949 | AO4: 0 | AP4: 227 | AQ4: =AO4+AP4 -> 227 | AR4: =AQ4*#REF! -> #REF! | AS4: =AR4/$AR$1 -> #REF! | AT4: 0.9324 | AU4: 10 | AV4: 182 | AW4: =AU4+AV4 -> 192 | AX4: =AW4*#REF! -> #REF! | AY4: =AX4/$AX$1 -> #REF! | AZ4: 0.9694 | BA4: 1 | BB4: 166 | BC4: =BA4+BB4 -> 167 | BD4: =BC4*#REF! -> #REF! | BE4: =BD4/$BD$1 -> #REF! | BF4: 0.9603 | BG4: 2 | BH4: 166 | BI4: =BG4+BH4 -> 168 | BJ4: =BI4*#REF! -> #REF! | BK4: =BJ4/$BJ$1 -> #REF! | BL4: 0.9121 | BM4: 0 | BN4: 84 | BO4: =BM4+BN4 -> 84 | BP4: =BO4*#REF! -> #REF! | BQ4: =BP4/$BP$1 -> #REF! | BR4: 0.9745 | BS4: 0 | BT4: 93 | BU4: 437106 | BV4: 1 | BW4: 5499 | BX4: 17 | BY4: 80523 | BZ4: =BS4+BT4+BX4+BV4 -> 111 | CA4: =BY4+BU4+BW4 -> 523128 | CB4: =CA4/$CA$1 -> 0.063934335 | CC4: =BZ4*#REF! -> #REF! | CD4: 83 | CE4: 391213 | CF4: 1 | CG4: 4699 | CH4: 68 | CI4: 244732 | CJ4: =CD4+CH4+CF4 -> 152 | CK4: =CI4+CE4+CG4 -> 640644 | CL4: =CK4/$CK$1 -> 0.08647456 | CM4: =CJ4*#REF! -> #REF! | CN4: 103 | CO4: 484640.58 | CP4: 0 | CQ4: 0 | CR4: 34 | CS4: 136654 | CT4: =CN4+CR4+CP4 -> 137 | CU4: =CS4+CO4+CQ4 -> 621294.58 | CV4: =CU4/$CU$1 -> 0.087806033 | CW4: =CT4*#REF! -> #REF! | CX4: 149 | CY4: 698210.16 | CZ4: 0 | DA4: 0 | DB4: =CX4+CZ4 -> 149 | DC4: =CY4+DA4 -> 698210.16 | DD4: =DC4/$DC$1 -> 0.091231552 | DE4: 18631 | DF4: 190 | DG4: 817626 | DH4: =DB4*#REF! -> #REF! | DI4: 101 | DJ4: 465903.58 | DK4: 0 | DL4: 0 | DM4: =DI4+DK4 -> 101 | DN4: =DJ4+DL4 -> 465903.58 | DO4: =DN4/1.18 -> 394833.54 | DP4: =DN4/$DN$1 -> 0.053363603 | DQ4: 16563 | DR4: 141 | DS4: 593122 | DT4: =DS4/$DS$1 -> 0.059206795 | DU4: =DM4*#REF! -> #REF! | DV4: =(DR4-DF4)/DF4 -> -0.25789474 | DW4: =(DM4-DB4)/DB4 -> -0.32214765 | DX4: 71125.03 | DY4: 172 | DZ4: 583195.59 | EA4: =DX4/DZ4 -> 0.12195742 | EB4: =DX4/DO4 -> 0.18013928 | EC4: Decrese in Footfall by 2K | ED4: AMS recheck, Meta promo., 1% coupon & Customer review | EE4: 145 | EF4: 647476.04 | EG4: 3 | EH4: 13197 | EI4: =EE4+EG4 -> 148 | EJ4: =EF4+EH4 -> 660673.04 | EK4: =EJ4/1.18 -> 559892.41 | EL4: =EJ4/$EJ$1 -> 0.067035106 | EM4: 19473 | EN4: 219 | EO4: 869729 | EP4: =EO4/$EO$1 -> 0.076797514 | EQ4: =EI4*#REF! -> #REF! | ER4: =(EN4-DR4)/DR4 -> 0.55319149 | ES4: =(EI4-DM4)/DM4 -> 0.46534653 | EV4: 394 | EW4: 1689291.3 | EX4: 0 | EY4: 0 | EZ4: =EV4+EX4 -> 394 | FA4: =EW4+EY4 -> 1689291.3 | FB4: =FA4/1.18 -> 1431602.8 | FC4: =FA4/$FA$1 -> 0.16494653 | FD4: 29522 | FE4: 619 | FF4: 2405259 | FG4: =FF4/$FF$1 -> 0.18300401 | FH4: =EZ4*#REF! -> #REF! | FI4: 566 | FJ4: 2298409.9 | FK4: 2 | FL4: 7998 | FM4: =FI4+FK4 -> 568 | FN4: =FJ4+FL4 -> 2306407.9 | FO4: =FN4/1.18 -> 1954582.9 | FP4: =FN4/$FN$1 -> 0.17796948 | FQ4: 40432 | FR4: 821 | FS4: 3024056 | FT4: =FS4/$FS$1 -> 0.17969321 | FU4: =FM4*#REF! -> #REF! | FV4: 369 | FW4: 1558227.8 | FX4: 0 | FY4: 0 | FZ4: =FV4+FX4 -> 369 | GA4: =FW4+FY4 -> 1558227.8 | GB4: =GA4/1.18 -> 1320532 | GC4: =GA4/$GA$1 -> 0.14315899 | GD4: 31209 | GE4: 496 | GF4: 1943744 | GG4: =GF4/$GF$1 -> 0.15802345 | GH4: =J4*FZ4 -> 752293.98 | GI4: 321 | GJ4: 1375897.3 | GM4: =GI4+GK4 -> 321 | GN4: =GJ4+GL4 -> 1375897.3 | GO4: =GN4/1.18 -> 1166014.7 | GP4: =GN4/$GN$1 -> 0.15307181 | GQ4: 22124 | GR4: 415 | GS4: 1592898 | GT4: =GS4/$GS$1 -> 0.15109328 | GU4: =J4*GM4 -> 654434.6 | GV4: 260 | GW4: 1046390.8 | GZ4: =GV4+GX4 -> 260 | HA4: =GW4+GY4 -> 1046390.8 | HB4: =HA4/1.18 -> 886771.9 | HC4: =HA4/$HA$1 -> 0.1255163 | HD4: 27884 | HE4: 510 | HF4: 1985633 | HG4: =HF4/$HF$1 -> 0.1722569 | HH4: =J4*GZ4 -> 530071.64 | HI4: 397 | HJ4: 1667301.6 | HM4: =HI4+HK4 -> 397 | HN4: =HJ4+HL4 -> 1667301.6 | HO4: =HN4/1.18 -> 1412967.5 | HP4: =HN4/$HN$1 -> 0.19905961 | HQ4: 31418 | HR4: 512 | HS4: 1962073 | HT4: =HS4/$HS$1 -> 0.20362698 | HU4: =J4*HM4 -> 809378.61 | HV4: 170 | HW4: 724970 | HX4: 471 | HY4: 2047529.4 | HZ4: =HV4+HX4 -> 641 | IA4: =HW4+HY4 -> 2772499.4 | IB4: =IA4/1.18 -> 2349575.8 | IC4: =IA4/$IA$1 -> 0.22602741 | ID4: 28144 | IE4: 82 | IF4: 274498 | IG4: =IF4/$IF$1 -> 0.15193597 | IH4: =IY4*HZ4 -> 1388381.1 | II4: 61 | IJ4: 271376 | IK4: 363 | IL4: 1579169.6 | IM4: =II4+IK4 -> 424 | IN4: =IJ4+IL4 -> 1850545.6 | IO4: =IN4/1.18 -> 1568259 | IP4: =IN4/$IN$1 -> 0.20116058 | IQ4: 23644 | IR4: 73 | IS4: 302349 | IT4: =IS4/$IS$1 -> 0.28868166 | IU4: =IY4*IM4 -> 918367.52 | IV4: =E4 -> AI-04 Red | IW4: =A4 -> B0BPLZ5CGV | IX4: =B4 -> FBA76864 | IY4: 2165.9611 | IZ4: 224 | JA4: =IZ4*IY4 -> 485175.29 | JB4: 428 | JC4: =JB4*IY4 -> 927031.36 | JD4: 53 | JE4: =JD4*IY4 -> 114795.94 | JF4: 0 | JG4: =JF4*IY4 -> 0 | JH4: 0 | JI4: =JH4*IY4 -> 0 | JJ4: 2005 | JK4: =JJ4*IY4 -> 4342752 | JL4: 2000 | JM4: =JL4*IY4 -> 4331922.2 | JN4: =IZ4+JB4+JH4+JD4+JF4+JJ4+JL4 -> 4710 | JO4: =JN4*IY4 -> 10201677 | JP4: =E4 -> AI-04 Red | JQ4: =C4 -> Head | JR4: 2165.9611 | JS4: 12 | JT4: 51453.48 | JU4: 473 | JV4: 2051907.5 | JW4: =JS4+JU4 -> 485 | JX4: =JT4+JV4 -> 2103360.9 | JY4: =JX4/1.18 -> 1782509.3 | JZ4: =JX4/$JX$1 -> 0.19120454 | KA4: 27717 | KB4: 73 | KC4: 302349 | KD4: =KC4/$IS$1 -> 0.28868166 | KE4: =KI4*JW4 -> 1050491.1 | KF4: =E4 -> AI-04 Red | KG4: =A4 -> B0BPLZ5CGV | KH4: =B4 -> FBA76864 | KI4: 2165.9611 | KJ4: 154 | KK4: =KJ4*KI4 -> 333558.01 | KL4: 15 | KM4: =KL4*KI4 -> 32489.417 | KN4: 53 | KO4: =KN4*KI4 -> 114795.94 | KP4: 0 | KQ4: =KP4*KI4 -> 0 | KR4: 0 | KS4: =KR4*KI4 -> 0 | KT4: 2005 | KU4: =KT4*KI4 -> 4342752 | KV4: 2000 | KW4: =KV4*KI4 -> 4331922.2 | KX4: =KJ4+KL4+KR4+KN4+KP4+KT4+KV4 -> 4227 | KY4: =KX4*KI4 -> 9155517.7 | KZ4: =E4 -> AI-04 Red | LA4: =C4 -> Head | LB4: 2165.9611 | LC4: 4 | LD4: 18047 | LE4: 490 | LF4: 2155069.8 | LG4: =LC4+LE4 -> 494 | LH4: =LD4+LF4 -> 2173116.8 | LI4: =LH4/1.18 -> 1841624.4 | LJ4: =LH4/$LH$1 -> 0.20096577 | LK4: 29791 | LL4: 73 | LM4: 302349 | LN4: =LM4/$IS$1 -> 0.28868166 | LO4: =LS4*LG4 -> 1007136.1 | LP4: =E4 -> AI-04 Red | LQ4: =A4 -> B0BPLZ5CGV | LR4: =B4 -> FBA76864 | LS4: 2038.7371 | LT4: 144 | LU4: =LT4*LS4 -> 293578.14 | LV4: 1404 | LW4: =LV4*LS4 -> 2862386.8 | LX4: 0 | LY4: =LX4*LS4 -> 0 | LZ4: 0 | MA4: =LZ4*LS4 -> 0 | MB4: 0 | MC4: =MB4*LS4 -> 0 | MD4: 2000 | ME4: =MD4*LS4 -> 4077474.1 | MF4: 0 | MG4: =MF4*LS4 -> 0 | MH4: =LT4+LV4+MB4+LX4+LZ4+MD4+MF4 -> 3548 | MI4: =MH4*LS4 -> 7233439.1 | MJ4: =E4 -> AI-04 Red | MK4: Head | ML4: 2038.7371 | MM4: 6 | MN4: 26771 | MO4: 685 | MP4: 2974015.7 | MQ4: =MM4+MO4 -> 691 | MR4: =MN4+MP4 -> 3000786.7 | MS4: =MR4/1.18 -> 2543039.6 | MT4: =MR4/$MR$1 -> 0.21996507 | MU4: 38774 | MV4: 73 | MW4: 302349 | MX4: =MW4/$IS$1 -> 0.28868166 | MY4: =MQ4*NC4 -> 1408767.3 | MZ4: =E4 -> AI-04 Red | NA4: =A4 -> B0BPLZ5CGV | NB4: =B4 -> FBA76864 | NC4: =J4 -> 2038.7371 | ND4: 227 | NE4: =ND4*NC4 -> 462793.31 | NF4: 898 | NG4: =NF4*NC4 -> 1830785.9 | NH4: 0 | NI4: =NH4*NC4 -> 0 | NJ4: 0 | NK4: =NJ4*NC4 -> 0 | NL4: 0 | NM4: =NL4*NC4 -> 0 | NN4: 2000 | NO4: =NN4*NC4 -> 4077474.1 | NP4: 0 | NQ4: =NP4*NC4 -> 0 | NR4: =ND4+NF4+NL4+NH4+NJ4+NN4+NP4 -> 3125 | NS4: =NR4*NC4 -> 6371053.3 | NT4: 425 | NU4: =E4 -> AI-04 Red | NV4: Head | NW4: 2038.7371 | NX4: 10 | NY4: 45256 | NZ4: 574 | OA4: 2493229 | OB4: =NX4+NZ4 -> 584 | OC4: =NY4+OA4 -> 2538485 | OD4: =OC4/1.18 -> 2151258.5 | OE4: =OC4/$OC$1 -> 0.1778762 | OF4: 35946 | OG4: 73 | OH4: 302349 | OI4: =OH4/$IS$1 -> 0.28868166 | OJ4: =OB4*ON4 -> 1190622.4 | OK4: =E4 -> AI-04 Red | OL4: =A4 -> B0BPLZ5CGV | OM4: =B4 -> FBA76864 | ON4: =J4 -> 2038.7371 | OO4: 191 | OP4: =OO4*ON4 -> 389398.78 | OQ4: 1206 | OR4: =OQ4*ON4 -> 2458716.9 | OS4: 0 | OT4: =OS4*ON4 -> 0 | OU4: 0 | OV4: =OU4*ON4 -> 0 | OW4: 0 | OX4: =OW4*ON4 -> 0 | OY4: 0 | OZ4: =OY4*ON4 -> 0 | PA4: 2010 | PB4: =PA4*ON4 -> 4097861.5 | PC4: =OO4+OQ4+OW4+OS4+OU4+OY4+PA4 -> 3407 | PD4: =PC4*ON4 -> 6945977.2 | PE4: 1286 | PF4: =E4 -> AI-04 Red | PG4: Head | PH4: 2038.7371 | PI4: 1 | PJ4: 4663 | PK4: 657 | PL4: 2795531.5 | PM4: =PI4+PK4 -> 658 | PN4: =PJ4+PL4 -> 2800194.5 | PO4: =PN4/1.18 -> 2373046.2 | PP4: =PN4/$PN$1 -> 0.15774164 | PQ4: 41650 | PR4: 73 | PS4: 302349 | PT4: =PS4/$IS$1 -> 0.28868166 | PU4: =PM4*PY4 -> 1341489 | PV4: =E4 -> AI-04 Red | PW4: =A4 -> B0BPLZ5CGV | PX4: =B4 -> FBA76864 | PY4: =J4 -> 2038.7371 | PZ4: 108 | QA4: =PZ4*PY4 -> 220183.6 | QC4: =QB4*PY4 -> 0 | QD4: 0 | QE4: =QD4*PY4 -> 0 | QF4: 0 | QG4: =QF4*PY4 -> 0 | QH4: 0 | QI4: =QH4*PY4 -> 0 | QJ4: 0 | QK4: =QJ4*PY4 -> 0 | QL4: 2010 | QM4: =QL4*PY4 -> 4097861.5 | QN4: =PZ4+QB4+QH4+QD4+QF4+QJ4+QL4 -> 2118 | QO4: =QN4*PY4 -> 4318045.1 | QP4: 1089 | QQ4: =E4 -> AI-04 Red | QR4: Head | QS4: 2038.7371 | QT4: 1 | QU4: 4839 | QV4: 670 | QW4: 2806526 | QX4: =QT4+QV4 -> 671 | QY4: =QU4+QW4 -> 2811365 | QZ4: =QY4/1.18 -> 2382512.7 | RA4: =QY4/$QY$1 -> 0.15043793 | RB4: 40727 | RC4: 73 | RD4: 302349 | RE4: =RD4/$IS$1 -> 0.28868166 | RF4: =QX4*RJ4 -> 1367992.6 | RG4: =E4 -> AI-04 Red | RH4: =A4 -> B0BPLZ5CGV | RI4: =B4 -> FBA76864 | RJ4: =J4 -> 2038.7371 | RK4: 31 | RL4: =RK4*RJ4 -> 63200.849 | RM4: 2736 | RN4: =RM4*RJ4 -> 5577984.6 | RO4: 28 | RP4: =RO4*RJ4 -> 57084.638 | RQ4: 0 | RR4: =RQ4*RJ4 -> 0 | RS4: 0 | RT4: =RS4*RJ4 -> 0 | RU4: 0 | RV4: =RU4*RJ4 -> 0 | RW4: 0 | RX4: =RW4*RJ4 -> 0 | RY4: =RK4+RM4+RS4+RO4+RQ4+RU4+RW4 -> 2795 | RZ4: =RY4*RJ4 -> 5698270.1 | SA4: 577 | SB4: =E4 -> AI-04 Red | SC4: Head | SD4: =J4 -> 2038.7371 | SE4: 1 | SF4: 4663 | SG4: 514 | SH4: 2260796 | SI4: =SE4+SG4 -> 515 | SJ4: =SF4+SH4 -> 2265459 | SK4: =SJ4/1.18 -> 1919880.5 | SL4: =SJ4/$SJ$1 -> 0.14513572 | SM4: 115510 | SN4: 73 | SO4: 302349 | SP4: =SO4/$IS$1 -> 0.28868166 | SQ4: =SI4*SU4 -> 1049949.6 | SR4: =E4 -> AI-04 Red | SS4: =A4 -> B0BPLZ5CGV | ST4: =B4 -> FBA76864 | SU4: =J4 -> 2038.7371 | SV4: 299 | SW4: =SV4*SU4 -> 609582.38 | SX4: 2121 | SY4: =SX4*SU4 -> 4324161.3 | SZ4: 28 | TA4: =SZ4*SU4 -> 57084.638 | TB4: 0 | TC4: =TB4*SU4 -> 0 | TD4: 0 | TE4: =TD4*SU4 -> 0 | TF4: 0 | TG4: =TF4*SU4 -> 0 | TH4: 0 | TI4: =TH4*SU4 -> 0 | TJ4: =SV4+SX4+TD4+SZ4+TB4+TF4+TH4 -> 2448 | TK4: =TJ4*SU4 -> 4990828.3 | TL4: 639 | TM4: =E4 -> AI-04 Red | TN4: Head | TO4: =J4 -> 2038.7371 | TP4: 2 | TQ4: 4839 | TR4: 660 | TS4: 2892346.1 | TT4: =TP4+TR4 -> 662 | TU4: =TQ4+TS4 -> 2897185.1 | TV4: =TU4/1.18 -> 2455241.6 | TW4: =TU4/$TU$1 -> 0.17110999 | TX4: 107526 | TY4: 73 | TZ4: 302349 | UA4: =TZ4/$IS$1 -> 0.28868166 | UB4: =TT4*J4 -> 1349643.9 | UC4: =E4 -> AI-04 Red | UD4: =A4 -> B0BPLZ5CGV | UE4: =B4 -> FBA76864 | UF4: =J4 -> 2038.7371 | UG4: 268 | UH4: =UG4*J4 -> 546381.53 | UI4: 968 | UJ4: =UI4*J4 -> 1973497.5 | UK4: 28 | UL4: =UK4*J4 -> 57084.638 | UM4: 0 | UN4: =UM4*J4 -> 0 | UO4: 0 | UP4: =UO4*J4 -> 0 | UQ4: 0 | UR4: =UQ4*J4 -> 0 | US4: 0 | UT4: =US4*J4 -> 0 | UU4: =UG4+UI4+UO4+UK4+UM4+UQ4+US4 -> 1264 | UV4: =UU4*J4 -> 2576963.6 | UW4: 1027 | UX4: =E4 -> AI-04 Red | UY4: Head | UZ4: =J4 -> 2038.7371 | VA4: 11 | VB4: 44654 | VC4: 668 | VD4: 2989104.2 | VE4: =VA4+VC4 -> 679 | VF4: =VB4+VD4 -> 3033758.2 | VG4: =VF4/1.18 -> 2570981.5 | VH4: =VF4/$VF$1 -> 0.18133138 | VI4: 139681 | VJ4: 73 | VK4: 302349 | VL4: =VK4/$IS$1 -> 0.28868166 | VM4: =VE4*J4 -> 1384302.5 | VN4: =E4 -> AI-04 Red | VO4: =A4 -> B0BPLZ5CGV | VP4: =B4 -> FBA76864 | VQ4: =J4 -> 2038.7371 | VR4: 280 | VS4: =VR4*J4 -> 570846.38 | VT4: 498 | VU4: =VT4*J4 -> 1015291.1 | VV4: 6 | VW4: =VV4*J4 -> 12232.422 | VX4: 0 | VY4: =VX4*J4 -> 0 | VZ4: 0 | WA4: =VZ4*J4 -> 0 | WB4: 0 | WC4: =WB4*J4 -> 0 | WD4: 2010 | WE4: =WD4*J4 -> 4097861.5 | WF4: =VR4+VT4+VZ4+VV4+VX4+WB4+WD4 -> 2794 | WG4: =WF4*J4 -> 5696231.3 | WH4: 768 | WI4: =E4 -> AI-04 Red | WJ4: Head | WK4: =J4 -> 2038.7371
