Workbook

Sheet Monthly Sales
L1: =SUBTOTAL(9,L4:L18) -> 1 | M1: =SUBTOTAL(9,M4:M18) -> 1 | N1: =1-L1/M1 -> 0 | P1: =SUBTOTAL(9,P4:P20) -> 1 | Q1: =SUBTOTAL(9,Q4:Q20) -> 1 | R1: =1-P1/Q1 -> 0 | T1: =SUBTOTAL(9,T4:T29) -> 376 | U1: =SUBTOTAL(9,U4:U29) -> 450 | V1: =1-T1/U1 -> 0.16444444 | X1: =SUBTOTAL(9,X4:X63) -> 384 | Y1: =SUBTOTAL(9,Y4:Y63) -> 493 | Z1: =1-X1/Y1 -> 0.22109533 | AB1: =SUBTOTAL(9,AB4:AB63) -> 272 | AC1: =SUBTOTAL(9,AC4:AC63) -> 456 | AD1: =1-AB1/AC1 -> 0.40350877 | AF1: =SUBTOTAL(9,AF4:AF76) -> 327 | AG1: =SUBTOTAL(9,AG4:AG76) -> 394 | AH1: =1-AF1/AG1 -> 0.17005076 | AJ1: =SUBTOTAL(9,AJ4:AJ76) -> 639 | AK1: =SUBTOTAL(9,AK4:AK76) -> 781 | AL1: =1-AJ1/AK1 -> 0.18181818 | AN1: =SUBTOTAL(9,AN4:AN76) -> 1272 | AO1: =SUBTOTAL(9,AO4:AO76) -> 1559 | AP1: =1-AN1/AO1 -> 0.18409237 | AR1: =SUBTOTAL(9,AR4:AR76) -> 1640 | AS1: =SUBTOTAL(9,AS4:AS76) -> 1883 | AT1: =1-AR1/AS1 -> 0.12904939 | AV1: =SUBTOTAL(9,AV4:AV76) -> 3295 | AW1: =SUBTOTAL(9,AW4:AW76) -> 3922 | AZ1: =SUBTOTAL(9,AZ4:AZ76) -> 5280 | BA1: =SUBTOTAL(9,BA4:BA76) -> 6213 | BB1: =1-AZ1/BA1 -> 0.150169 | BD1: =SUBTOTAL(9,BD4:BD76) -> 5791 | BE1: =SUBTOTAL(9,BE4:BE76) -> 7417 | BF1: =1-BD1/BE1 -> 0.2192261 | BH1: =SUBTOTAL(9,BH4:BH96) -> 9440 | BI1: =SUBTOTAL(9,BI4:BI96) -> 10654 | BJ1: =1-BH1/BI1 -> 0.11394781 | BK1: =SUBTOTAL(9,BK4:BK96) -> 462097 | BL1: =SUBTOTAL(9,BL4:BL96) -> 6744 | BM1: =SUBTOTAL(9,BM4:BM96) -> 12278407 | BN1: =SUBTOTAL(9,BN4:BN96) -> 5905526.3 | BO1: =SUBTOTAL(9,BO4:BO96) -> 7836 | BP1: =SUBTOTAL(9,BP4:BP96) -> 13703901 | BQ1: =1-BL1/BO1 -> 0.13935681 | BR1: =SUBTOTAL(9,BR4:BR96) -> 1 | BT1: =SUBTOTAL(9,BT4:BT96) -> 22592 | BU1: =SUBTOTAL(9,BU4:BU96) -> 37467 | BV1: =SUBTOTAL(9,BV4:BV96) -> 15648 | BW1: =BT1+BU1+BV1 -> 75707 | BX1: =SUBTOTAL(9,BX4:BX96) -> 63188946 | BY1: =SUBTOTAL(9,BY4:BY96) -> 26150 | BZ1: =SUBTOTAL(9,BZ4:BZ96) -> 28664665 | CA1: =SUBTOTAL(9,CA4:CA96) -> 101857 | CB1: =SUBTOTAL(9,CB4:CB96) -> 91853611 | CG1: =SUBTOTAL(9,CG4:CG96) -> 402043 | CH1: =SUBTOTAL(9,CH4:CH96) -> 5869 | CI1: =SUBTOTAL(9,CI4:CI96) -> 11349955 | CJ1: =SUBTOTAL(9,CJ4:CJ96) -> 5442057.3 | CK1: =SUBTOTAL(9,CK4:CK96) -> 6843 | CL1: =SUBTOTAL(9,CL4:CL96) -> 12719046 | CM1: =1-CH1/CK1 -> 0.14233523 | CN1: =SUBTOTAL(9,CN4:CN96) -> 1 | CP1: =SUBTOTAL(9,CP4:CP96) -> 26111 | CQ1: =SUBTOTAL(9,CQ4:CQ96) -> 42042 | CR1: =SUBTOTAL(9,CR4:CR96) -> 15648 | CS1: =CP1+CQ1+CR1 -> 83801 | CT1: =SUBTOTAL(9,CT4:CT96) -> 72873566 | CU1: =SUBTOTAL(9,CU4:CU96) -> 26150 | CV1: =SUBTOTAL(9,CV4:CV96) -> 28664665 | CW1: =SUBTOTAL(9,CW4:CW96) -> 109951 | CX1: =SUBTOTAL(9,CX4:CX96) -> 1.0153823e+08 | DC1: =SUBTOTAL(9,DC4:DC96) -> 551472 | DD1: =SUBTOTAL(9,DD4:DD96) -> 6889 | DE1: =SUBTOTAL(9,DE4:DE96) -> 12611721 | DF1: =SUBTOTAL(9,DF4:DF96) -> 5998498.8 | DG1: =SUBTOTAL(9,DG4:DG96) -> 8113 | DH1: =SUBTOTAL(9,DH4:DH96) -> 14405977 | DI1: =1-DD1/DG1 -> 0.15086898 | DJ1: =SUBTOTAL(9,DJ4:DJ96) -> 1 | DL1: =SUBTOTAL(9,DL4:DL96) -> 23327 | DM1: =SUBTOTAL(9,DM4:DM96) -> 52543 | DN1: =SUBTOTAL(9,DN4:DN96) -> 15648 | DO1: =DL1+DM1+DN1 -> 91518 | DP1: =SUBTOTAL(9,DP4:DP96) -> 81641762 | DQ1: =SUBTOTAL(9,DQ4:DQ96) -> 26150 | DR1: =SUBTOTAL(9,DR4:DR96) -> 28664665 | DS1: =SUBTOTAL(9,DS4:DS96) -> 117668 | DT1: =SUBTOTAL(9,DT4:DT96) -> 1.1030643e+08 | DY1: =SUBTOTAL(9,DY4:DY96) -> 448589 | DZ1: =SUBTOTAL(9,DZ4:DZ96) -> 4589 | EA1: =SUBTOTAL(9,EA4:EA96) -> 8786637.3 | EB1: =SUBTOTAL(9,EB4:EB96) -> 4099840.1 | EC1: =SUBTOTAL(9,EC4:EC96) -> 5383 | ED1: =SUBTOTAL(9,ED4:ED96) -> 2024841 | EE1: =1-DZ1/EC1 -> 0.14750139 | EF1: =SUBTOTAL(9,EF4:EF96) -> 1 | EH1: =SUBTOTAL(9,EH4:EH96) -> 18351 | EI1: =SUBTOTAL(9,EI4:EI96) -> 59585 | EJ1: =SUBTOTAL(9,EJ4:EJ96) -> 15648 | EK1: =EH1+EI1+EJ1 -> 93584 | EL1: =SUBTOTAL(9,EL4:EL96) -> 84119944 | EM1: =SUBTOTAL(9,EM4:EM96) -> 26150 | EN1: =SUBTOTAL(9,EN4:EN96) -> 28664665 | EO1: =SUBTOTAL(9,EO4:EO96) -> 119734 | EP1: =SUBTOTAL(9,EP4:EP96) -> 1.1278461e+08 | EU1: =SUBTOTAL(9,EU4:EU96) -> 520803 | EV1: =SUBTOTAL(9,EV4:EV96) -> 2896 | EW1: =SUBTOTAL(9,EW4:EW96) -> 6663805.7 | EX1: =SUBTOTAL(9,EX4:EX96) -> 3142093.7 | EY1: =SUBTOTAL(9,EY4:EY96) -> 3554 | EZ1: =SUBTOTAL(9,EZ4:EZ96) -> 1379651 | FA1: =1-EV1/EY1 -> 0.1851435 | FB1: =SUBTOTAL(9,FB4:FB96) -> 1 | FD1: =SUBTOTAL(9,FD4:FD96) -> 13986 | FE1: =SUBTOTAL(9,FE4:FE96) -> 58160 | FF1: =SUBTOTAL(9,FF4:FF96) -> 15648 | FG1: =FD1+FE1+FF1 -> 87794 | FH1: =SUBTOTAL(9,FH4:FH96) -> 77473660 | FI1: =SUBTOTAL(9,FI4:FI96) -> 26150 | FJ1: =SUBTOTAL(9,FJ4:FJ96) -> 28664665 | FK1: =SUBTOTAL(9,FK4:FK96) -> 113944 | FL1: =SUBTOTAL(9,FL4:FL96) -> 1.0613833e+08 | FQ1: =SUBTOTAL(9,FQ4:FQ96) -> 492024 | FV1: =SUBTOTAL(9,FV4:FV96) -> 5068 | FW1: =SUBTOTAL(9,FW4:FW96) -> 9367096 | FX1: =SUBTOTAL(9,FX4:FX96) -> 4530373.1 | FY1: =SUBTOTAL(9,FY4:FY96) -> 1 | GA1: =SUBTOTAL(9,GA4:GA96) -> 4256 | GB1: =SUBTOTAL(9,GB4:GB96) -> 54221 | GC1: =SUBTOTAL(9,GC4:GC96) -> 15648 | GD1: =GA1+GB1+GC1 -> 74125 | GE1: =SUBTOTAL(9,GE4:GE96) -> 67007188 | GF1: =SUBTOTAL(9,GF4:GF96) -> 26150 | GG1: =SUBTOTAL(9,GG4:GG96) -> 28664665 | GH1: =SUBTOTAL(9,GH4:GH96) -> 100275 | GI1: =SUBTOTAL(9,GI4:GI96) -> 95671853 | GN1: =SUBTOTAL(9,GN4:GN96) -> 457793 | GS1: =SUBTOTAL(9,GS4:GS96) -> 5017 | GT1: =SUBTOTAL(9,GT4:GT96) -> 9464370.1 | GU1: =SUBTOTAL(9,GU4:GU96) -> 4573113.8 | GV1: =SUBTOTAL(9,GV4:GV96) -> 1 | GX1: =SUBTOTAL(9,GX4:GX96) -> 9285 | GY1: =SUBTOTAL(9,GY4:GY96) -> 50578 | GZ1: =SUBTOTAL(9,GZ4:GZ96) -> 15648 | HA1: =GX1+GY1+GZ1 -> 75511 | HB1: =SUBTOTAL(9,HB4:HB96) -> 68989445 | HC1: =SUBTOTAL(9,HC4:HC96) -> 26150 | HD1: =SUBTOTAL(9,HD4:HD96) -> 28664665 | HE1: =SUBTOTAL(9,HE4:HE96) -> 101661 | HF1: =SUBTOTAL(9,HF4:HF96) -> 97654110 | HK1: =SUBTOTAL(9,HK4:HK118) -> 557516 | HP1: =SUBTOTAL(9,HP4:HP118) -> 5112 | HQ1: =SUBTOTAL(9,HQ4:HQ118) -> 10951496 | HR1: =SUBTOTAL(9,HR4:HR118) -> 5248434.8 | HS1: =SUBTOTAL(9,HS4:HS118) -> 1 | HU1: =SUBTOTAL(9,HU4:HU118) -> 13334 | HV1: =SUBTOTAL(9,HV4:HV118) -> 44532 | HW1: =SUBTOTAL(9,HW4:HW118) -> 15648 | HX1: =HU1+HV1+HW1 -> 73514 | HY1: =SUBTOTAL(9,HY4:HY118) -> 69516329 | HZ1: =SUBTOTAL(9,HZ4:HZ118) -> 26150 | IA1: =SUBTOTAL(9,IA4:IA118) -> 28664665 | IB1: =SUBTOTAL(9,IB4:IB118) -> 95105 | IC1: =SUBTOTAL(9,IC4:IC118) -> 98180994 | IH1: =SUBTOTAL(9,IH4:IH118) -> 540913 | II1: =SUBTOTAL(9,II4:II222) -> 3890 | IJ1: =SUBTOTAL(9,IJ4:IJ222) -> 9290801.4 | IK1: =SUBTOTAL(9,IK4:IK222) -> 1491 | IL1: =SUBTOTAL(9,IL4:IL222) -> 2047482.8 | IM1: =SUBTOTAL(9,IM4:IM222) -> 5381 | IN1: =SUBTOTAL(9,IN4:IN222) -> 11338284 | IO1: =SUBTOTAL(9,IO4:IO222) -> 5377810.2 | IP1: =SUBTOTAL(9,IP4:IP222) -> 1 | IR1: =SUBTOTAL(9,IR4:IR118) -> 26926 | IS1: =SUBTOTAL(9,IS4:IS118) -> 47576 | IT1: =SUBTOTAL(9,IT4:IT118) -> 15648 | IU1: =IR1+IS1+IT1 -> 90150 | IV1: =SUBTOTAL(9,IV4:IV118) -> 86416412 | IW1: =SUBTOTAL(9,IW4:IW118) -> 26150 | IX1: =SUBTOTAL(9,IX4:IX118) -> 28664665 | IY1: =SUBTOTAL(9,IY4:IY118) -> 110697 | IZ1: =SUBTOTAL(9,IZ4:IZ118) -> 1.1508108e+08 | JE1: =SUBTOTAL(9,JE4:JE121) -> 527871 | JF1: =SUBTOTAL(9,JF4:JF222) -> 3181 | JG1: =SUBTOTAL(9,JG4:JG222) -> 7626892.6 | JH1: =SUBTOTAL(9,JH4:JH222) -> 963 | JI1: =SUBTOTAL(9,JI4:JI222) -> 1414888 | JJ1: =SUBTOTAL(9,JJ4:JJ222) -> 4144 | JK1: =SUBTOTAL(9,JK4:JK222) -> 9041780.6 | JL1: =SUBTOTAL(9,JL4:JL222) -> 4246671.4 | JM1: =SUBTOTAL(9,JM4:JM222) -> 1 | JO1: =SUBTOTAL(9,JO4:JO118) -> 26926 | JP1: =SUBTOTAL(9,JP4:JP118) -> 47576 | JQ1: =SUBTOTAL(9,JQ4:JQ118) -> 15648 | JR1: =JO1+JP1+JQ1 -> 90150 | JS1: =SUBTOTAL(9,JS4:JS118) -> 361230 | JT1: =SUBTOTAL(9,JT4:JT118) -> 26150 | JU1: =SUBTOTAL(9,JU4:JU118) -> 372000 | JV1: =SUBTOTAL(9,JV4:JV118) -> 110697 | JW1: =SUBTOTAL(9,JW4:JW118) -> 733230 | KB1: =SUBTOTAL(9,KB4:KB121) -> 800146 | KC1: =SUBTOTAL(9,KC4:KC222) -> 4408 | KD1: =SUBTOTAL(9,KD4:KD222) -> 11052673 | KE1: =SUBTOTAL(9,KE4:KE222) -> 475 | KF1: =SUBTOTAL(9,KF4:KF222) -> 747624.35 | KG1: =SUBTOTAL(9,KG4:KG222) -> 4883 | KH1: =SUBTOTAL(9,KH4:KH222) -> 11800298 | KI1: =SUBTOTAL(9,KI4:KI222) -> 5508667.7 | KJ1: =SUBTOTAL(9,KJ4:KJ222) -> 1 | KL1: =SUBTOTAL(9,KL4:KL118) -> 26926 | KM1: =SUBTOTAL(9,KM4:KM118) -> 47576 | KN1: =SUBTOTAL(9,KN4:KN118) -> 15648 | KO1: =KL1+KM1+KN1 -> 90150 | KP1: =SUBTOTAL(9,KP4:KP118) -> 8936142 | KQ1: =SUBTOTAL(9,KQ4:KQ118) -> 26150 | KR1: =SUBTOTAL(9,KR4:KR118) -> 5950438 | KS1: =SUBTOTAL(9,KS4:KS118) -> 110697 | KT1: =SUBTOTAL(9,KT4:KT118) -> 14886580 | KY1: =SUBTOTAL(9,KY4:KY121) -> 666302 | KZ1: =SUBTOTAL(9,KZ4:KZ222) -> 5338 | LA1: =SUBTOTAL(9,LA4:LA222) -> 13164314 | LB1: =SUBTOTAL(9,LB4:LB222) -> 198 | LC1: =SUBTOTAL(9,LC4:LC222) -> 282761.19 | LD1: =SUBTOTAL(9,LD4:LD222) -> 5536 | LE1: =SUBTOTAL(9,LE4:LE222) -> 13447076 | LF1: =SUBTOTAL(9,LF4:LF222) -> 6474650.8 | LG1: =SUBTOTAL(9,LG4:LG222) -> 1 | LI1: =SUBTOTAL(9,LI4:LI118) -> 26926 | LJ1: =SUBTOTAL(9,LJ4:LJ118) -> 47576 | LK1: =SUBTOTAL(9,LK4:LK118) -> 15648 | LL1: =LI1+LJ1+LK1 -> 90150 | LM1: =SUBTOTAL(9,LM4:LM118) -> 147398063 | LN1: =SUBTOTAL(9,LN4:LN118) -> 26150 | LO1: =SUBTOTAL(9,LO4:LO118) -> 94087948 | LP1: =SUBTOTAL(9,LP4:LP118) -> 110697 | LQ1: =SUBTOTAL(9,LQ4:LQ118) -> 241486011 | LV1: =SUBTOTAL(9,LV4:LV125) -> 1585414 | LW1: =SUBTOTAL(9,LW4:LW222) -> 3960 | LX1: =SUBTOTAL(9,LX4:LX222) -> 9409199.3 | LY1: =SUBTOTAL(9,LY4:LY222) -> 159 | LZ1: =SUBTOTAL(9,LZ4:LZ222) -> 176692.81 | MA1: =SUBTOTAL(9,MA4:MA222) -> 3973 | MB1: =SUBTOTAL(9,MB4:MB222) -> 9486413.4 | MC1: =SUBTOTAL(9,MC4:MC222) -> 4336977.2 | MD1: =SUBTOTAL(9,MD4:MD222) -> 1 | MF1: =SUBTOTAL(9,MF4:MF118) -> 26926 | MG1: =SUBTOTAL(9,MG4:MG118) -> 47576 | MH1: =SUBTOTAL(9,MH4:MH118) -> 15648 | MI1: =MF1+MG1+MH1 -> 90150 | MJ1: =SUBTOTAL(9,MJ4:MJ118) -> 1.6799388e+11 | MK1: =SUBTOTAL(9,MK4:MK118) -> 26150 | ML1: =SUBTOTAL(9,ML4:ML118) -> 1.0419171e+11 | MM1: =SUBTOTAL(9,MM4:MM118) -> 110697 | MN1: =SUBTOTAL(9,MN4:MN118) -> 2.7218559e+11 | MS1: =SUBTOTAL(9,MS4:MS146) -> 1467707 | MT1: =SUBTOTAL(9,MT4:MT222) -> 5672 | MU1: =SUBTOTAL(9,MU4:MU222) -> 12443129 | MV1: =SUBTOTAL(9,MV4:MV222) -> 93 | MW1: =SUBTOTAL(9,MW4:MW222) -> 111229.69 | MX1: =SUBTOTAL(9,MX4:MX222) -> 5765 | MY1: =SUBTOTAL(9,MY4:MY222) -> 12554359 | MZ1: =SUBTOTAL(9,MZ4:MZ222) -> 6016751.5 | NA1: =SUBTOTAL(9,NA4:NA222) -> 1 | NC1: =SUBTOTAL(9,NC4:NC118) -> 26926 | ND1: =SUBTOTAL(9,ND4:ND118) -> 47576 | NE1: =SUBTOTAL(9,NE4:NE118) -> 15648 | NF1: =NC1+ND1+NE1 -> 90150 | NG1: =SUBTOTAL(9,NG4:NG118) -> #VALUE! | NH1: =SUBTOTAL(9,NH4:NH118) -> 26150 | NI1: =SUBTOTAL(9,NI4:NI118) -> #VALUE! | NJ1: =SUBTOTAL(9,NJ4:NJ118) -> 110697 | NK1: =SUBTOTAL(9,NK4:NK118) -> #VALUE! | NP1: =SUBTOTAL(9,NP4:NP146) -> 1137447 | NQ1: =SUBTOTAL(9,NQ4:NQ222) -> 4953 | NR1: =SUBTOTAL(9,NR4:NR222) -> 9617223.4 | NS1: =SUBTOTAL(9,NS4:NS222) -> 10 | NT1: =SUBTOTAL(9,NT4:NT222) -> 9226.28 | NU1: =SUBTOTAL(9,NU4:NU222) -> 4963 | NV1: =SUBTOTAL(9,NV4:NV222) -> 9626449.7 | NW1: =SUBTOTAL(9,NW4:NW222) -> 4759220.8 | NX1: =SUBTOTAL(9,NX4:NX222) -> 1 | NZ1: =SUBTOTAL(9,NZ4:NZ118) -> 26926 | OA1: =SUBTOTAL(9,OA4:OA118) -> 47576 | OB1: =SUBTOTAL(9,OB4:OB118) -> 15648 | OC1: =NZ1+OA1+OB1 -> 90150 | OD1: =SUBTOTAL(9,OD4:OD118) -> #VALUE! | OE1: =SUBTOTAL(9,OE4:OE118) -> 26150 | OF1: =SUBTOTAL(9,OF4:OF118) -> #VALUE! | OG1: =SUBTOTAL(9,OG4:OG118) -> 110697 | OH1: =SUBTOTAL(9,OH4:OH118) -> #VALUE!
K2: 45200 | O2: 45231 | S2: Dec-23(1-31st) | W2: Jan-24(1-30th) | AA2: Feb-24(1-29th) | AE2: March-24(1-30th) | AI2: April-24(1-30th) | AM2: May-24(1-31st) | AQ2: June-24 (1-30th) | AU2: July-24 (1-31st) | AY2: Aug-24 (1-31st) | BC2: Sept-24 (1-30th) | BG2: Oct-24 (1-31st) | BK2: Nov-24 (1-30th) | BT2: 02nd Dec | BU2: 02nd Dec | BV2: 28th Nov | BY2: 28th Nov | CG2: Dec-24 (1-31st) | CP2: 19th Dec | CQ2: 19th Dec | CR2: 28th Nov | CU2: 28th Nov | DC2: Jan - 25 (1-31st) | DL2: 19th Dec | DM2: 19th Dec | DN2: 28th Nov | DQ2: 28th Nov | DY2: Feb - 25 (1-28th) | EU2: Mar - 25 (1-31st) | FQ2: Apr - 25 (1-30th) | GN2: May - 25 (1-31st) | HK2: June - 25 (1-30th) | IH2: July - 25 (1-31st) | JE2: Aug - 25 (1-31st) | KB2: Sept - 25 (1-30th) | KY2: Oct - 25 (1-31st) | LV2: Nov - 25 (1-30th) | MS2: Dec - 25 (1-31st) | NP2: Jan - 26 (1-31st)
A3: FBA SKU | B3: Model | C3: SKU | D3: Category | E3: Main Category | F3: Brand | G3: ASIN | H3: Description | I3: DP | J3: NLC | K3: Sessions | L3: Net Units | M3: Gross Units | N3: Ops to Net Cancellation % | O3: Sessions | P3: Net Units | Q3: Gross Units | R3: Gross to Net Cancellation % | S3: Sessions | T3: Net Units | U3: Gross Units | V3: Gross to Net Cancellation % | W3: Sessions | X3: Net Units | Y3: Gross Units | Z3: Gross to Net Cancellation % | AA3: Sessions | AB3: Net Units | AC3: Gross Units | AD3: Gross to Net Cancellation % | AE3: Sessions | AF3: Net Units | AG3: Gross Units | AH3: Gross to Net Cancellation % | AI3: Sessions | AJ3: Net Units | AK3: Gross Units | AL3: Gross to Net Cancellation % | AM3: Sessions | AN3: Net Units | AO3: Gross Units | AP3: Gross to Net Cancellation % | AQ3: Sessions | AR3: Net Units | AS3: Gross Units | AT3: Gross to Net Cancellation % | AU3: Sessions | AV3: Net Units | AW3: Gross Units | AX3: Gross to Net Cancellation % | AY3: Sessions | AZ3: Net Units | BA3: Gross Units | BB3: Gross to Net Cancellation % | BC3: Sessions | BD3: Net Units | BE3: Gross Units | BF3: Gross to Net Cancellation % | BG3: Sessions | BH3: Net Units | BI3: Gross Units | BJ3: Gross to Net Cancellation % | BK3: Sessions | BL3: Net Units Sold | BM3: Net Units Value at SP | BN3: Net Units Value at NLC | BO3: Gross Units Sold | BP3: Gross Units Value | BQ3: Gross to Net Cancellation % | BR3: Contribution to sales | BS3: Model no | BT3: Current Amazon Inventory | BU3: AMPM Inventory | BV3: Pipeline Inventory | BW3: Total Inventory (Amazon+AMPM+Pipeline) | BX3: Total Inventory (Amazon+AMPM+Pipeline) Value | BY3: Open Order | BZ3: Open Order Value | CA3: Total SOH | CB3: Total SOH Value at NLC | CC3: Model | CD3: =C3 -> SKU | CE3: ASIN | CF3: Model | CG3: Sessions | CH3: Net Units Sold | CI3: Net Units Value at SP | CJ3: Net Units Value at NLC | CK3: Gross Units Sold | CL3: Gross Units Value | CM3: Gross to Net Cancellation % | CN3: Contribution to sales | CO3: Model no | CP3: Current Amazon Inventory | CQ3: AMPM Inventory | CR3: Pipeline Inventory | CS3: Total Inventory (Amazon+AMPM+Pipeline) | CT3: Total Inventory (Amazon+AMPM+Pipeline) Value | CU3: Open Order | CV3: Open Order Value | CW3: Total SOH | CX3: Total SOH Value at NLC | CY3: Model | CZ3: =C3 -> SKU | DA3: ASIN | DB3: Model | DC3: Sessions | DD3: Net Units Sold | DE3: Net Units Value at SP | DF3: Net Units Value at NLC | DG3: Gross Units Sold | DH3: Gross Units Value | DI3: Gross to Net Cancellation % | DJ3: Contribution to sales | DK3: Model no | DL3: Current Amazon Inventory | DM3: AMPM Inventory | DN3: Pipeline Inventory | DO3: Total Inventory (Amazon+AMPM+Pipeline) | DP3: Total Inventory (Amazon+AMPM+Pipeline) Value | DQ3: Open Order | DR3: Open Order Value | DS3: Total SOH | DT3: Total SOH Value at NLC | DU3: Model | DV3: SKU | DW3: ASIN | DX3: Model | DY3: Sessions | DZ3: Net Units Sold | EA3: Net Units Value at SP | EB3: Net Units Value at NLC | EC3: Gross Units Sold | ED3: Gross Units Value | EE3: Gross to Net Cancellation % | EF3: Contribution to sales | EG3: Model no | EH3: Current Amazon Inventory | EI3: AMPM Inventory | EJ3: Pipeline Inventory | EK3: Total Inventory (Amazon+AMPM+Pipeline) | EL3: Total Inventory (Amazon+AMPM+Pipeline) Value | EM3: Open Order | EN3: Open Order Value | EO3: Total SOH | EP3: Total SOH Value at NLC | EQ3: Model | ER3: SKU | ES3: ASIN | ET3: Model | EU3: Sessions | EV3: Net Units Sold | EW3: Net Units Value at SP | EX3: Net Units Value at NLC | EY3: Gross Units Sold | EZ3: Gross Units Value | FA3: Gross to Net Cancellation % | FB3: Contribution to sales | FC3: Model no | FD3: Current Amazon Inventory | FE3: AMPM Inventory | FF3: Pipeline Inventory | FG3: Total Inventory (Amazon+AMPM+Pipeline) | FH3: Total Inventory (Amazon+AMPM+Pipeline) Value | FI3: Open Order | FJ3: Open Order Value | FK3: Total SOH | FL3: Total SOH Value at NLC | FM3: Model | FN3: SKU | FO3: ASIN | FP3: Model | FQ3: Sessions | FR3: Amazon Sales Unit | FS3: Amazon Sales Value | FT3: EB Sales Units | FU3: EB Sales Value | FV3: Net Units Sold | FW3: Net Units Value at SP | FX3: Net Units Value at NLC | FY3: Contribution to sales | FZ3: Model no | GA3: Current Amazon Inventory | GB3: AMPM Inventory | GC3: Pipeline Inventory | GD3: Total Inventory (Amazon+AMPM+Pipeline) | GE3: Total Inventory (Amazon+AMPM+Pipeline) Value | GF3: Open Order | GG3: Open Order Value | GH3: Total SOH | GI3: Total SOH Value at NLC | GJ3: Model | GK3: SKU | GL3: ASIN | GM3: Model | GN3: Sessions | GO3: Amazon Sales Unit | GP3: Amazon Sales Value | GQ3: EB Sales Units | GR3: EB Sales Value | GS3: Net Units Sold | GT3: Net Units Value at SP | GU3: Net Units Value at NLC | GV3: Contribution to sales | GW3: Model no | GX3: Current Amazon Inventory | GY3: AMPM Inventory | GZ3: Pipeline Inventory | HA3: Total Inventory (Amazon+AMPM+Pipeline) | HB3: Total Inventory (Amazon+AMPM+Pipeline) Value | HC3: Open Order | HD3: Open Order Value | HE3: Total SOH | HF3: Total SOH Value at NLC | HG3: Model | HH3: SKU | HI3: ASIN | HJ3: Model | HK3: Sessions | HL3: Amazon Sales Unit | HM3: Amazon Sales Value | HN3: EB Sales Units | HO3: EB Sales Value | HP3: Net Units Sold | HQ3: Net Units Value at SP | HR3: Net Units Value at NLC | HS3: Contribution to sales | HT3: Model no | HU3: Current Amazon Inventory | HV3: AMPM Inventory | HW3: Pipeline Inventory | HX3: Total Inventory (Amazon+AMPM+Pipeline) | HY3: Total Inventory (Amazon+AMPM+Pipeline) Value | HZ3: Open Order | IA3: Open Order Value | IB3: Total SOH | IC3: Total SOH Value at NLC | ID3: Model | IE3: SKU | IF3: ASIN | IG3: Model | IH3: Sessions | II3: Amazon Sales Unit | IJ3: Amazon Sales Value | IK3: EB Sales Units | IL3: EB Sales Value | IM3: Net Units Sold | IN3: Net Units Value at SP | IO3: Net Units Value at NLC | IP3: Contribution to sales | IQ3: Model no | IR3: Current Amazon Inventory | IS3: AMPM Inventory | IT3: Pipeline Inventory | IU3: Total Inventory (Amazon+AMPM+Pipeline) | IV3: Total Inventory (Amazon+AMPM+Pipeline) Value | IW3: Open Order | IX3: Open Order Value | IY3: Total SOH | IZ3: Total SOH Value at NLC | JA3: Model | JB3: SKU | JC3: ASIN | JD3: Model | JE3: Sessions | JF3: Amazon Sales Unit | JG3: Amazon Sales Value | JH3: EB Sales Units | JI3: EB Sales Value | JJ3: Net Units Sold | JK3: Net Units Value at SP | JL3: Net Units Value at NLC | JM3: Contribution to sales | JN3: Model no | JO3: Current Amazon Inventory | JP3: AMPM Inventory | JQ3: Pipeline Inventory | JR3: Total Inventory (Amazon+AMPM+Pipeline) | JS3: Total Inventory (Amazon+AMPM+Pipeline) Value | JT3: Open Order | JU3: Open Order Value | JV3: Total SOH | JW3: Total SOH Value at NLC | JX3: Model | JY3: SKU | JZ3: ASIN | KA3: Model | KB3: Sessions | KC3: Amazon Sales Unit | KD3: Amazon Sales Value | KE3: EB Sales Units | KF3: EB Sales Value | KG3: Net Units Sold | KH3: Net Units Value at SP | KI3: Net Units Value at NLC | KJ3: Contribution to sales | KK3: Model no | KL3: Current Amazon Inventory | KM3: AMPM Inventory | KN3: Pipeline Inventory | KO3: Total Inventory (Amazon+AMPM+Pipeline) | KP3: Total Inventory (Amazon+AMPM+Pipeline) Value | KQ3: Open Order | KR3: Open Order Value | KS3: Total SOH | KT3: Total SOH Value at NLC | KU3: Model | KV3: SKU | KW3: ASIN | KX3: Model | KY3: Sessions | KZ3: Amazon Sales Unit | LA3: Amazon Sales Value | LB3: EB Sales Units | LC3: EB Sales Value | LD3: Net Units Sold | LE3: Net Units Value at SP | LF3: Net Units Value at NLC | LG3: Contribution to sales | LH3: Model no | LI3: Current Amazon Inventory | LJ3: AMPM Inventory | LK3: Pipeline Inventory | LL3: Total Inventory (Amazon+AMPM+Pipeline) | LM3: Total Inventory (Amazon+AMPM+Pipeline) Value | LN3: Open Order | LO3: Open Order Value | LP3: Total SOH | LQ3: Total SOH Value at NLC | LR3: Model | LS3: SKU | LT3: ASIN | LU3: Model | LV3: Sessions | LW3: Amazon Sales Unit | LX3: Amazon Sales Value | LY3: EB Sales Units | LZ3: EB Sales Value | MA3: Net Units Sold | MB3: Net Units Value at SP | MC3: Net Units Value at NLC | MD3: Contribution to sales | ME3: Model no | MF3: Current Amazon Inventory | MG3: AMPM Inventory | MH3: Pipeline Inventory | MI3: Total Inventory (Amazon+AMPM+Pipeline) | MJ3: Total Inventory (Amazon+AMPM+Pipeline) Value | MK3: Open Order | ML3: Open Order Value | MM3: Total SOH | MN3: Total SOH Value at NLC | MO3: Model | MP3: SKU | MQ3: ASIN | MR3: Model | MS3: Sessions | MT3: Amazon Sales Unit | MU3: Amazon Sales Value | MV3: EB Sales Units | MW3: EB Sales Value | MX3: Net Units Sold | MY3: Net Units Value at SP | MZ3: Net Units Value at NLC | NA3: Contribution to sales | NB3: Model no | NC3: Current Amazon Inventory | ND3: AMPM Inventory | NE3: Pipeline Inventory | NF3: Total Inventory (Amazon+AMPM+Pipeline) | NG3: Total Inventory (Amazon+AMPM+Pipeline) Value | NH3: Open Order | NI3: Open Order Value | NJ3: Total SOH | NK3: Total SOH Value at NLC | NL3: Model | NM3: SKU | NN3: ASIN | NO3: Model | NP3: Sessions | NQ3: Amazon Sales Unit | NR3: Amazon Sales Value | NS3: EB Sales Units | NT3: EB Sales Value | NU3: Net Units Sold | NV3: Net Units Value at SP | NW3: Net Units Value at NLC | NX3: Contribution to sales | NY3: Model no | NZ3: Current Amazon Inventory | OA3: AMPM Inventory | OB3: Pipeline Inventory | OC3: Total Inventory (Amazon+AMPM+Pipeline) | OD3: Total Inventory (Amazon+AMPM+Pipeline) Value | OE3: Open Order | OF3: Open Order Value | OG3: Total SOH | OH3: Total SOH Value at NLC | OI3: Model | OJ3: SKU | OK3: ASIN | OL3: Model
A4: FBA79262 | B4: SC-02 | C4: FBA79262 | D4: Home & Kitchen | E4: Cleaning & Vacumming | F4: Nexlev | G4: B0CYSMBCB8 | H4: Nexlev Steam Cleaner | I4: 1088.3211 | J4: 1284.2189 | K4: 0 | L4: 0 | M4: 0 | N4: =1-L4/M4 -> #DIV/0! | O4: 0 | P4: 0 | Q4: 0 | R4: =1-P4/Q4 -> #DIV/0! | S4: 0 | T4: 0 | U4: 0 | V4: =1-T4/U4 -> #DIV/0! | W4: 0 | X4: 0 | Y4: 0 | Z4: =1-X4/Y4 -> #DIV/0! | AA4: 0 | AB4: 0 | AC4: 0 | AD4: =1-AB4/AC4 -> #DIV/0! | AE4: 0 | AF4: 0 | AG4: 0 | AH4: =1-AF4/AG4 -> #DIV/0! | AI4: 3385 | AJ4: 15 | AK4: 29 | AL4: =1-AJ4/AK4 -> 0.48275862 | AM4: 27847 | AN4: 367 | AO4: 486 | AP4: =1-AN4/AO4 -> 0.24485597 | AQ4: 31212 | AR4: 306 | AS4: 362 | AT4: =1-AR4/AS4 -> 0.15469613 | AU4: 30179 | AV4: 294 | AW4: 349 | AX4: =1-AV4/AW4 -> 0.15759312 | AY4: 44123 | AZ4: 306 | BA4: 371 | BB4: =1-AZ4/BA4 -> 0.17520216 | BC4: 25535 | BD4: 286 | BE4: 393 | BF4: =1-BD4/BE4 -> 0.27226463 | BG4: 91824 | BH4: 1086 | BI4: 1345 | BJ4: =1-BH4/BI4 -> 0.19256506 | BK4: 62353 | BL4: 652 | BM4: 1853003 | BN4: =BL4*J4 -> 837310.74 | BO4: 833 | BP4: 2069171 | BQ4: =1-BL4/BO4 -> 0.21728691 | BR4: =BM4/$BM$1 -> 0.15091559 | BS4: =B4 -> SC-02 | BT4: 870 | BU4: 1691 | BV4: 0 | BW4: =BT4+BU4+BV4 -> 2561 | BX4: =BW4*J4 -> 3288884.7 | BY4: 3000 | BZ4: =BY4*J4 -> 3852656.8 | CA4: =BW4+BY4 -> 5561 | CB4: =BX4+BZ4 -> 7141541.5 | CC4: =B4 -> SC-02 | CD4: =C4 -> FBA79262 | CE4: =G4 -> B0CYSMBCB8 | CF4: =B4 -> SC-02 | CG4: 26982 | CH4: 338 | CI4: 911996.11 | CJ4: =CH4*J4 -> 434066 | CK4: 402 | CL4: 979531 | CM4: =1-CH4/CK4 -> 0.15920398 | CN4: =CI4/$CI$1 -> 0.080352397 | CO4: =B4 -> SC-02 | CP4: 1099 | CQ4: 1164 | CR4: 0 | CS4: =CP4+CQ4+CR4 -> 2263 | CT4: =CS4*J4 -> 2906187.4 | CU4: 3000 | CV4: =CU4*J4 -> 3852656.8 | CW4: =CS4+CU4 -> 5263 | CX4: =CT4+CV4 -> 6758844.2 | CY4: =B4 -> SC-02 | CZ4: =C4 -> FBA79262 | DA4: =G4 -> B0CYSMBCB8 | DB4: =B4 -> SC-02 | DC4: 28319 | DD4: 275 | DE4: 737395.51 | DF4: =DD4*J4 -> 353160.21 | DG4: 336 | DH4: 851483 | DI4: =1-DD4/DG4 -> 0.18154762 | DJ4: =DE4/$DE$1 -> 0.058469064 | DK4: =B4 -> SC-02 | DL4: 893 | DM4: 1057 | DN4: 0 | DO4: =DL4+DM4+DN4 -> 1950 | DP4: =DO4*J4 -> 2504226.9 | DQ4: 3000 | DR4: =DQ4*J4 -> 3852656.8 | DS4: =DO4+DQ4 -> 4950 | DT4: =DP4+DR4 -> 6356883.7 | DU4: =B4 -> SC-02 | DV4: =C4 -> FBA79262 | DW4: =G4 -> B0CYSMBCB8 | DX4: =B4 -> SC-02 | DY4: 13255 | DZ4: 138 | EA4: 364807.16 | EB4: =DZ4*J4 -> 177222.21 | EC4: 169 | ED4: 4,08,945.00 | EE4: =1-DZ4/EC4 -> 0.18343195 | EF4: =EA4/$EA$1 -> 0.041518404 | EG4: =B4 -> SC-02 | EH4: 658 | EI4: 992 | EJ4: 0 | EK4: =EH4+EI4+EJ4 -> 1650 | EL4: =EK4*J4 -> 2118961.2 | EM4: 3000 | EN4: =EM4*J4 -> 3852656.8 | EO4: =EK4+EM4 -> 4650 | EP4: =EL4+EN4 -> 5971618 | EQ4: =B4 -> SC-02 | ER4: =C4 -> FBA79262 | ES4: =G4 -> B0CYSMBCB8 | ET4: =B4 -> SC-02 | EU4: 20601 | EV4: 120 | EW4: 300059 | EX4: =EV4*J4 -> 154106.27 | EY4: 149 | EZ4: 3,22,499 | FA4: =1-EV4/EY4 -> 0.19463087 | FB4: =EW4/$EW$1 -> 0.045028174 | FC4: =B4 -> SC-02 | FD4: 526 | FE4: 837 | FF4: 0 | FG4: =FD4+FE4+FF4 -> 1363 | FH4: =FG4*J4 -> 1750390.4 | FI4: 3000 | FJ4: =FI4*J4 -> 3852656.8 | FK4: =FG4+FI4 -> 4363 | FL4: =FH4+FJ4 -> 5603047.2 | FM4: =B4 -> SC-02 | FN4: =C4 -> FBA79262 | FO4: =G4 -> B0CYSMBCB8 | FP4: =B4 -> SC-02 | FQ4: 25575 | FR4: 128 | FS4: 304792 | FT4: 0 | FU4: 0 | FV4: =FR4+FT4 -> 128 | FW4: =FS4+FU4 -> 304792 | FX4: =FV4*J4 -> 164380.02 | FY4: =FW4/$FW$1 -> 0.03253858 | FZ4: =B4 -> SC-02 | GA4: 0 | GB4: 775 | GC4: 0 | GD4: =GA4+GB4+GC4 -> 775 | GE4: =GD4*J4 -> 995269.67 | GF4: 3000 | GG4: =GF4*J4 -> 3852656.8 | GH4: =GD4+GF4 -> 3775 | GI4: =GE4+GG4 -> 4847926.5 | GJ4: =B4 -> SC-02 | GK4: =C4 -> FBA79262 | GL4: =G4 -> B0CYSMBCB8 | GM4: =B4 -> SC-02 | GN4: 30592 | GO4: 155 | GP4: 366411 | GQ4: 0 | GR4: 0 | GS4: =GO4+GQ4 -> 155 | GT4: =GP4+GR4 -> 366411 | GU4: =GS4*J4 -> 199053.93 | GV4: =GT4/$GT$1 -> 0.038714779 | GW4: =B4 -> SC-02 | GX4: 239 | GY4: 771 | GZ4: 0 | HA4: =GX4+GY4+GZ4 -> 1010 | HB4: =HA4*J4 -> 1297061.1 | HC4: 3000 | HD4: =HC4*J4 -> 3852656.8 | HE4: =HA4+HC4 -> 4010 | HF4: =HB4+HD4 -> 5149717.9 | HG4: =B4 -> SC-02 | HH4: =C4 -> FBA79262 | HI4: =G4 -> B0CYSMBCB8 | HJ4: =B4 -> SC-02 | HK4: 23433 | HL4: 163 | HM4: 395912 | HN4: 0 | HO4: 0 | HP4: =HL4+HN4 -> 163 | HQ4: =HM4+HO4 -> 395912 | HR4: =HP4*J4 -> 209327.69 | HS4: =HQ4/$HQ$1 -> 0.036151409 | HT4: =B4 -> SC-02 | HU4: 571 | HV4: 162 | HW4: 0 | HX4: =HU4+HV4+HW4 -> 733 | HY4: =HX4*J4 -> 941332.48 | HZ4: 3000 | IA4: =HZ4*J4 -> 3852656.8 | IB4: =HX4+HZ4 -> 3733 | IC4: =HY4+IA4 -> 4793989.3 | ID4: =B4 -> SC-02 | IE4: =C4 -> FBA79262 | IF4: =G4 -> B0CYSMBCB8 | IG4: =B4 -> SC-02 | IH4: 9913 | II4: 148 | IJ4: 356074.7 | IK4: 0 | IL4: 0 | IM4: =II4+IK4 -> 148 | IN4: =IJ4+IL4 -> 356074.7 | IO4: =IM4*J4 -> 190064.4 | IP4: =IN4/$IN$1 -> 0.031404637 | IQ4: =B4 -> SC-02 | IR4: 694 | IS4: 75 | IT4: 0 | IU4: =IR4+IS4+IT4 -> 769 | IV4: =IU4*J4 -> 987564.36 | IW4: 3000 | IX4: =IW4*J4 -> 3852656.8 | IY4: =IU4+IW4 -> 3769 | IZ4: =IV4+IX4 -> 4840221.2 | JA4: =B4 -> SC-02 | JB4: =C4 -> FBA79262 | JC4: =G4 -> B0CYSMBCB8 | JD4: =B4 -> SC-02 | JE4: 29846 | JF4: 117 | JG4: 280182.04 | JH4: 0 | JI4: 0 | JJ4: =JF4+JH4 -> 117 | JK4: =JG4+JI4 -> 280182.04 | JL4: =JJ4*J4 -> 150253.62 | JM4: =JK4/$JK$1 -> 0.030987485 | JN4: =B4 -> SC-02 | JO4: 694 | JP4: 75 | JQ4: 0 | JR4: =JO4+JP4+JQ4 -> 769 | JS4: =JR4*AG4 -> 0 | JT4: 3000 | JU4: =JT4*AG4 -> 0 | JV4: =JR4+JT4 -> 3769 | JW4: =JS4+JU4 -> 0 | JX4: =B4 -> SC-02 | JY4: =C4 -> FBA79262 | JZ4: =G4 -> B0CYSMBCB8 | KA4: =B4 -> SC-02 | KB4: 13951 | KC4: 160 | KD4: 376393.12 | KE4: 0 | KF4: 0 | KG4: =KC4+KE4 -> 160 | KH4: =KD4+KF4 -> 376393.12 | KI4: =KG4*J4 -> 205475.03 | KJ4: =KH4/$KH$1 -> 0.031896917 | KK4: =B4 -> SC-02 | KL4: 694 | KM4: 75 | KN4: 0 | KO4: =KL4+KM4+KN4 -> 769 | KP4: =KO4*BD4 -> 219934 | KQ4: 3000 | KR4: =KQ4*BD4 -> 858000 | KS4: =KO4+KQ4 -> 3769 | KT4: =KP4+KR4 -> 1077934 | KU4: =B4 -> SC-02 | KV4: =C4 -> FBA79262 | KW4: =G4 -> B0CYSMBCB8 | KX4: =B4 -> SC-02 | KY4: 17904 | KZ4: 267 | LA4: 624729.36 | LB4: 0 | LC4: 0 | LD4: =KZ4+LB4 -> 267 | LE4: =LA4+LC4 -> 624729.36 | LF4: =LD4*J4 -> 342886.46 | LG4: =LE4/$LE$1 -> 0.046458381 | LH4: =B4 -> SC-02 | LI4: 694 | LJ4: 75 | LK4: 0 | LL4: =LI4+LJ4+LK4 -> 769 | LM4: =LL4*CA4 -> 4276409 | LN4: 3000 | LO4: =LN4*CA4 -> 16683000 | LP4: =LL4+LN4 -> 3769 | LQ4: =LM4+LO4 -> 20959409 | LR4: =B4 -> SC-02 | LS4: =C4 -> FBA79262 | LT4: =G4 -> B0CYSMBCB8 | LU4: =B4 -> SC-02 | LV4: 9617 | LW4: 31 | LX4: 81841.26 | LY4: 0 | LZ4: 0 | MA4: =LW4+LY4 -> 31 | MB4: =LX4+LZ4 -> 81841.26 | MC4: =MA4*J4 -> 39810.787 | MD4: =MB4/$MB$1 -> 0.0086272078 | ME4: =B4 -> SC-02 | MF4: 694 | MG4: 75 | MH4: 0 | MI4: =MF4+MG4+MH4 -> 769 | MJ4: =MI4*CX4 -> 5.1975512e+09 | MK4: 3000 | ML4: =MK4*CX4 -> 2.0276533e+10 | MM4: =MI4+MK4 -> 3769 | MN4: =MJ4+ML4 -> 2.5474084e+10 | MO4: =B4 -> SC-02 | MP4: =C4 -> FBA79262 | MQ4: =G4 -> B0CYSMBCB8 | MR4: =B4 -> SC-02 | MS4: 10790 | MT4: 69 | MU4: 148161.62 | MV4: 0 | MW4: 0 | MX4: =MT4+MV4 -> 69 | MY4: =MU4+MW4 -> 148161.62 | MZ4: =MX4*J4 -> 88611.106 | NA4: =MY4/$MY$1 -> 0.011801608 | NB4: =B4 -> SC-02 | NC4: 694 | ND4: 75 | NE4: 0 | NF4: =NC4+ND4+NE4 -> 769 | NG4: =NF4*DU4 -> #VALUE! | NH4: 3000 | NI4: =NH4*DU4 -> #VALUE! | NJ4: =NF4+NH4 -> 3769 | NK4: =NG4+NI4 -> #VALUE! | NL4: =B4 -> SC-02 | NM4: =C4 -> FBA79262 | NN4: =G4 -> B0CYSMBCB8 | NO4: =B4 -> SC-02 | NP4: 1841 | NQ4: 29 | NR4: 62289.4 | NS4: 0 | NT4: 0 | NU4: =NQ4+NS4 -> 29 | NV4: =NR4+NT4 -> 62289.4 | NW4: =NU4*J4 -> 37242.349 | NX4: =NV4/$NV$1 -> 0.0064706514 | NY4: =B4 -> SC-02 | NZ4: 694 | OA4: 75 | OB4: 0 | OC4: =NZ4+OA4+OB4 -> 769 | OD4: =OC4*ER4 -> #VALUE! | OE4: 3000 | OF4: =OE4*ER4 -> #VALUE! | OG4: =OC4+OE4 -> 3769 | OH4: =OD4+OF4 -> #VALUE! | OI4: =B4 -> SC-02 | OJ4: =C4 -> FBA79262 | OK4: =G4 -> B0CYSMBCB8 | OL4: =B4 -> SC-02
A5: FBA79263 | B5: MR-01 | C5: FBA79263 | D5: Home & Kitchen | E5: Cleaning & Vacumming | F5: Nexlev | G5: B0CYSLCRQS | H5: Nexlev Dust Mite UV | I5: 908.87355 | J5: 1072.4708 | K5: 0 | L5: 0 | M5: 0 | N5: =1-L5/M5 -> #DIV/0! | O5: 0 | P5: 0 | Q5: 0 | R5: =1-P5/Q5 -> #DIV/0! | S5: 0 | T5: 0 | U5: 0 | V5: =1-T5/U5 -> #DIV/0! | W5: 0 | X5: 0 | Y5: 0 | Z5: =1-X5/Y5 -> #DIV/0! | AA5: 0 | AB5: 0 | AC5: 0 | AD5: =1-AB5/AC5 -> #DIV/0! | AE5: 0 | AF5: 0 | AG5: 0 | AH5: =1-AF5/AG5 -> #DIV/0! | AI5: 8884 | AJ5: 7 | AK5: 18 | AL5: =1-AJ5/AK5 -> 0.61111111 | AM5: 17432 | AN5: 262 | AO5: 302 | AP5: =1-AN5/AO5 -> 0.13245033 | AQ5: 16574 | AR5: 350 | AS5: 385 | AT5: =1-AR5/AS5 -> 0.090909091 | AU5: 25278 | AV5: 476 | AW5: 531 | AX5: =1-AV5/AW5 -> 0.10357815 | AY5: 32573 | AZ5: 550 | BA5: 434 | BB5: =1-AZ5/BA5 -> -0.26728111 | BC5: 77021 | BD5: 519 | BE5: 651 | BF5: =1-BD5/BE5 -> 0.20276498 | BG5: 112340 | BH5: 1116 | BI5: 1266 | BJ5: =1-BH5/BI5 -> 0.11848341 | BK5: 62354 | BL5: 331 | BM5: 1154626 | BN5: =BL5*J5 -> 354987.83 | BO5: 385 | BP5: 1248208 | BQ5: =1-BL5/BO5 -> 0.14025974 | BR5: =BM5/$BM$1 -> 0.094037117 | BS5: =B5 -> MR-01 | BT5: 1000 | BU5: 1680 | BV5: 0 | BW5: =BT5+BU5+BV5 -> 2680 | BX5: =BW5*J5 -> 2874221.7 | BY5: 3130 | BZ5: =BY5*J5 -> 3356833.6 | CA5: =BW5+BY5 -> 5810 | CB5: =BX5+BZ5 -> 6231055.3 | CC5: =B5 -> MR-01 | CD5: =C5 -> FBA79263 | CE5: =G5 -> B0CYSLCRQS | CF5: =B5 -> MR-01 | CG5: 37362 | CH5: 462 | CI5: 1409678.7 | CJ5: =CH5*J5 -> 495481.5 | CK5: 532 | CL5: 1513843 | CM5: =1-CH5/CK5 -> 0.13157895 | CN5: =CI5/$CI$1 -> 0.12420126 | CO5: =B5 -> MR-01 | CP5: 1017 | CQ5: 1191 | CR5: 0 | CS5: =CP5+CQ5+CR5 -> 2208 | CT5: =CS5*J5 -> 2368015.5 | CU5: 3130 | CV5: =CU5*J5 -> 3356833.6 | CW5: =CS5+CU5 -> 5338 | CX5: =CT5+CV5 -> 5724849.1 | CY5: =B5 -> MR-01 | CZ5: =C5 -> FBA79263 | DA5: =G5 -> B0CYSLCRQS | DB5: =B5 -> MR-01 | DC5: 47410 | DD5: 351 | DE5: 1047736.7 | DF5: =DD5*J5 -> 376437.25 | DG5: 420 | DH5: 1165980 | DI5: =1-DD5/DG5 -> 0.16428571 | DJ5: =DE5/$DE$1 -> 0.083076424 | DK5: =B5 -> MR-01 | DL5: 1283 | DM5: 3388 | DN5: 0 | DO5: =DL5+DM5+DN5 -> 4671 | DP5: =DO5*J5 -> 5009511.1 | DQ5: 3130 | DR5: =DQ5*J5 -> 3356833.6 | DS5: =DO5+DQ5 -> 7801 | DT5: =DP5+DR5 -> 8366344.6 | DU5: =B5 -> MR-01 | DV5: =C5 -> FBA79263 | DW5: =G5 -> B0CYSLCRQS | DX5: =B5 -> MR-01 | DY5: 57506 | DZ5: 210 | EA5: 626706 | EB5: =DZ5*J5 -> 225218.87 | EC5: 242 | ED5: 6,83,020.00 | EE5: =1-DZ5/EC5 -> 0.1322314 | EF5: =EA5/$EA$1 -> 0.071324897 | EG5: =B5 -> MR-01 | EH5: 1041 | EI5: 1743 | EJ5: 0 | EK5: =EH5+EI5+EJ5 -> 2784 | EL5: =EK5*J5 -> 2985758.7 | EM5: 3130 | EN5: =EM5*J5 -> 3356833.6 | EO5: =EK5+EM5 -> 5914 | EP5: =EL5+EN5 -> 6342592.2 | EQ5: =B5 -> MR-01 | ER5: =C5 -> FBA79263 | ES5: =G5 -> B0CYSLCRQS | ET5: =B5 -> MR-01 | EU5: 45013 | EV5: 163 | EW5: 482445 | EX5: =EV5*J5 -> 174812.74 | EY5: 198 | EZ5: 5,19,097 | FA5: =1-EV5/EY5 -> 0.17676768 | FB5: =EW5/$EW$1 -> 0.072397819 | FC5: =B5 -> MR-01 | FD5: 894 | FE5: 3002 | FF5: 0 | FG5: =FD5+FE5+FF5 -> 3896 | FH5: =FG5*J5 -> 4178346.2 | FI5: 3130 | FJ5: =FI5*J5 -> 3356833.6 | FK5: =FG5+FI5 -> 7026 | FL5: =FH5+FJ5 -> 7535179.8 | FM5: =B5 -> MR-01 | FN5: =C5 -> FBA79263 | FO5: =G5 -> B0CYSLCRQS | FP5: =B5 -> MR-01 | FQ5: 36377 | FR5: 243 | FS5: 693251 | FT5: 0 | FU5: 0 | FV5: =FR5+FT5 -> 243 | FW5: =FS5+FU5 -> 693251 | FX5: =FV5*J5 -> 260610.4 | FY5: =FW5/$FW$1 -> 0.07400917 | FZ5: =B5 -> MR-01 | GA5: 0 | GB5: 2827 | GC5: 0 | GD5: =GA5+GB5+GC5 -> 2827 | GE5: =GD5*J5 -> 3031874.9 | GF5: 3130 | GG5: =GF5*J5 -> 3356833.6 | GH5: =GD5+GF5 -> 5957 | GI5: =GE5+GG5 -> 6388708.5 | GJ5: =B5 -> MR-01 | GK5: =C5 -> FBA79263 | GL5: =G5 -> B0CYSLCRQS | GM5: =B5 -> MR-01 | GN5: 52917 | GO5: 271 | GP5: 777402 | GQ5: 0 | GR5: 0 | GS5: =GO5+GQ5 -> 271 | GT5: =GP5+GR5 -> 777402 | GU5: =GS5*J5 -> 290639.58 | GV5: =GT5/$GT$1 -> 0.082139856 | GW5: =B5 -> MR-01 | GX5: 417 | GY5: 2707 | GZ5: 0 | HA5: =GX5+GY5+GZ5 -> 3124 | HB5: =HA5*J5 -> 3350398.7 | HC5: 3130 | HD5: =HC5*J5 -> 3356833.6 | HE5: =HA5+HC5 -> 6254 | HF5: =HB5+HD5 -> 6707232.3 | HG5: =B5 -> MR-01 | HH5: =C5 -> FBA79263 | HI5: =G5 -> B0CYSLCRQS | HJ5: =B5 -> MR-01 | HK5: 31808 | HL5: 227 | HM5: 650447 | HN5: 0 | HO5: 0 | HP5: =HL5+HN5 -> 227 | HQ5: =HM5+HO5 -> 650447 | HR5: =HP5*J5 -> 243450.87 | HS5: =HQ5/$HQ$1 -> 0.059393439 | HT5: =B5 -> MR-01 | HU5: 392 | HV5: 2548 | HW5: 0 | HX5: =HU5+HV5+HW5 -> 2940 | HY5: =HX5*J5 -> 3153064.1 | HZ5: 3130 | IA5: =HZ5*J5 -> 3356833.6 | IB5: =HX5+HZ5 -> 6070 | IC5: =HY5+IA5 -> 6509897.7 | ID5: =B5 -> MR-01 | IE5: =C5 -> FBA79263 | IF5: =G5 -> B0CYSLCRQS | IG5: =B5 -> MR-01 | IH5: 57544 | II5: 267 | IJ5: 762248.02 | IK5: 0 | IL5: 0 | IM5: =II5+IK5 -> 267 | IN5: =IJ5+IL5 -> 762248.02 | IO5: =IM5*J5 -> 286349.7 | IP5: =IN5/$IN$1 -> 0.06722781 | IQ5: =B5 -> MR-01 | IR5: 772 | IS5: 2101 | IT5: 0 | IU5: =IR5+IS5+IT5 -> 2873 | IV5: =IU5*J5 -> 3081208.6 | IW5: 3130 | IX5: =IW5*J5 -> 3356833.6 | IY5: =IU5+IW5 -> 6003 | IZ5: =IV5+IX5 -> 6438042.1 | JA5: =B5 -> MR-01 | JB5: =C5 -> FBA79263 | JC5: =G5 -> B0CYSLCRQS | JD5: =B5 -> MR-01 | JE5: 58494 | JF5: 239 | JG5: 690999.26 | JH5: 0 | JI5: 0 | JJ5: =JF5+JH5 -> 239 | JK5: =JG5+JI5 -> 690999.26 | JL5: =JJ5*J5 -> 256320.52 | JM5: =JK5/$JK$1 -> 0.076422918 | JN5: =B5 -> MR-01 | JO5: 772 | JP5: 2101 | JQ5: 0 | JR5: =JO5+JP5+JQ5 -> 2873 | JS5: =JR5*AG5 -> 0 | JT5: 3130 | JU5: =JT5*AG5 -> 0 | JV5: =JR5+JT5 -> 6003 | JW5: =JS5+JU5 -> 0 | JX5: =B5 -> MR-01 | JY5: =C5 -> FBA79263 | JZ5: =G5 -> B0CYSLCRQS | KA5: =B5 -> MR-01 | KB5: 297966 | KC5: 519 | KD5: 1461641.5 | KE5: 0 | KF5: 0 | KG5: =KC5+KE5 -> 519 | KH5: =KD5+KF5 -> 1461641.5 | KI5: =KG5*J5 -> 556612.34 | KJ5: =KH5/$KH$1 -> 0.12386479 | KK5: =B5 -> MR-01 | KL5: 772 | KM5: 2101 | KN5: 0 | KO5: =KL5+KM5+KN5 -> 2873 | KP5: =KO5*BD5 -> 1491087 | KQ5: 3130 | KR5: =KQ5*BD5 -> 1624470 | KS5: =KO5+KQ5 -> 6003 | KT5: =KP5+KR5 -> 3115557 | KU5: =B5 -> MR-01 | KV5: =C5 -> FBA79263 | KW5: =G5 -> B0CYSLCRQS | KX5: =B5 -> MR-01 | KY5: 197065 | KZ5: 656 | LA5: 1807157.4 | LB5: 0 | LC5: 0 | LD5: =KZ5+LB5 -> 656 | LE5: =LA5+LC5 -> 1807157.4 | LF5: =LD5*J5 -> 703540.84 | LG5: =LE5/$LE$1 -> 0.13439036 | LH5: =B5 -> MR-01 | LI5: 772 | LJ5: 2101 | LK5: 0 | LL5: =LI5+LJ5+LK5 -> 2873 | LM5: =LL5*CA5 -> 16692130 | LN5: 3130 | LO5: =LN5*CA5 -> 18185300 | LP5: =LL5+LN5 -> 6003 | LQ5: =LM5+LO5 -> 34877430 | LR5: =B5 -> MR-01 | LS5: =C5 -> FBA79263 | LT5: =G5 -> B0CYSLCRQS | LU5: =B5 -> MR-01 | LV5: 482976 | LW5: 278 | LX5: 802320.94 | LY5: 0 | LZ5: 0 | MA5: =LW5+LY5 -> 278 | MB5: =LX5+LZ5 -> 802320.94 | MC5: =MA5*J5 -> 298146.88 | MD5: =MB5/$MB$1 -> 0.084575793 | ME5: =B5 -> MR-01 | MF5: 772 | MG5: 2101 | MH5: 0 | MI5: =MF5+MG5+MH5 -> 2873 | MJ5: =MI5*CX5 -> 1.6447491e+10 | MK5: 3130 | ML5: =MK5*CX5 -> 1.7918778e+10 | MM5: =MI5+MK5 -> 6003 | MN5: =MJ5+ML5 -> 3.4366269e+10 | MO5: =B5 -> MR-01 | MP5: =C5 -> FBA79263 | MQ5: =G5 -> B0CYSLCRQS | MR5: =B5 -> MR-01 | MS5: 486322 | MT5: 225 | MU5: 619000 | MV5: 0 | MW5: 0 | MX5: =MT5+MV5 -> 225 | MY5: =MU5+MW5 -> 619000 | MZ5: =MX5*J5 -> 241305.93 | NA5: =MY5/$MY$1 -> 0.049305583 | NB5: =B5 -> MR-01 | NC5: 772 | ND5: 2101 | NE5: 0 | NF5: =NC5+ND5+NE5 -> 2873 | NG5: =NF5*DU5 -> #VALUE! | NH5: 3130 | NI5: =NH5*DU5 -> #VALUE! | NJ5: =NF5+NH5 -> 6003 | NK5: =NG5+NI5 -> #VALUE! | NL5: =B5 -> MR-01 | NM5: =C5 -> FBA79263 | NN5: =G5 -> B0CYSLCRQS | NO5: =Y5 -> 0 | NP5: 454966 | NQ5: 275 | NR5: 699828 | NS5: 0 | NT5: 0 | NU5: =NQ5+NS5 -> 275 | NV5: =NR5+NT5 -> 699828 | NW5: =NU5*J5 -> 294929.47 | NX5: =NV5/$NV$1 -> 0.072698453 | NY5: =B5 -> MR-01 | NZ5: 772 | OA5: 2101 | OB5: 0 | OC5: =NZ5+OA5+OB5 -> 2873 | OD5: =OC5*ER5 -> #VALUE! | OE5: 3130 | OF5: =OE5*ER5 -> #VALUE! | OG5: =OC5+OE5 -> 6003 | OH5: =OD5+OF5 -> #VALUE! | OI5: =B5 -> MR-01 | OJ5: =C5 -> FBA79263 | OK5: =G5 -> B0CYSLCRQS | OL5: =B5 -> MR-01
A6: FBA79452 | B6: VC-01 | C6: FBA79452 | D6: Home & Kitchen | E6: Cleaning & Vacumming | F6: Nexlev | G6: B0DCGHVN81 | H6: Nexlev Handheld Vacuum Cleaner | I6: 832.33683 | J6: 982.15746 | K6: 0 | L6: 0 | M6: 0 | N6: =1-L6/M6 -> #DIV/0! | O6: 0 | P6: 0 | Q6: 0 | R6: =1-P6/Q6 -> #DIV/0! | S6: 0 | T6: 0 | U6: 0 | V6: =1-T6/U6 -> #DIV/0! | W6: 0 | X6: 0 | Y6: 0 | Z6: =1-X6/Y6 -> #DIV/0! | AA6: 0 | AB6: 0 | AC6: 0 | AD6: =1-AB6/AC6 -> #DIV/0! | AE6: 0 | AF6: 0 | AG6: 0 | AH6: =1-AF6/AG6 -> #DIV/0! | AI6: 0 | AJ6: 0 | AK6: 0 | AL6: =1-AJ6/AK6 -> #DIV/0! | AM6: 0 | AN6: 0 | AO6: 0 | AP6: =1-AN6/AO6 -> #DIV/0! | AQ6: 0 | AR6: 0 | AS6: 0 | AT6: =1-AR6/AS6 -> #DIV/0! | AU6: 0 | AV6: 0 | AW6: 0 | AX6: =1-AV6/AW6 -> #DIV/0! | AY6: 0 | AZ6: 0 | BA6: 0 | BB6: =1-AZ6/BA6 -> #DIV/0! | BC6: 9002 | BD6: 65 | BE6: 94 | BF6: =1-BD6/BE6 -> 0.30851064 | BG6: 24619 | BH6: 319 | BI6: 384 | BJ6: =1-BH6/BI6 -> 0.16927083 | BK6: 22634 | BL6: 493 | BM6: 1037136 | BN6: =BL6*J6 -> 484203.63 | BO6: 533 | BP6: 1067228 | BQ6: =1-BL6/BO6 -> 0.075046904 | BR6: =BM6/$BM$1 -> 0.084468286 | BS6: =B6 -> VC-01 | BT6: 6 | BU6: 1 | BV6: 0 | BW6: =BT6+BU6+BV6 -> 7 | BX6: =BW6*J6 -> 6875.1022 | BY6: 2004 | BZ6: =BY6*J6 -> 1968243.5 | CA6: =BW6+BY6 -> 2011 | CB6: =BX6+BZ6 -> 1975118.7 | CC6: =B6 -> VC-01 | CD6: =C6 -> FBA79452 | CE6: =G6 -> B0DCGHVN81 | CF6: =B6 -> VC-01 | CG6: 135 | CH6: 7 | CI6: 15393 | CJ6: =CH6*J6 -> 6875.1022 | CK6: 5 | CL6: 10995 | CM6: =1-CH6/CK6 -> -0.4 | CN6: =CI6/$CI$1 -> 0.0013562168 | CO6: =B6 -> VC-01 | CP6: 1206 | CQ6: 3 | CR6: 0 | CS6: =CP6+CQ6+CR6 -> 1209 | CT6: =CS6*J6 -> 1187428.4 | CU6: 2004 | CV6: =CU6*J6 -> 1968243.5 | CW6: =CS6+CU6 -> 3213 | CX6: =CT6+CV6 -> 3155671.9 | CY6: =B6 -> VC-01 | CZ6: =C6 -> FBA79452 | DA6: =G6 -> B0DCGHVN81 | DB6: =B6 -> VC-01 | DC6: 11523 | DD6: 76 | DE6: 157582 | DF6: =DD6*J6 -> 74643.967 | DG6: 90 | DH6: 173741 | DI6: =1-DD6/DG6 -> 0.15555556 | DJ6: =DE6/$DE$1 -> 0.012494885 | DK6: =B6 -> VC-01 | DL6: 345 | DM6: 1570 | DN6: 0 | DO6: =DL6+DM6+DN6 -> 1915 | DP6: =DO6*J6 -> 1880831.5 | DQ6: 2004 | DR6: =DQ6*J6 -> 1968243.5 | DS6: =DO6+DQ6 -> 3919 | DT6: =DP6+DR6 -> 3849075.1 | DU6: =B6 -> VC-01 | DV6: =C6 -> FBA79452 | DW6: =G6 -> B0DCGHVN81 | DX6: =B6 -> VC-01 | DY6: 14778 | DZ6: 108 | EA6: 225050 | EB6: =DZ6*J6 -> 106073.01 | EC6: 149 | ED6: 2,66,182.00 | EE6: =1-DZ6/EC6 -> 0.27516779 | EF6: =EA6/$EA$1 -> 0.025612756 | EG6: =B6 -> VC-01 | EH6: 414 | EI6: 1375 | EJ6: 0 | EK6: =EH6+EI6+EJ6 -> 1789 | EL6: =EK6*J6 -> 1757079.7 | EM6: 2004 | EN6: =EM6*J6 -> 1968243.5 | EO6: =EK6+EM6 -> 3793 | EP6: =EL6+EN6 -> 3725323.2 | EQ6: =B6 -> VC-01 | ER6: =C6 -> FBA79452 | ES6: =G6 -> B0DCGHVN81 | ET6: =B6 -> VC-01 | EU6: 20648 | EV6: 140 | EW6: 280479.58 | EX6: =EV6*J6 -> 137502.04 | EY6: 170 | EZ6: 3,01,863 | FA6: =1-EV6/EY6 -> 0.17647059 | FB6: =EW6/$EW$1 -> 0.04209 | FC6: =B6 -> VC-01 | FD6: 246 | FE6: 1297 | FF6: 0 | FG6: =FD6+FE6+FF6 -> 1543 | FH6: =FG6*J6 -> 1515469 | FI6: 2004 | FJ6: =FI6*J6 -> 1968243.5 | FK6: =FG6+FI6 -> 3547 | FL6: =FH6+FJ6 -> 3483712.5 | FM6: =B6 -> VC-01 | FN6: =C6 -> FBA79452 | FO6: =G6 -> B0DCGHVN81 | FP6: =B6 -> VC-01 | FQ6: 18612 | FR6: 145 | FS6: 261090 | FT6: 0 | FU6: 0 | FV6: =FR6+FT6 -> 145 | FW6: =FS6+FU6 -> 261090 | FX6: =FV6*J6 -> 142412.83 | FY6: =FW6/$FW$1 -> 0.027873099 | FZ6: =B6 -> VC-01 | GA6: 0 | GB6: 1015 | GC6: 0 | GD6: =GA6+GB6+GC6 -> 1015 | GE6: =GD6*J6 -> 996889.82 | GF6: 2004 | GG6: =GF6*J6 -> 1968243.5 | GH6: =GD6+GF6 -> 3019 | GI6: =GE6+GG6 -> 2965133.4 | GJ6: =B6 -> VC-01 | GK6: =C6 -> FBA79452 | GL6: =G6 -> B0DCGHVN81 | GM6: =B6 -> VC-01 | GN6: 25662 | GO6: 277 | GP6: 513101.58 | GQ6: 0 | GR6: 0 | GS6: =GO6+GQ6 -> 277 | GT6: =GP6+GR6 -> 513101.58 | GU6: =GS6*J6 -> 272057.62 | GV6: =GT6/$GT$1 -> 0.054214023 | GW6: =B6 -> VC-01 | GX6: 463 | GY6: 118 | GZ6: 0 | HA6: =GX6+GY6+GZ6 -> 581 | HB6: =HA6*J6 -> 570633.48 | HC6: 2004 | HD6: =HC6*J6 -> 1968243.5 | HE6: =HA6+HC6 -> 2585 | HF6: =HB6+HD6 -> 2538877 | HG6: =B6 -> VC-01 | HH6: =C6 -> FBA79452 | HI6: =G6 -> B0DCGHVN81 | HJ6: =B6 -> VC-01 | HK6: 23567 | HL6: 205 | HM6: 409043 | HN6: 0 | HO6: 0 | HP6: =HL6+HN6 -> 205 | HQ6: =HM6+HO6 -> 409043 | HR6: =HP6*J6 -> 201342.28 | HS6: =HQ6/$HQ$1 -> 0.037350423 | HT6: =B6 -> VC-01 | HU6: 475 | HV6: 1404 | HW6: 0 | HX6: =HU6+HV6+HW6 -> 1879 | HY6: =HX6*J6 -> 1845473.9 | HZ6: 2004 | IA6: =HZ6*J6 -> 1968243.5 | IB6: =HX6+HZ6 -> 3883 | IC6: =HY6+IA6 -> 3813717.4 | ID6: =B6 -> VC-01 | IE6: =C6 -> FBA79452 | IF6: =G6 -> B0DCGHVN81 | IG6: =B6 -> VC-01 | IH6: 19726 | II6: 195 | IJ6: 383503.77 | IK6: 0 | IL6: 0 | IM6: =II6+IK6 -> 195 | IN6: =IJ6+IL6 -> 383503.77 | IO6: =IM6*J6 -> 191520.7 | IP6: =IN6/$IN$1 -> 0.033823792 | IQ6: =B6 -> VC-01 | IR6: 601 | IS6: 1270 | IT6: 0 | IU6: =IR6+IS6+IT6 -> 1871 | IV6: =IU6*J6 -> 1837616.6 | IW6: 2004 | IX6: =IW6*J6 -> 1968243.5 | IY6: =IU6+IW6 -> 3875 | IZ6: =IV6+IX6 -> 3805860.2 | JA6: =B6 -> VC-01 | JB6: =C6 -> FBA79452 | JC6: =G6 -> B0DCGHVN81 | JD6: =B6 -> VC-01 | JE6: 19816 | JF6: 106 | JG6: 210160.3 | JH6: 0 | JI6: 0 | JJ6: =JF6+JH6 -> 106 | JK6: =JG6+JI6 -> 210160.3 | JL6: =JJ6*J6 -> 104108.69 | JM6: =JK6/$JK$1 -> 0.023243243 | JN6: =B6 -> VC-01 | JO6: 601 | JP6: 1270 | JQ6: 0 | JR6: =JO6+JP6+JQ6 -> 1871 | JS6: =JR6*AG6 -> 0 | JT6: 2004 | JU6: =JT6*AG6 -> 0 | JV6: =JR6+JT6 -> 3875 | JW6: =JS6+JU6 -> 0 | JX6: =B6 -> VC-01 | JY6: =C6 -> FBA79452 | JZ6: =G6 -> B0DCGHVN81 | KA6: =B6 -> VC-01 | KB6: 32376 | KC6: 164 | KD6: 318413.02 | KE6: 0 | KF6: 0 | KG6: =KC6+KE6 -> 164 | KH6: =KD6+KF6 -> 318413.02 | KI6: =KG6*J6 -> 161073.82 | KJ6: =KH6/$KH$1 -> 0.026983473 | KK6: =B6 -> VC-01 | KL6: 601 | KM6: 1270 | KN6: 0 | KO6: =KL6+KM6+KN6 -> 1871 | KP6: =KO6*BD6 -> 121615 | KQ6: 2004 | KR6: =KQ6*BD6 -> 130260 | KS6: =KO6+KQ6 -> 3875 | KT6: =KP6+KR6 -> 251875 | KU6: =B6 -> VC-01 | KV6: =C6 -> FBA79452 | KW6: =G6 -> B0DCGHVN81 | KX6: =B6 -> VC-01 | KY6: 25198 | KZ6: 250 | LA6: 478149.44 | LB6: 0 | LC6: 0 | LD6: =KZ6+LB6 -> 250 | LE6: =LA6+LC6 -> 478149.44 | LF6: =LD6*J6 -> 245539.36 | LG6: =LE6/$LE$1 -> 0.035557875 | LH6: =B6 -> VC-01 | LI6: 601 | LJ6: 1270 | LK6: 0 | LL6: =LI6+LJ6+LK6 -> 1871 | LM6: =LL6*CA6 -> 3762581 | LN6: 2004 | LO6: =LN6*CA6 -> 4030044 | LP6: =LL6+LN6 -> 3875 | LQ6: =LM6+LO6 -> 7792625 | LR6: =B6 -> VC-01 | LS6: =C6 -> FBA79452 | LT6: =G6 -> B0DCGHVN81 | LU6: =B6 -> VC-01 | LV6: 36838 | LW6: 99 | LX6: 196467.15 | LY6: 0 | LZ6: 0 | MA6: =LW6+LY6 -> 99 | MB6: =LX6+LZ6 -> 196467.15 | MC6: =MA6*J6 -> 97233.588 | MD6: =MB6/$MB$1 -> 0.020710372 | ME6: =B6 -> VC-01 | MF6: 601 | MG6: 1270 | MH6: 0 | MI6: =MF6+MG6+MH6 -> 1871 | MJ6: =MI6*CX6 -> 5.9042622e+09 | MK6: 2004 | ML6: =MK6*CX6 -> 6.3239665e+09 | MM6: =MI6+MK6 -> 3875 | MN6: =MJ6+ML6 -> 1.2228229e+10 | MO6: =B6 -> VC-01 | MP6: =C6 -> FBA79452 | MQ6: =G6 -> B0DCGHVN81 | MR6: =B6 -> VC-01 | MS6: 26737 | MT6: 173 | MU6: 322713 | MV6: 0 | MW6: 0 | MX6: =MT6+MV6 -> 173 | MY6: =MU6+MW6 -> 322713 | MZ6: =MX6*J6 -> 169913.24 | NA6: =MY6/$MY$1 -> 0.025705255 | NB6: =B6 -> VC-01 | NC6: 601 | ND6: 1270 | NE6: 0 | NF6: =NC6+ND6+NE6 -> 1871 | NG6: =NF6*DU6 -> #VALUE! | NH6: 2004 | NI6: =NH6*DU6 -> #VALUE! | NJ6: =NF6+NH6 -> 3875 | NK6: =NG6+NI6 -> #VALUE! | NL6: =B6 -> VC-01 | NM6: =C6 -> FBA79452 | NN6: =G6 -> B0DCGHVN81 | NO6: =Y6 -> 0 | NP6: 28712 | NQ6: 193 | NR6: 337698 | NS6: 0 | NT6: 0 | NU6: =NQ6+NS6 -> 193 | NV6: =NR6+NT6 -> 337698 | NW6: =NU6*J6 -> 189556.39 | NX6: =NV6/$NV$1 -> 0.035080223 | NY6: =B6 -> VC-01 | NZ6: 601 | OA6: 1270 | OB6: 0 | OC6: =NZ6+OA6+OB6 -> 1871 | OD6: =OC6*ER6 -> #VALUE! | OE6: 2004 | OF6: =OE6*ER6 -> #VALUE! | OG6: =OC6+OE6 -> 3875 | OH6: =OD6+OF6 -> #VALUE! | OI6: =B6 -> VC-01 | OJ6: =C6 -> FBA79452 | OK6: =G6 -> B0DCGHVN81 | OL6: =B6 -> VC-01
A7: FBA79439 | B7: MR-02 | C7: FBA79439 | D7: Home & Kitchen | E7: Cleaning & Vacumming | F7: Nexlev | G7: B0DCK7ZH5P | H7: Nexlev Cordless Mite Remover | I7: 999.7609 | J7: 1179.7179 | K7: 0 | L7: 0 | M7: 0 | N7: =1-L7/M7 -> #DIV/0! | O7: 0 | P7: 0 | Q7: 0 | R7: =1-P7/Q7 -> #DIV/0! | S7: 0 | T7: 0 | U7: 0 | V7: =1-T7/U7 -> #DIV/0! | W7: 0 | X7: 0 | Y7: 0 | Z7: =1-X7/Y7 -> #DIV/0! | AA7: 0 | AB7: 0 | AC7: 0 | AD7: =1-AB7/AC7 -> #DIV/0! | AE7: 0 | AF7: 0 | AG7: 0 | AH7: =1-AF7/AG7 -> #DIV/0! | AI7: 0 | AJ7: 0 | AK7: 0 | AL7: =1-AJ7/AK7 -> #DIV/0! | AM7: 0 | AN7: 0 | AO7: 0 | AP7: =1-AN7/AO7 -> #DIV/0! | AQ7: 0 | AR7: 0 | AS7: 0 | AT7: =1-AR7/AS7 -> #DIV/0! | AU7: 0 | AV7: 0 | AW7: 0 | AX7: =1-AV7/AW7 -> #DIV/0! | AY7: 0 | AZ7: 0 | BA7: 0 | BB7: =1-AZ7/BA7 -> #DIV/0! | BC7: 14548 | BD7: 217 | BE7: 286 | BF7: =1-BD7/BE7 -> 0.24125874 | BG7: 43903 | BH7: 376 | BI7: 402 | BJ7: =1-BH7/BI7 -> 0.064676617 | BK7: 22383 | BL7: 247 | BM7: 976155 | BN7: =BL7*J7 -> 291390.31 | BO7: 266 | BP7: 1027819 | BQ7: =1-BL7/BO7 -> 0.071428571 | BR7: =BM7/$BM$1 -> 0.079501763 | BS7: =B7 -> MR-02 | BT7: 89 | BU7: 17 | BV7: 1500 | BW7: =BT7+BU7+BV7 -> 1606 | BX7: =BW7*J7 -> 1894626.9 | BY7: 1500 | BZ7: =BY7*J7 -> 1769576.8 | CA7: =BW7+BY7 -> 3106 | CB7: =BX7+BZ7 -> 3664203.7 | CC7: =B7 -> MR-02 | CD7: =C7 -> FBA79439 | CE7: =G7 -> B0DCK7ZH5P | CF7: =B7 -> MR-02 | CG7: 18851 | CH7: 159 | CI7: 641339.1 | CJ7: =CH7*J7 -> 187575.14 | CK7: 185 | CL7: 725892 | CM7: =1-CH7/CK7 -> 0.14054054 | CN7: =CI7/$CI$1 -> 0.05650587 | CO7: =B7 -> MR-02 | CP7: 596 | CQ7: 870 | CR7: 1500 | CS7: =CP7+CQ7+CR7 -> 2966 | CT7: =CS7*J7 -> 3499043.2 | CU7: 1500 | CV7: =CU7*J7 -> 1769576.8 | CW7: =CS7+CU7 -> 4466 | CX7: =CT7+CV7 -> 5268620 | CY7: =B7 -> MR-02 | CZ7: =C7 -> FBA79439 | DA7: =G7 -> B0DCK7ZH5P | DB7: =B7 -> MR-02 | DC7: 39422 | DD7: 347 | DE7: 1225063.9 | DF7: =DD7*J7 -> 409362.1 | DG7: 401 | DH7: 1380570 | DI7: =1-DD7/DG7 -> 0.13466334 | DJ7: =DE7/$DE$1 -> 0.097136934 | DK7: =B7 -> MR-02 | DL7: 567 | DM7: 569 | DN7: 1500 | DO7: =DL7+DM7+DN7 -> 2636 | DP7: =DO7*J7 -> 3109736.3 | DQ7: 1500 | DR7: =DQ7*J7 -> 1769576.8 | DS7: =DO7+DQ7 -> 4136 | DT7: =DP7+DR7 -> 4879313.1 | DU7: =B7 -> MR-02 | DV7: =C7 -> FBA79439 | DW7: =G7 -> B0DCK7ZH5P | DX7: =B7 -> MR-02 | DY7: 28955 | DZ7: 134 | EA7: 474622 | EB7: =DZ7*J7 -> 158082.19 | EC7: 163 | ED7: 5,58,203.00 | EE7: =1-DZ7/EC7 -> 0.17791411 | EF7: =EA7/$EA$1 -> 0.054016342 | EG7: =B7 -> MR-02 | EH7: 490 | EI7: 1664 | EJ7: 1500 | EK7: =EH7+EI7+EJ7 -> 3654 | EL7: =EK7*J7 -> 4310689.1 | EM7: 1500 | EN7: =EM7*J7 -> 1769576.8 | EO7: =EK7+EM7 -> 5154 | EP7: =EL7+EN7 -> 6080265.9 | EQ7: =B7 -> MR-02 | ER7: =C7 -> FBA79439 | ES7: =G7 -> B0DCK7ZH5P | ET7: =B7 -> MR-02 | EU7: 31297 | EV7: 108 | EW7: 351934 | EX7: =EV7*J7 -> 127409.53 | EY7: 132 | EZ7: 4,12,191 | FA7: =1-EV7/EY7 -> 0.18181818 | FB7: =EW7/$EW$1 -> 0.052812764 | FC7: =B7 -> MR-02 | FD7: 373 | FE7: 1549 | FF7: 1500 | FG7: =FD7+FE7+FF7 -> 3422 | FH7: =FG7*J7 -> 4036994.5 | FI7: 1500 | FJ7: =FI7*J7 -> 1769576.8 | FK7: =FG7+FI7 -> 4922 | FL7: =FH7+FJ7 -> 5806571.3 | FM7: =B7 -> MR-02 | FN7: =C7 -> FBA79439 | FO7: =G7 -> B0DCK7ZH5P | FP7: =B7 -> MR-02 | FQ7: 28460 | FR7: 181 | FS7: 588256 | FT7: 0 | FU7: 0 | FV7: =FR7+FT7 -> 181 | FW7: =FS7+FU7 -> 588256 | FX7: =FV7*J7 -> 213528.93 | FY7: =FW7/$FW$1 -> 0.062800253 | FZ7: =B7 -> MR-02 | GA7: 0 | GB7: 1259 | GC7: 1500 | GD7: =GA7+GB7+GC7 -> 2759 | GE7: =GD7*J7 -> 3254841.6 | GF7: 1500 | GG7: =GF7*J7 -> 1769576.8 | GH7: =GD7+GF7 -> 4259 | GI7: =GE7+GG7 -> 5024418.4 | GJ7: =B7 -> MR-02 | GK7: =C7 -> FBA79439 | GL7: =G7 -> B0DCK7ZH5P | GM7: =B7 -> MR-02 | GN7: 28472 | GO7: 185 | GP7: 599956 | GQ7: 0 | GR7: 0 | GS7: =GO7+GQ7 -> 185 | GT7: =GP7+GR7 -> 599956 | GU7: =GS7*J7 -> 218247.81 | GV7: =GT7/$GT$1 -> 0.063391012 | GW7: =B7 -> MR-02 | GX7: 148 | GY7: 1222 | GZ7: 1500 | HA7: =GX7+GY7+GZ7 -> 2870 | HB7: =HA7*J7 -> 3385790.3 | HC7: 1500 | HD7: =HC7*J7 -> 1769576.8 | HE7: =HA7+HC7 -> 4370 | HF7: =HB7+HD7 -> 5155367.1 | HG7: =B7 -> MR-02 | HH7: =C7 -> FBA79439 | HI7: =G7 -> B0DCK7ZH5P | HJ7: =B7 -> MR-02 | HK7: 39511 | HL7: 132 | HM7: 437850 | HN7: 0 | HO7: 0 | HP7: =HL7+HN7 -> 132 | HQ7: =HM7+HO7 -> 437850 | HR7: =HP7*J7 -> 155722.76 | HS7: =HQ7/$HQ$1 -> 0.03998084 | HT7: =B7 -> MR-02 | HU7: 549 | HV7: 552 | HW7: 1500 | HX7: =HU7+HV7+HW7 -> 2601 | HY7: =HX7*J7 -> 3068446.2 | HZ7: 1500 | IA7: =HZ7*J7 -> 1769576.8 | IB7: =HX7+HZ7 -> 4101 | IC7: =HY7+IA7 -> 4838023 | ID7: =B7 -> MR-02 | IE7: =C7 -> FBA79439 | IF7: =G7 -> B0DCK7ZH5P | IG7: =B7 -> MR-02 | IH7: 48112 | II7: 265 | IJ7: 842524.23 | IK7: 0 | IL7: 0 | IM7: =II7+IK7 -> 265 | IN7: =IJ7+IL7 -> 842524.23 | IO7: =IM7*J7 -> 312625.23 | IP7: =IN7/$IN$1 -> 0.074307912 | IQ7: =B7 -> MR-02 | IR7: 641 | IS7: 414 | IT7: 1500 | IU7: =IR7+IS7+IT7 -> 2555 | IV7: =IU7*J7 -> 3014179.2 | IW7: 1500 | IX7: =IW7*J7 -> 1769576.8 | IY7: =IU7+IW7 -> 4055 | IZ7: =IV7+IX7 -> 4783756 | JA7: =B7 -> MR-02 | JB7: =C7 -> FBA79439 | JC7: =G7 -> B0DCK7ZH5P | JD7: =B7 -> MR-02 | JE7: 48864 | JF7: 202 | JG7: 651632.62 | JH7: 0 | JI7: 0 | JJ7: =JF7+JH7 -> 202 | JK7: =JG7+JI7 -> 651632.62 | JL7: =JJ7*J7 -> 238303.01 | JM7: =JK7/$JK$1 -> 0.072069059 | JN7: =B7 -> MR-02 | JO7: 641 | JP7: 414 | JQ7: 1500 | JR7: =JO7+JP7+JQ7 -> 2555 | JS7: =JR7*AG7 -> 0 | JT7: 1500 | JU7: =JT7*AG7 -> 0 | JV7: =JR7+JT7 -> 4055 | JW7: =JS7+JU7 -> 0 | JX7: =B7 -> MR-02 | JY7: =C7 -> FBA79439 | JZ7: =G7 -> B0DCK7ZH5P | KA7: =B7 -> MR-02 | KB7: 74655 | KC7: 332 | KD7: 1067157.1 | KE7: 0 | KF7: 0 | KG7: =KC7+KE7 -> 332 | KH7: =KD7+KF7 -> 1067157.1 | KI7: =KG7*J7 -> 391666.33 | KJ7: =KH7/$KH$1 -> 0.090434756 | KK7: =B7 -> MR-02 | KL7: 641 | KM7: 414 | KN7: 1500 | KO7: =KL7+KM7+KN7 -> 2555 | KP7: =KO7*BD7 -> 554435 | KQ7: 1500 | KR7: =KQ7*BD7 -> 325500 | KS7: =KO7+KQ7 -> 4055 | KT7: =KP7+KR7 -> 879935 | KU7: =B7 -> MR-02 | KV7: =C7 -> FBA79439 | KW7: =G7 -> B0DCK7ZH5P | KX7: =B7 -> MR-02 | KY7: 38750 | KZ7: 279 | LA7: 871760.31 | LB7: 0 | LC7: 0 | LD7: =KZ7+LB7 -> 279 | LE7: =LA7+LC7 -> 871760.31 | LF7: =LD7*J7 -> 329141.29 | LG7: =LE7/$LE$1 -> 0.064828988 | LH7: =B7 -> MR-02 | LI7: 641 | LJ7: 414 | LK7: 1500 | LL7: =LI7+LJ7+LK7 -> 2555 | LM7: =LL7*CA7 -> 7935830 | LN7: 1500 | LO7: =LN7*CA7 -> 4659000 | LP7: =LL7+LN7 -> 4055 | LQ7: =LM7+LO7 -> 12594830 | LR7: =B7 -> MR-02 | LS7: =C7 -> FBA79439 | LT7: =G7 -> B0DCK7ZH5P | LU7: =B7 -> MR-02 | LV7: 100155 | LW7: 192 | LX7: 627659.8 | LY7: 0 | LZ7: 0 | MA7: =LW7+LY7 -> 192 | MB7: =LX7+LZ7 -> 627659.8 | MC7: =MA7*J7 -> 226505.83 | MD7: =MB7/$MB$1 -> 0.066164078 | ME7: =B7 -> MR-02 | MF7: 641 | MG7: 414 | MH7: 1500 | MI7: =MF7+MG7+MH7 -> 2555 | MJ7: =MI7*CX7 -> 1.3461324e+10 | MK7: 1500 | ML7: =MK7*CX7 -> 7.90293e+09 | MM7: =MI7+MK7 -> 4055 | MN7: =MJ7+ML7 -> 2.1364254e+10 | MO7: =B7 -> MR-02 | MP7: =C7 -> FBA79439 | MQ7: =G7 -> B0DCK7ZH5P | MR7: =B7 -> MR-02 | MS7: 68949 | MT7: 166 | MU7: 536530 | MV7: 0 | MW7: 0 | MX7: =MT7+MV7 -> 166 | MY7: =MU7+MW7 -> 536530 | MZ7: =MX7*J7 -> 195833.17 | NA7: =MY7/$MY$1 -> 0.04273655 | NB7: =B7 -> MR-02 | NC7: 641 | ND7: 414 | NE7: 1500 | NF7: =NC7+ND7+NE7 -> 2555 | NG7: =NF7*DU7 -> #VALUE! | NH7: 1500 | NI7: =NH7*DU7 -> #VALUE! | NJ7: =NF7+NH7 -> 4055 | NK7: =NG7+NI7 -> #VALUE! | NL7: =B7 -> MR-02 | NM7: =C7 -> FBA79439 | NN7: =G7 -> B0DCK7ZH5P | NO7: =Y7 -> 0 | NP7: 61086 | NQ7: 119 | NR7: 394747 | NS7: 0 | NT7: 0 | NU7: =NQ7+NS7 -> 119 | NV7: =NR7+NT7 -> 394747 | NW7: =NU7*J7 -> 140386.43 | NX7: =NV7/$NV$1 -> 0.041006499 | NY7: =B7 -> MR-02 | NZ7: 641 | OA7: 414 | OB7: 1500 | OC7: =NZ7+OA7+OB7 -> 2555 | OD7: =OC7*ER7 -> #VALUE! | OE7: 1500 | OF7: =OE7*ER7 -> #VALUE! | OG7: =OC7+OE7 -> 4055 | OH7: =OD7+OF7 -> #VALUE! | OI7: =B7 -> MR-02 | OJ7: =C7 -> FBA79439 | OK7: =G7 -> B0DCK7ZH5P | OL7: =B7 -> MR-02
