Workbook

Sheet Master
A1: SKU | B1: ASIN | C1: Model | D1: Category - L1 | E1: Category - L2 | F1: Fee Category | G1: Product Name | H1: HSN | I1: Latest FOB | J1: Freight+Clearance | K1: L (cm) | L1: B (cm) | M1: H (cm) | N1: CBM per unit | O1: Import Duty % | P1: Duty and Surcharge | Q1: DP | R1: NLC | S1: Referral Fee % | T1: Fixed Closing Fee | U1: Fulfillment Fees | V1: AMS % | W1: Coupon % | X1: Returns Loss % | Y1: SMM | Z1: GST Slab | AA1: GST in SP | AB1: Business overhead expenses | AC1: Cost of finance | AD1: Additional Cost | AE1: BAU Deal SP | AF1: MRP | AG1: Gross Margin | AH1: Gross Margin % | AI1: BAU SP/MOP(MP) | AJ1: Deals | AK1: Art deals | AL1: MOP(B2B) | AM1: MOP(D2C)
A2: FBA75673 | B2: B0B4DPX2J2 | C2: AM-C1 | D2: Microphone | E2: Condenser Mic with Boom Arm | F2: 0.11 | G2: AM-C1 | H2: 85181000 | I2: 11 | J2: ='Edit Parameters'!$B$2/('Edit Parameters'!$B$3/N2) | K2: 42.4 | L2: 20.8 | M2: 8.8 | N2: =(K2*L2*M2)/1000000 | O2: 15 | P2: =(I2+J2)*(O2%+(O2%*10%)) | Q2: =(I2+J2+P2)*'Edit Parameters'!B$1 | R2: =Q2*1.18 | S2: 11 | T2: 51 | U2: 114 | V2: 10 | W2: 2 | X2: 5 | Y2: 0 | Z2: 18 | AA2: =AE2-(AE2/1.18) | AB2: =R2*0.05 | AC2: =R2*0.03 | AD2: 0 | AE2: 2699 | AF2: 4999 | AI2: 2699
A3: FBA76864 | B3: B0BPLZ5CGV | C3: AI-04 Red | D3: Audio Interface | E3: 4 Channel Audio Interface | F3: 0.11 | G3: AI-04 Red | H3: 85437029 | I3: 18 | J3: ='Edit Parameters'!$B$2/('Edit Parameters'!$B$3/N3) | K3: 26.4 | L3: 14 | M3: 7 | N3: =(K3*L3*M3)/1000000 | O3: 7.5 | P3: =(I3+J3)*(O3%+(O3%*10%)) | Q3: =(I3+J3+P3)*'Edit Parameters'!B$1 | R3: =Q3*1.18 | S3: 11 | T3: 51 | U3: 76 | V3: 10 | W3: 2 | X3: 5 | Y3: 0 | Z3: 18 | AA3: =AE3-(AE3/1.18) | AB3: =R3*0.05 | AC3: =R3*0.03 | AD3: 0 | AE3: 4398 | AF3: 9999 | AI3: 4599
A4: FBA79482 | B4: B0DXFPM4N2 | C4: AM-S1 | D4: Speaker | E4: Studio Monitor Speaker | F4: 0.11 | G4: AM-S1 | H4: 85182290 | I4: 32.85 | J4: ='Edit Parameters'!$B$2/('Edit Parameters'!$B$3/N4) | K4: 38.5 | L4: 29.2 | M4: 21.3 | N4: =(K4*L4*M4)/1000000 | O4: 20 | P4: =(I4+J4)*(O4%+(O4%*10%)) | Q4: =(I4+J4+P4)*'Edit Parameters'!B$1 | R4: =Q4*1.18 | S4: 11 | T4: 51 | U4: 213 | V4: 10 | W4: 2 | X4: 5 | Y4: 0 | Z4: 18 | AA4: =AE4-(AE4/1.18) | AB4: =R4*0.05 | AC4: =R4*0.03 | AD4: 0 | AE4: 7999 | AF4: 12999 | AI4: 8799
A5: FBA79103 | B5: B0CM6NTWBP | C5: AI-10 | D5: Audio Interface | E5: Audio Interface | F5: 0.11 | G5: AI-10 | H5: 85437029 | I5: 11.5 | J5: ='Edit Parameters'!$B$2/('Edit Parameters'!$B$3/N5) | K5: 25.3 | L5: 15 | M5: 5.7 | N5: =(K5*L5*M5)/1000000 | O5: 7.5 | P5: =(I5+J5)*(O5%+(O5%*10%)) | Q5: =(I5+J5+P5)*'Edit Parameters'!B$1 | R5: =Q5*1.18 | S5: 11 | T5: 51 | U5: 76 | V5: 10 | W5: 2 | X5: 5 | Y5: 0 | Z5: 18 | AA5: =AE5-(AE5/1.18) | AB5: =R5*0.05 | AC5: =R5*0.03 | AD5: 0 | AE5: 2749 | AF5: 6999 | AI5: 3249
A6: FBA79816 | B6: B0FPR962YS | C6: AM-W22 | D6: Microphone | E6: Wireless Lapel Microphone | F6: 0.11 | G6: AM-W22 | H6: 85181000 | I6: 12.88 | J6: ='Edit Parameters'!$B$2/('Edit Parameters'!$B$3/N6) | K6: 11.7 | L6: 8.2 | M6: 6.8 | N6: =(K6*L6*M6)/1000000 | O6: 15 | P6: =(I6+J6)*(O6%+(O6%*10%)) | Q6: =(I6+J6+P6)*'Edit Parameters'!B$1 | R6: =Q6*1.18 | S6: 11 | T6: 51 | U6: 59 | V6: 10 | W6: 2 | X6: 5 | Y6: 0 | Z6: 18 | AA6: =AE6-(AE6/1.18) | AB6: =R6*0.05 | AC6: =R6*0.03 | AD6: 0 | AE6: 2999 | AF6: 6499 | AI6: 3599
A7: FBA79005 | B7: B0CKHVHVQ1 | C7: AM-W45 | D7: Microphone | E7: Wireless Conference Microphone | F7: 0.11 | G7: AM-W45 | H7: 85181000 | I7: 21.7 | J7: ='Edit Parameters'!$B$2/('Edit Parameters'!$B$3/N7) | K7: 18 | L7: 16.7 | M7: 5.7 | N7: =(K7*L7*M7)/1000000 | O7: 15 | P7: =(I7+J7)*(O7%+(O7%*10%)) | Q7: =(I7+J7+P7)*'Edit Parameters'!B$1 | R7: =Q7*1.18 | S7: 11 | T7: 51 | U7: 143.94915 | V7: 10 | W7: 2 | X7: 5 | Y7: 0 | Z7: 18 | AA7: =AE7-(AE7/1.18) | AB7: =R7*0.05 | AC7: =R7*0.03 | AD7: 0 | AE7: 4990 | AF7: 9999 | AI7: 4999
A8: FBA79380 | B8: B0D3M1B4Z8 | C8: AM-C46 | D8: Microphone | E8: RGB Condenser Mic with Boom Arm | F8: 0.11 | G8: AM-C46 | H8: 85181000 | I8: 15.5 | J8: ='Edit Parameters'!$B$2/('Edit Parameters'!$B$3/N8) | K8: 43.6 | L8: 17 | M8: 10.4 | N8: =(K8*L8*M8)/1000000 | O8: 15 | P8: =(I8+J8)*(O8%+(O8%*10%)) | Q8: =(I8+J8+P8)*'Edit Parameters'!B$1 | R8: =Q8*1.18 | S8: 11 | T8: 51 | U8: 114 | V8: 10 | W8: 2 | X8: 5 | Y8: 0 | Z8: 18 | AA8: =AE8-(AE8/1.18) | AB8: =R8*0.05 | AC8: =R8*0.03 | AD8: 0 | AE8: 3599 | AF8: 7999 | AI8: 3549
A9: FBA78975 | B9: B0CF5TCQKL | C9: AA-21 | D9: Speaker Accessories | E9: Speaker Stand | F9: 0.11 | G9: AA-21 | H9: 85189000 | I9: 12.8 | J9: ='Edit Parameters'!$B$2/('Edit Parameters'!$B$3/N9) | K9: 29.5 | L9: 27.3 | M9: 10.5 | N9: =(K9*L9*M9)/1000000 | O9: 15 | P9: =(I9+J9)*(O9%+(O9%*10%)) | Q9: =(I9+J9+P9)*'Edit Parameters'!B$1 | R9: =Q9*1.18 | S9: 11 | T9: 51 | U9: 214 | V9: 10 | W9: 2 | X9: 5 | Y9: 0 | Z9: 18 | AA9: =AE9-(AE9/1.18) | AB9: =R9*0.05 | AC9: =R9*0.03 | AD9: 0 | AE9: 3799 | AF9: 7399 | AI9: 3699
A10: FBA79815 | B10: B0FPR7VFCH | C10: AM-W19 | D10: Microphone | E10: Wireless Lapel Microphone | F10: 0.11 | G10: AM-W19 | H10: 85181000 | I10: 8.89 | J10: ='Edit Parameters'!$B$2/('Edit Parameters'!$B$3/N10) | K10: 12.1 | L10: 8.2 | M10: 3.4 | N10: =(K10*L10*M10)/1000000 | O10: 15 | P10: =(I10+J10)*(O10%+(O10%*10%)) | Q10: =(I10+J10+P10)*'Edit Parameters'!B$1 | R10: =Q10*1.18 | S10: 11 | T10: 51 | U10: 59 | V10: 10 | W10: 2 | X10: 5 | Y10: 0 | Z10: 18 | AA10: =AE10-(AE10/1.18) | AB10: =R10*0.05 | AC10: =R10*0.03 | AD10: 0 | AE10: 2199 | AF10: 3999 | AI10: 1999
A11: FBA79379 | B11: B0D3LZWTHV | C11: AM-C45 | D11: Microphone | E11: RGB Dynamic Microphone | F11: 0.11 | G11: AM-C45 | H11: 85181000 | I11: 15.5 | J11: ='Edit Parameters'!$B$2/('Edit Parameters'!$B$3/N11) | K11: 24.7 | L11: 17.5 | M11: 7.9 | N11: =(K11*L11*M11)/1000000 | O11: 15 | P11: =(I11+J11)*(O11%+(O11%*10%)) | Q11: =(I11+J11+P11)*'Edit Parameters'!B$1 | R11: =Q11*1.18 | S11: 11 | T11: 51 | U11: 76 | V11: 10 | W11: 2 | X11: 5 | Y11: 0 | Z11: 18 | AA11: =AE11-(AE11/1.18) | AB11: =R11*0.05 | AC11: =R11*0.03 | AD11: 0 | AE11: 3499 | AF11: 7499 | AI11: 3499
A12: FBA79011 | B12: B0CH4RNWJX | C12: AM-C43 | D12: Microphone | E12: XLR Condenser Microphone Kit - Boomarm | F12: 0.11 | G12: AM-C43 | H12: 85181000 | I12: 10 | J12: ='Edit Parameters'!$B$2/('Edit Parameters'!$B$3/N12) | K12: 42.5 | L12: 20.7 | M12: 7.3 | N12: =(K12*L12*M12)/1000000 | O12: 15 | P12: =(I12+J12)*(O12%+(O12%*10%)) | Q12: =(I12+J12+P12)*'Edit Parameters'!B$1 | R12: =Q12*1.18 | S12: 11 | T12: 51 | U12: 114 | V12: 10 | W12: 2 | X12: 5 | Y12: 0 | Z12: 18 | AA12: =AE12-(AE12/1.18) | AB12: =R12*0.05 | AC12: =R12*0.03 | AD12: 0 | AE12: 2499 | AF12: 5999 | AI12: 2499
A13: FBA79446 | B13: B0DFMMTWLY | C13: AM-W33 | D13: Microphone | E13: Wireless UHF Microphone | F13: 0.11 | G13: AM-W33 | H13: 85181000 | I13: 9.16 | J13: ='Edit Parameters'!$B$2/('Edit Parameters'!$B$3/N13) | K13: 30.2 | L13: 12.8 | M13: 6.3 | N13: =(K13*L13*M13)/1000000 | O13: 15 | P13: =(I13+J13)*(O13%+(O13%*10%)) | Q13: =(I13+J13+P13)*'Edit Parameters'!B$1 | R13: =Q13*1.18 | S13: 11 | T13: 51 | U13: 76 | V13: 10 | W13: 2 | X13: 5 | Y13: 0 | Z13: 18 | AA13: =AE13-(AE13/1.18) | AB13: =R13*0.05 | AC13: =R13*0.03 | AD13: 0 | AE13: 1799 | AF13: 3299 | AI13: 1999
... A36: FBA79838 | B36: B0FQBX8J17 | C36: AH-40 SL | D36: Headphone | E36: DJ Headphone | F36: 0.11 | G36: AH-40 SL | H36: 85183020 | I36: 3.5 | J36: ='Edit Parameters'!$B$2/('Edit Parameters'!$B$3/N36) | K36: 18.9 | L36: 16.2 | M36: 8.9 | N36: =(K36*L36*M36)/1000000 | O36: 20 | P36: =(I36+J36)*(O36%+(O36%*10%)) | Q36: =(I36+J36+P36)*'Edit Parameters'!B$1 | R36: =Q36*1.18 | S36: 11 | T36: 51 | U36: 144 | V36: 10 | W36: 2 | X36: 5 | Y36: 0 | Z36: 18 | AA36: =AE36-(AE36/1.18) | AB36: =R36*0.05 | AC36: =R36*0.03 | AD36: 0 | AE36: 1199 | AF36: 1999 | AI36: 1299
A37: FBA79844 | B37: B0FN7DYB2M | C37: PB-08 (AM-C1 + AI-04) | D37: Bundles | E37: PB-08 | F37: 0.11 | G37: PB-08 (AM-C1 + AI-04) | H37: 85181000 | I37: 29 | J37: ='Edit Parameters'!$B$2/('Edit Parameters'!$B$3/N37) | K37: 43.4 | L37: 27.4 | M37: 18.5 | N37: =(K37*L37*M37)/1000000 | O37: 15 | P37: =(I37+J37)*(O37%+(O37%*10%)) | Q37: =(I37+J37+P37)*'Edit Parameters'!B$1 | R37: =Q37*1.18 | S37: 11 | T37: 51 | U37: 214 | V37: 10 | W37: 2 | X37: 5 | Y37: 0 | Z37: 18 | AA37: =AE37-(AE37/1.18) | AB37: =R37*0.05 | AC37: =R37*0.03 | AD37: 0 | AE37: 6999 | AF37: ₹ 11,999.00
A38: FBA79694 | B38: B0DT6T6N6B | C38: AA-26 | D38: Microphone Accessories | E38: Microphone Stand | F38: 0.07 | G38: AA-26 | H38: 85189000 | I38: 2 | J38: ='Edit Parameters'!$B$2/('Edit Parameters'!$B$3/N38) | K38: 12.6 | L38: 12.3 | M38: 3.02 | N38: =(K38*L38*M38)/1000000 | O38: 15 | P38: =(I38+J38)*(O38%+(O38%*10%)) | Q38: =(I38+J38+P38)*'Edit Parameters'!B$1 | R38: =Q38*1.18 | S38: 7 | T38: 26 | U38: 58 | V38: 10 | W38: 2 | X38: 5 | Y38: 0 | Z38: 18 | AA38: =AE38-(AE38/1.18) | AB38: =R38*0.05 | AC38: =R38*0.03 | AD38: 0 | AE38: 499 | AF38: 899 | AI38: 549
A39: FBA78960 | B39: B0CBCB82MT | C39: AM-C39 | D39: Microphone | E39: XLR Condenser Microphone Kit - Tripod | F39: 0.11 | G39: AM-C39 | H39: 85181000 | I39: 5.5 | J39: ='Edit Parameters'!$B$2/('Edit Parameters'!$B$3/N39) | K39: 20.8 | L39: 19.8 | M39: 7.3 | N39: =(K39*L39*M39)/1000000 | O39: 15 | P39: =(I39+J39)*(O39%+(O39%*10%)) | Q39: =(I39+J39+P39)*'Edit Parameters'!B$1 | R39: =Q39*1.18 | S39: 11 | T39: 51 | U39: 101.42373 | V39: 10 | W39: 2 | X39: 5 | Y39: 0 | Z39: 18 | AA39: =AE39-(AE39/1.18) | AB39: =R39*0.05 | AC39: =R39*0.03 | AD39: 0 | AE39: 1599 | AF39: 3999 | AI39: 1699
A40: FBA75679 | B40: B0B4JRQP22 | C40: AA-02 | D40: Microphone Accessories | E40: Sound Isolation Shield | F40: 0.11 | G40: AA-02 | H40: 85189000 | I40: 9.5 | J40: ='Edit Parameters'!$B$2/('Edit Parameters'!$B$3/N40) | K40: 33.4 | L40: 17.4 | M40: 17.4 | N40: =(K40*L40*M40)/1000000 | O40: 15 | P40: =(I40+J40)*(O40%+(O40%*10%)) | Q40: =(I40+J40+P40)*'Edit Parameters'!B$1 | R40: =Q40*1.18 | S40: 11 | T40: 51 | U40: 147 | V40: 10 | W40: 2 | X40: 5 | Y40: 0 | Z40: 18 | AA40: =AE40-(AE40/1.18) | AB40: =R40*0.05 | AC40: =R40*0.03 | AD40: 0 | AE40: 2499 | AF40: 5999 | AI40: 2499
A41: FBA79107 | B41: B0CM9P5CCK | C41: AM-W17 | D41: Microphone | E41: Wireless Lapel Microphone | F41: 0.115 | G41: AM-W17 | H41: 85181000 | I41: 8 | J41: ='Edit Parameters'!$B$2/('Edit Parameters'!$B$3/N41) | K41: 14.3 | L41: 8.2 | M41: 3.4 | N41: =(K41*L41*M41)/1000000 | O41: 15 | P41: =(I41+J41)*(O41%+(O41%*10%)) | Q41: =(I41+J41+P41)*'Edit Parameters'!B$1 | R41: =Q41*1.18 | S41: 11.5 | T41: 51 | U41: 58 | V41: 10 | W41: 2 | X41: 5 | Y41: 0 | Z41: 18 | AA41: =AE41-(AE41/1.18) | AB41: =R41*0.05 | AC41: =R41*0.03 | AD41: 0 | AE41: 1899 | AF41: 4999 | AI41: 1749
A42: FBA79655 | B42: B0DN6PFWNK | C42: AM-C44 Pro | D42: Bundles | E42: Bundles | F42: 0.11 | G42: AM-C44 Pro | H42: 85181000 | I42: 24 | J42: ='Edit Parameters'!$B$2/('Edit Parameters'!$B$3/N42) | K42: 41.4 | L42: 19.4 | M42: 16.1 | N42: =(K42*L42*M42)/1000000 | O42: 15 | P42: =(I42+J42)*(O42%+(O42%*10%)) | Q42: =(I42+J42+P42)*'Edit Parameters'!B$1 | R42: =Q42*1.18 | S42: 11 | T42: 51 | U42: 27 | V42: 10 | W42: 2 | X42: 5 | Y42: 0 | Z42: 18 | AA42: =AE42-(AE42/1.18) | AB42: =R42*0.05 | AC42: =R42*0.03 | AD42: 0 | AE42: 5799 | AF42: 9499 | AI42: 5299
A43: FBA79841 | B43: B0FQBTRM28 | C43: AH-60 BL | D43: Headphone | E43: DJ Headphone | F43: 0.11 | G43: AH-60 BL | H43: 85183020 | I43: 8 | J43: ='Edit Parameters'!$B$2/('Edit Parameters'!$B$3/N43) | K43: 27.1 | L43: 26.5 | M43: 12.4 | N43: =(K43*L43*M43)/1000000 | O43: 20 | P43: =(I43+J43)*(O43%+(O43%*10%)) | Q43: =(I43+J43+P43)*'Edit Parameters'!B$1 | R43: =Q43*1.18 | S43: 11 | T43: 51 | U43: 115 | V43: 10 | W43: 2 | X43: 5 | Y43: 0 | Z43: 18 | AA43: =AE43-(AE43/1.18) | AB43: =R43*0.05 | AC43: =R43*0.03 | AD43: 0 | AE43: 1999 | AF43: 3499 | AI43: 1999
A44: FBA75684 | B44: B0B4G7VWXD | C44: AA-04 | D44: Microphone Accessories | E44: Shock Mount | F44: 0.11 | G44: AA-04 | H44: 85189000 | I44: 6.6 | J44: ='Edit Parameters'!$B$2/('Edit Parameters'!$B$3/N44) | K44: 15.5 | L44: 13.1 | M44: 12.7 | N44: =(K44*L44*M44)/1000000 | O44: 15 | P44: =(I44+J44)*(O44%+(O44%*10%)) | Q44: =(I44+J44+P44)*'Edit Parameters'!B$1 | R44: =Q44*1.18 | S44: 11 | T44: 51 | U44: 76 | V44: 10 | W44: 2 | X44: 5 | Y44: 0 | Z44: 18 | AA44: =AE44-(AE44/1.18) | AB44: =R44*0.05 | AC44: =R44*0.03 | AD44: 0 | AE44: 1599 | AF44: 2999 | AI44: 1699
A45: FBA79008 | B45: B0CH4RT4P8 | C45: AI-06 | D45: Audio Interface | E45: Audio Interface | F45: 0.11 | G45: AI-06 | H45: 85437029 | I45: 22.5 | J45: ='Edit Parameters'!$B$2/('Edit Parameters'!$B$3/N45) | K45: 23 | L45: 15.8 | M45: 7.9 | N45: =(K45*L45*M45)/1000000 | O45: 7.5 | P45: =(I45+J45)*(O45%+(O45%*10%)) | Q45: =(I45+J45+P45)*'Edit Parameters'!B$1 | R45: =Q45*1.18 | S45: 11 | T45: 51 | U45: 77 | V45: 10 | W45: 2 | X45: 5 | Y45: 0 | Z45: 18 | AA45: =AE45-(AE45/1.18) | AB45: =R45*0.05 | AC45: =R45*0.03 | AD45: 0 | AE45: 3999 | AF45: 9999 | AI45: 3499
A46: FBA79445 | B46: B0DFMLS8JG | C46: AM-W32 | D46: Microphone | E46: Wireless UHF Microphone | F46: 0.11 | G46: AM-W32 | H46: 85181000 | I46: 16.62 | J46: ='Edit Parameters'!$B$2/('Edit Parameters'!$B$3/N46) | K46: 30.5 | L46: 19.1 | M46: 6.2 | N46: =(K46*L46*M46)/1000000 | O46: 15 | P46: =(I46+J46)*(O46%+(O46%*10%)) | Q46: =(I46+J46+P46)*'Edit Parameters'!B$1 | R46: =Q46*1.18 | S46: 11 | T46: 51 | U46: 76 | V46: 10 | W46: 2 | X46: 5 | Y46: 0 | Z46: 18 | AA46: =AE46-(AE46/1.18) | AB46: =R46*0.05 | AC46: =R46*0.03 | AD46: 0 | AE46: 3899 | AF46: 6999 | AI46: 3549
A47: FBA76414 | B47: B0BLJVJ2GN | C47: AA-05 | D47: Microphone Accessories | E47: Boom Arm | F47: 0.105 | G47: AA-05 | H47: 85189000 | I47: 2 | J47: ='Edit Parameters'!$B$2/('Edit Parameters'!$B$3/N47) | K47: 39.79 | L47: 11.4 | M47: 4.9 | N47: =(K47*L47*M47)/1000000 | O47: 15 | P47: =(I47+J47)*(O47%+(O47%*10%)) | Q47: =(I47+J47+P47)*'Edit Parameters'!B$1 | R47: =Q47*1.18 | S47: 10.5 | T47: 26 | U47: 76 | V47: 10 | W47: 2 | X47: 5 | Y47: 0 | Z47: 18 | AA47: =AE47-(AE47/1.18) | AB47: =R47*0.05 | AC47: =R47*0.03 | AD47: 0 | AE47: 679 | AF47: 1999 | AI47: 649
A48: FBA75675 | B48: B0B4G8ZB64 | C48: AM-C3 | D48: Microphone | E48: Wired Dynamic Mic | F48: 0.055 | G48: AM-C3 | H48: 85181000 | I48: 5 | J48: ='Edit Parameters'!$B$2/('Edit Parameters'!$B$3/N48) | K48: 24.5 | L48: 13.1 | M48: 5.8 | N48: =(K48*L48*M48)/1000000 | O48: 15 | P48: =(I48+J48)*(O48%+(O48%*10%)) | Q48: =(I48+J48+P48)*'Edit Parameters'!B$1 | R48: =Q48*1.18 | S48: 5.5 | T48: 26 | U48: 17 | V48: 10 | W48: 2 | X48: 5 | Y48: 0 | Z48: 18 | AA48: =AE48-(AE48/1.18) | AB48: =R48*0.05 | AC48: =R48*0.03 | AD48: 0 | AE48: 899 | AF48: 2999 | AI48: 899
A49: FBA79783 | B49: B0FF9R3GKK | C49: AM-C47 | D49: Microphone | E49: RGB Condenser Mic with Boom Arm | F49: 0.11 | G49: AM-C47 | H49: 85181000 | I49: 12.4 | J49: ='Edit Parameters'!$B$2/('Edit Parameters'!$B$3/N49) | K49: 43 | L49: 20.4 | M49: 10.2 | N49: =(K49*L49*M49)/1000000 | O49: 15 | P49: =(I49+J49)*(O49%+(O49%*10%)) | Q49: =(I49+J49+P49)*'Edit Parameters'!B$1 | R49: =Q49*1.18 | S49: 11 | T49: 51 | U49: 114 | V49: 10 | W49: 2 | X49: 5 | Y49: 0 | Z49: 18 | AA49: =AE49-(AE49/1.18) | AB49: =R49*0.05 | AC49: =R49*0.03 | AD49: 0 | AE49: 2999 | AF49: 4999 | AI49: 2999
A50: FBA79827 | B50: B0FJ8S5XJ8 | C50: PB-03 (AI-04 Red + AM-C11 x 2) | D50: Bundles | E50: PB-03 | F50: 0.11 | G50: PB-03 (AI-04 Red + AM-C11 x 2) | H50: 85181000 | I50: 64 | J50: ='Edit Parameters'!$B$2/('Edit Parameters'!$B$3/N50) | K50: 43.6 | L50: 21.5 | M50: 18.8 | N50: =(K50*L50*M50)/1000000 | O50: 15 | P50: =(I50+J50)*(O50%+(O50%*10%)) | Q50: =(I50+J50+P50)*'Edit Parameters'!B$1 | R50: =Q50*1.18 | S50: 11 | T50: 51 | U50: 246.94915 | V50: 10 | W50: 2 | X50: 5 | Y50: 0 | Z50: 18 | AA50: =AE50-(AE50/1.18) | AB50: =R50*0.05 | AC50: =R50*0.03 | AD50: 0 | AE50: 13999 | AF50: ₹ 26,299.00 | AI50: 13899
A51: FBA77171 | B51: B0CH4VCD6R | C51: AC-6XL | D51: Microphone Accessories | E51: 6m XLR to 6.35m Cable | F51: 0.155 | G51: AC-6XL | H51: 85189000 | I51: 1.3 | J51: ='Edit Parameters'!$B$2/('Edit Parameters'!$B$3/N51) | K51: 28.4 | L51: 19.5 | M51: 3.7 | N51: =(K51*L51*M51)/1000000 | O51: 15 | P51: =(I51+J51)*(O51%+(O51%*10%)) | Q51: =(I51+J51+P51)*'Edit Parameters'!B$1 | R51: =Q51*1.18 | S51: 15.5 | T51: 26 | U51: 76 | V51: 10 | W51: 2 | X51: 5 | Y51: 0 | Z51: 18 | AA51: =AE51-(AE51/1.18) | AB51: =R51*0.05 | AC51: =R51*0.03 | AD51: 0 | AE51: 499 | AF51: 999 | AI51: 549
A52: FBA79653 | B52: B0DN6LJZBR | C52: AM-C45 Pro | D52: Bundles | E52: Bundles | F52: 0.11 | G52: AM-C45 Pro | H52: 85181000 | I52: 17.5 | J52: ='Edit Parameters'!$B$2/('Edit Parameters'!$B$3/N52) | K52: 41.5 | L52: 19.3 | M52: 16 | N52: =(K52*L52*M52)/1000000 | O52: 15 | P52: =(I52+J52)*(O52%+(O52%*10%)) | Q52: =(I52+J52+P52)*'Edit Parameters'!B$1 | R52: =Q52*1.18 | S52: 11 | T52: 51 | U52: 27 | V52: 10 | W52: 2 | X52: 5 | Y52: 0 | Z52: 18 | AA52: =AE52-(AE52/1.18) | AB52: =R52*0.05 | AC52: =R52*0.03 | AD52: 0 | AE52: 4499 | AF52: 8999 | AI52: 4099
A53: FBA79825 | B53: B0FJ2DT13L | C53: GB-02 (AM-C43 + AI-11) | D53: Bundles | E53: GB-02 | F53: 0.11 | G53: GB-02 (AM-C43 + AI-11) | H53: 85181000 | I53: 16.5 | J53: ='Edit Parameters'!$B$2/('Edit Parameters'!$B$3/N53) | K53: 43.7 | L53: 21.9 | M53: 18.3 | N53: =(K53*L53*M53)/1000000 | O53: 15 | P53: =(I53+J53)*(O53%+(O53%*10%)) | Q53: =(I53+J53+P53)*'Edit Parameters'!B$1 | R53: =Q53*1.18 | S53: 11 | T53: 51 | U53: 247.94915 | V53: 10 | W53: 2 | X53: 5 | Y53: 0 | Z53: 18 | AA53: =AE53-(AE53/1.18) | AB53: =R53*0.05 | AC53: =R53*0.03 | AD53: 0 | AE53: 3899 | AF53: ₹ 12,499.00 | AI53: 3899
A54: FBA75687 | B54: B0B4G5ZLTB | C54: AM-W11 | D54: Microphone | E54: Wireless UHF Microphone | F54: 0.11 | G54: AM-W11 | H54: 85181000 | I54: 22.3 | J54: ='Edit Parameters'!$B$2/('Edit Parameters'!$B$3/N54) | K54: 12.4 | L54: 10.2 | M54: 5.4 | N54: =(K54*L54*M54)/1000000 | O54: 15 | P54: =(I54+J54)*(O54%+(O54%*10%)) | Q54: =(I54+J54+P54)*'Edit Parameters'!B$1 | R54: =Q54*1.18 | S54: 11 | T54: 51 | U54: 58 | V54: 10 | W54: 2 | X54: 5 | Y54: 0 | Z54: 18 | AA54: =AE54-(AE54/1.18) | AB54: =R54*0.05 | AC54: =R54*0.03 | AD54: 0 | AE54: 2799 | AF54: 9999 | AI54: 2299
A55: FBA78974 | B55: B0CF5RRTDJ | C55: AA-20 | D55: Microphone Accessories | E55: Boom Arm | F55: 0.11 | G55: AA-20 | H55: 85189000 | I55: 8.1 | J55: ='Edit Parameters'!$B$2/('Edit Parameters'!$B$3/N55) | K55: 44.9 | L55: 16 | M55: 10.6 | N55: =(K55*L55*M55)/1000000 | O55: 15 | P55: =(I55+J55)*(O55%+(O55%*10%)) | Q55: =(I55+J55+P55)*'Edit Parameters'!B$1 | R55: =Q55*1.18 | S55: 11 | T55: 51 | U55: 114 | V55: 10 | W55: 2 | X55: 5 | Y55: 0 | Z55: 18 | AA55: =AE55-(AE55/1.18) | AB55: =R55*0.05 | AC55: =R55*0.03 | AD55: 0 | AE55: 2499 | AF55: 4999 | AI55: 2149
A56: FBA75680 | B56: B0B4G1PXWV | C56: AM-C6 | D56: Microphone | E56: USB Microphone Kit - Tripod | F56: 0.11 | G56: AM-C6 | H56: 85181000 | I56: 14 | J56: ='Edit Parameters'!$B$2/('Edit Parameters'!$B$3/N56) | K56: 21.7 | L56: 12.2 | M56: 8.4 | N56: =(K56*L56*M56)/1000000 | O56: 15 | P56: =(I56+J56)*(O56%+(O56%*10%)) | Q56: =(I56+J56+P56)*'Edit Parameters'!B$1 | R56: =Q56*1.18 | S56: 11 | T56: 51 | U56: 76 | V56: 10 | W56: 2 | X56: 5 | Y56: 0 | Z56: 18 | AA56: =AE56-(AE56/1.18) | AB56: =R56*0.05 | AC56: =R56*0.03 | AD56: 0 | AE56: 2599 | AF56: 5999 | AI56: 1999
A57: FBA79009 | B57: B0CH4PMR8K | C57: AM-C41 | D57: Microphone | E57: USB Microphone Kit - Tripod | F57: 0.11 | G57: AM-C41 | H57: 85181000 | I57: 8 | J57: ='Edit Parameters'!$B$2/('Edit Parameters'!$B$3/N57) | K57: 20.8 | L57: 20.2 | M57: 7.5 | N57: =(K57*L57*M57)/1000000 | O57: 15 | P57: =(I57+J57)*(O57%+(O57%*10%)) | Q57: =(I57+J57+P57)*'Edit Parameters'!B$1 | R57: =Q57*1.18 | S57: 11 | T57: 51 | U57: 17 | V57: 10 | W57: 2 | X57: 5 | Y57: 0 | Z57: 18 | AA57: =AE57-(AE57/1.18) | AB57: =R57*0.05 | AC57: =R57*0.03 | AD57: 0 | AE57: 1799 | AF57: 3999 | AI57: 1649
A58: FBA75676 | B58: B0B4DS678Q | C58: AM-C4 | D58: Microphone | E58: USB Microphone Kit - Tripod | F58: 0.11 | G58: AM-C4 | H58: 85181000 | I58: 13 | J58: ='Edit Parameters'!$B$2/('Edit Parameters'!$B$3/N58) | K58: 23.3 | L58: 13.9 | M58: 10.9 | N58: =(K58*L58*M58)/1000000 | O58: 15 | P58: =(I58+J58)*(O58%+(O58%*10%)) | Q58: =(I58+J58+P58)*'Edit Parameters'!B$1 | R58: =Q58*1.18 | S58: 11 | T58: 51 | U58: 77 | V58: 10 | W58: 2 | X58: 5 | Y58: 0 | Z58: 18 | AA58: =AE58-(AE58/1.18) | AB58: =R58*0.05 | AC58: =R58*0.03 | AD58: 0 | AE58: 2499 | AF58: 5999 | AI58: 1999
A59: FBA76597 | B59: B0BQ7H7418 | C59: AA-06 | D59: Microphone Accessories | E59: Boom Arm Kit | F59: 0.11 | G59: AA-06 | H59: 85189000 | I59: 4.3 | J59: ='Edit Parameters'!$B$2/('Edit Parameters'!$B$3/N59) | K59: 40.5 | L59: 16.4 | M59: 7.2 | N59: =(K59*L59*M59)/1000000 | O59: 15 | P59: =(I59+J59)*(O59%+(O59%*10%)) | Q59: =(I59+J59+P59)*'Edit Parameters'!B$1 | R59: =Q59*1.18 | S59: 11 | T59: 51 | U59: 109 | V59: 10 | W59: 2 | X59: 5 | Y59: 0 | Z59: 18 | AA59: =AE59-(AE59/1.18) | AB59: =R59*0.05 | AC59: =R59*0.03 | AD59: 0 | AE59: 1349 | AF59: 2999 | AI59: 1299
A60: FBA79016 | B60: B0CH4R1V6S | C60: AM-C3a | D60: Microphone | E60: Wired Dynamic Mic | F60: 0.055 | G60: AM-C3a | H60: 85181000 | I60: 4 | J60: ='Edit Parameters'!$B$2/('Edit Parameters'!$B$3/N60) | K60: 25.3 | L60: 13.4 | M60: 5.7 | N60: =(K60*L60*M60)/1000000 | O60: 15 | P60: =(I60+J60)*(O60%+(O60%*10%)) | Q60: =(I60+J60+P60)*'Edit Parameters'!B$1 | R60: =Q60*1.18 | S60: 5.5 | T60: 26 | U60: 58 | V60: 10 | W60: 2 | X60: 5 | Y60: 0 | Z60: 18 | AA60: =AE60-(AE60/1.18) | AB60: =R60*0.05 | AC60: =R60*0.03 | AD60: 0 | AE60: 899 | AF60: 1999 | AI60: 749
A61: FBA79230 | B61: B0CX1XK5R6 | C61: AM-W46 | D61: Speaker | E61: Microphone with Speaker | F61: 0.11 | G61: AM-W46 | H61: 85182290 | I61: 32.8 | J61: ='Edit Parameters'!$B$2/('Edit Parameters'!$B$3/N61) | K61: 27.9 | L61: 23 | M61: 12.1 | N61: =(K61*L61*M61)/1000000 | O61: 20 | P61: =(I61+J61)*(O61%+(O61%*10%)) | Q61: =(I61+J61+P61)*'Edit Parameters'!B$1 | R61: =Q61*1.18 | S61: 11 | T61: 51 | U61: 142 | V61: 10 | W61: 2 | X61: 5 | Y61: 0 | Z61: 18 | AA61: =AE61-(AE61/1.18) | AB61: =R61*0.05 | AC61: =R61*0.03 | AD61: 0 | AE61: 5999 | AF61: 12999 | AI61: 4799
A62: FBA79448 | B62: B0DFMKY4TT | C62: AM-W35 | D62: Microphone | E62: Wireless UHF Microphone | F62: 0.11 | G62: AM-W35 | H62: 85181000 | I62: 15.22 | J62: ='Edit Parameters'!$B$2/('Edit Parameters'!$B$3/N62) | K62: 26.2 | L62: 15.3 | M62: 6.2 | N62: =(K62*L62*M62)/1000000 | O62: 15 | P62: =(I62+J62)*(O62%+(O62%*10%)) | Q62: =(I62+J62+P62)*'Edit Parameters'!B$1 | R62: =Q62*1.18 | S62: 11 | T62: 51 | U62: 76 | V62: 10 | W62: 2 | X62: 5 | Y62: 0 | Z62: 18 | AA62: =AE62-(AE62/1.18) | AB62: =R62*0.05 | AC62: =R62*0.03 | AD62: 0 | AE62: 3359 | AF62: 6499 | AI62: 3199
...

Sheet Edit Parameters
A1: Dollar Conversion Rate | B1: 95
A2: 40HQ Freight+Clearance | B2: 2000
A3: 40HQ Usable CBM | B3: 68
A4: Fulfillment Rate/kg | B4: 40
A5: Surcharge | B5: 0.1
A6: Referral Fee (<15001) | B6: 0.15
A7: Referral Fee (>15000) | B7: 0.1
A8: AMS | B8: 0.15
A9: Returns and Repairs | B9: 0.05
A10: Overheads | B10: 0.05
A11: Finance | B11: 0.03
A12: Coupon | B12: 0.02
... A15: SMM | B15: 0
